2020-02-10 17:20:02,027 INFO: Microblog startup [in /Users/yhz/Desktop/pypy/Flask_Learn/app/__init__.py:104]
2020-02-10 17:20:02,792 ERROR: Exception on /index [GET] [in /Library/Frameworks/Python.framework/Versions/3.7/lib/python3.7/site-packages/flask/app.py:1761]
Traceback (most recent call last):
  File "/Library/Frameworks/Python.framework/Versions/3.7/lib/python3.7/site-packages/sqlalchemy/engine/base.py", line 1249, in _execute_context
    cursor, statement, parameters, context
  File "/Library/Frameworks/Python.framework/Versions/3.7/lib/python3.7/site-packages/sqlalchemy/engine/default.py", line 552, in do_execute
    cursor.execute(statement, parameters)
sqlite3.OperationalError: no such table: user

The above exception was the direct cause of the following exception:

Traceback (most recent call last):
  File "/Library/Frameworks/Python.framework/Versions/3.7/lib/python3.7/site-packages/flask/app.py", line 2292, in wsgi_app
    response = self.full_dispatch_request()
  File "/Library/Frameworks/Python.framework/Versions/3.7/lib/python3.7/site-packages/flask/app.py", line 1815, in full_dispatch_request
    rv = self.handle_user_exception(e)
  File "/Library/Frameworks/Python.framework/Versions/3.7/lib/python3.7/site-packages/flask/app.py", line 1718, in handle_user_exception
    reraise(exc_type, exc_value, tb)
  File "/Library/Frameworks/Python.framework/Versions/3.7/lib/python3.7/site-packages/flask/_compat.py", line 35, in reraise
    raise value
  File "/Library/Frameworks/Python.framework/Versions/3.7/lib/python3.7/site-packages/flask/app.py", line 1811, in full_dispatch_request
    rv = self.preprocess_request()
  File "/Library/Frameworks/Python.framework/Versions/3.7/lib/python3.7/site-packages/flask/app.py", line 2087, in preprocess_request
    rv = func()
  File "/Users/yhz/Desktop/pypy/Flask_Learn/app/main/routes.py", line 21, in before_request
    if current_user.is_authenticated:
  File "/Library/Frameworks/Python.framework/Versions/3.7/lib/python3.7/site-packages/werkzeug/local.py", line 347, in __getattr__
    return getattr(self._get_current_object(), name)
  File "/Library/Frameworks/Python.framework/Versions/3.7/lib/python3.7/site-packages/werkzeug/local.py", line 306, in _get_current_object
    return self.__local()
  File "/Library/Frameworks/Python.framework/Versions/3.7/lib/python3.7/site-packages/flask_login/utils.py", line 26, in <lambda>
    current_user = LocalProxy(lambda: _get_user())
  File "/Library/Frameworks/Python.framework/Versions/3.7/lib/python3.7/site-packages/flask_login/utils.py", line 335, in _get_user
    current_app.login_manager._load_user()
  File "/Library/Frameworks/Python.framework/Versions/3.7/lib/python3.7/site-packages/flask_login/login_manager.py", line 359, in _load_user
    return self.reload_user()
  File "/Library/Frameworks/Python.framework/Versions/3.7/lib/python3.7/site-packages/flask_login/login_manager.py", line 321, in reload_user
    user = self.user_callback(user_id)
  File "/Users/yhz/Desktop/pypy/Flask_Learn/app/models.py", line 269, in load_user
    return User.query.get(int(id))  # 传入字符串类型，使用数字ID的数据库需要将字符串转换为整数。
  File "/Library/Frameworks/Python.framework/Versions/3.7/lib/python3.7/site-packages/sqlalchemy/orm/query.py", line 959, in get
    return self._get_impl(ident, loading.load_on_pk_identity)
  File "/Library/Frameworks/Python.framework/Versions/3.7/lib/python3.7/site-packages/sqlalchemy/orm/query.py", line 1069, in _get_impl
    return db_load_fn(self, primary_key_identity)
  File "/Library/Frameworks/Python.framework/Versions/3.7/lib/python3.7/site-packages/sqlalchemy/orm/loading.py", line 282, in load_on_pk_identity
    return q.one()
  File "/Library/Frameworks/Python.framework/Versions/3.7/lib/python3.7/site-packages/sqlalchemy/orm/query.py", line 3292, in one
    ret = self.one_or_none()
  File "/Library/Frameworks/Python.framework/Versions/3.7/lib/python3.7/site-packages/sqlalchemy/orm/query.py", line 3261, in one_or_none
    ret = list(self)
  File "/Library/Frameworks/Python.framework/Versions/3.7/lib/python3.7/site-packages/sqlalchemy/orm/query.py", line 3334, in __iter__
    return self._execute_and_instances(context)
  File "/Library/Frameworks/Python.framework/Versions/3.7/lib/python3.7/site-packages/sqlalchemy/orm/query.py", line 3359, in _execute_and_instances
    result = conn.execute(querycontext.statement, self._params)
  File "/Library/Frameworks/Python.framework/Versions/3.7/lib/python3.7/site-packages/sqlalchemy/engine/base.py", line 988, in execute
    return meth(self, multiparams, params)
  File "/Library/Frameworks/Python.framework/Versions/3.7/lib/python3.7/site-packages/sqlalchemy/sql/elements.py", line 287, in _execute_on_connection
    return connection._execute_clauseelement(self, multiparams, params)
  File "/Library/Frameworks/Python.framework/Versions/3.7/lib/python3.7/site-packages/sqlalchemy/engine/base.py", line 1107, in _execute_clauseelement
    distilled_params,
  File "/Library/Frameworks/Python.framework/Versions/3.7/lib/python3.7/site-packages/sqlalchemy/engine/base.py", line 1253, in _execute_context
    e, statement, parameters, cursor, context
  File "/Library/Frameworks/Python.framework/Versions/3.7/lib/python3.7/site-packages/sqlalchemy/engine/base.py", line 1473, in _handle_dbapi_exception
    util.raise_from_cause(sqlalchemy_exception, exc_info)
  File "/Library/Frameworks/Python.framework/Versions/3.7/lib/python3.7/site-packages/sqlalchemy/util/compat.py", line 398, in raise_from_cause
    reraise(type(exception), exception, tb=exc_tb, cause=cause)
  File "/Library/Frameworks/Python.framework/Versions/3.7/lib/python3.7/site-packages/sqlalchemy/util/compat.py", line 152, in reraise
    raise value.with_traceback(tb)
  File "/Library/Frameworks/Python.framework/Versions/3.7/lib/python3.7/site-packages/sqlalchemy/engine/base.py", line 1249, in _execute_context
    cursor, statement, parameters, context
  File "/Library/Frameworks/Python.framework/Versions/3.7/lib/python3.7/site-packages/sqlalchemy/engine/default.py", line 552, in do_execute
    cursor.execute(statement, parameters)
sqlalchemy.exc.OperationalError: (sqlite3.OperationalError) no such table: user
[SQL: SELECT user.id AS user_id, user.username AS user_username, user.email AS user_email, user.password_hash AS user_password_hash, user.about_me AS user_about_me, user.last_seen AS user_last_seen, user.token AS user_token, user.token_expiration AS user_token_expiration, user.last_message_read_time AS user_last_message_read_time 
FROM user 
WHERE user.id = ?]
[parameters: (1,)]
(Background on this error at: http://sqlalche.me/e/e3q8)
2020-02-10 17:20:05,190 ERROR: Exception on /explore [GET] [in /Library/Frameworks/Python.framework/Versions/3.7/lib/python3.7/site-packages/flask/app.py:1761]
Traceback (most recent call last):
  File "/Library/Frameworks/Python.framework/Versions/3.7/lib/python3.7/site-packages/sqlalchemy/engine/base.py", line 1249, in _execute_context
    cursor, statement, parameters, context
  File "/Library/Frameworks/Python.framework/Versions/3.7/lib/python3.7/site-packages/sqlalchemy/engine/default.py", line 552, in do_execute
    cursor.execute(statement, parameters)
sqlite3.OperationalError: no such table: user

The above exception was the direct cause of the following exception:

Traceback (most recent call last):
  File "/Library/Frameworks/Python.framework/Versions/3.7/lib/python3.7/site-packages/flask/app.py", line 2292, in wsgi_app
    response = self.full_dispatch_request()
  File "/Library/Frameworks/Python.framework/Versions/3.7/lib/python3.7/site-packages/flask/app.py", line 1815, in full_dispatch_request
    rv = self.handle_user_exception(e)
  File "/Library/Frameworks/Python.framework/Versions/3.7/lib/python3.7/site-packages/flask/app.py", line 1718, in handle_user_exception
    reraise(exc_type, exc_value, tb)
  File "/Library/Frameworks/Python.framework/Versions/3.7/lib/python3.7/site-packages/flask/_compat.py", line 35, in reraise
    raise value
  File "/Library/Frameworks/Python.framework/Versions/3.7/lib/python3.7/site-packages/flask/app.py", line 1811, in full_dispatch_request
    rv = self.preprocess_request()
  File "/Library/Frameworks/Python.framework/Versions/3.7/lib/python3.7/site-packages/flask/app.py", line 2087, in preprocess_request
    rv = func()
  File "/Users/yhz/Desktop/pypy/Flask_Learn/app/main/routes.py", line 21, in before_request
    if current_user.is_authenticated:
  File "/Library/Frameworks/Python.framework/Versions/3.7/lib/python3.7/site-packages/werkzeug/local.py", line 347, in __getattr__
    return getattr(self._get_current_object(), name)
  File "/Library/Frameworks/Python.framework/Versions/3.7/lib/python3.7/site-packages/werkzeug/local.py", line 306, in _get_current_object
    return self.__local()
  File "/Library/Frameworks/Python.framework/Versions/3.7/lib/python3.7/site-packages/flask_login/utils.py", line 26, in <lambda>
    current_user = LocalProxy(lambda: _get_user())
  File "/Library/Frameworks/Python.framework/Versions/3.7/lib/python3.7/site-packages/flask_login/utils.py", line 335, in _get_user
    current_app.login_manager._load_user()
  File "/Library/Frameworks/Python.framework/Versions/3.7/lib/python3.7/site-packages/flask_login/login_manager.py", line 359, in _load_user
    return self.reload_user()
  File "/Library/Frameworks/Python.framework/Versions/3.7/lib/python3.7/site-packages/flask_login/login_manager.py", line 321, in reload_user
    user = self.user_callback(user_id)
  File "/Users/yhz/Desktop/pypy/Flask_Learn/app/models.py", line 269, in load_user
    return User.query.get(int(id))  # 传入字符串类型，使用数字ID的数据库需要将字符串转换为整数。
  File "/Library/Frameworks/Python.framework/Versions/3.7/lib/python3.7/site-packages/sqlalchemy/orm/query.py", line 959, in get
    return self._get_impl(ident, loading.load_on_pk_identity)
  File "/Library/Frameworks/Python.framework/Versions/3.7/lib/python3.7/site-packages/sqlalchemy/orm/query.py", line 1069, in _get_impl
    return db_load_fn(self, primary_key_identity)
  File "/Library/Frameworks/Python.framework/Versions/3.7/lib/python3.7/site-packages/sqlalchemy/orm/loading.py", line 282, in load_on_pk_identity
    return q.one()
  File "/Library/Frameworks/Python.framework/Versions/3.7/lib/python3.7/site-packages/sqlalchemy/orm/query.py", line 3292, in one
    ret = self.one_or_none()
  File "/Library/Frameworks/Python.framework/Versions/3.7/lib/python3.7/site-packages/sqlalchemy/orm/query.py", line 3261, in one_or_none
    ret = list(self)
  File "/Library/Frameworks/Python.framework/Versions/3.7/lib/python3.7/site-packages/sqlalchemy/orm/query.py", line 3334, in __iter__
    return self._execute_and_instances(context)
  File "/Library/Frameworks/Python.framework/Versions/3.7/lib/python3.7/site-packages/sqlalchemy/orm/query.py", line 3359, in _execute_and_instances
    result = conn.execute(querycontext.statement, self._params)
  File "/Library/Frameworks/Python.framework/Versions/3.7/lib/python3.7/site-packages/sqlalchemy/engine/base.py", line 988, in execute
    return meth(self, multiparams, params)
  File "/Library/Frameworks/Python.framework/Versions/3.7/lib/python3.7/site-packages/sqlalchemy/sql/elements.py", line 287, in _execute_on_connection
    return connection._execute_clauseelement(self, multiparams, params)
  File "/Library/Frameworks/Python.framework/Versions/3.7/lib/python3.7/site-packages/sqlalchemy/engine/base.py", line 1107, in _execute_clauseelement
    distilled_params,
  File "/Library/Frameworks/Python.framework/Versions/3.7/lib/python3.7/site-packages/sqlalchemy/engine/base.py", line 1253, in _execute_context
    e, statement, parameters, cursor, context
  File "/Library/Frameworks/Python.framework/Versions/3.7/lib/python3.7/site-packages/sqlalchemy/engine/base.py", line 1473, in _handle_dbapi_exception
    util.raise_from_cause(sqlalchemy_exception, exc_info)
  File "/Library/Frameworks/Python.framework/Versions/3.7/lib/python3.7/site-packages/sqlalchemy/util/compat.py", line 398, in raise_from_cause
    reraise(type(exception), exception, tb=exc_tb, cause=cause)
  File "/Library/Frameworks/Python.framework/Versions/3.7/lib/python3.7/site-packages/sqlalchemy/util/compat.py", line 152, in reraise
    raise value.with_traceback(tb)
  File "/Library/Frameworks/Python.framework/Versions/3.7/lib/python3.7/site-packages/sqlalchemy/engine/base.py", line 1249, in _execute_context
    cursor, statement, parameters, context
  File "/Library/Frameworks/Python.framework/Versions/3.7/lib/python3.7/site-packages/sqlalchemy/engine/default.py", line 552, in do_execute
    cursor.execute(statement, parameters)
sqlalchemy.exc.OperationalError: (sqlite3.OperationalError) no such table: user
[SQL: SELECT user.id AS user_id, user.username AS user_username, user.email AS user_email, user.password_hash AS user_password_hash, user.about_me AS user_about_me, user.last_seen AS user_last_seen, user.token AS user_token, user.token_expiration AS user_token_expiration, user.last_message_read_time AS user_last_message_read_time 
FROM user 
WHERE user.id = ?]
[parameters: (1,)]
(Background on this error at: http://sqlalche.me/e/e3q8)
2020-02-10 17:22:10,357 ERROR: Exception on /explore [GET] [in /Library/Frameworks/Python.framework/Versions/3.7/lib/python3.7/site-packages/flask/app.py:1761]
Traceback (most recent call last):
  File "/Library/Frameworks/Python.framework/Versions/3.7/lib/python3.7/site-packages/sqlalchemy/engine/base.py", line 1249, in _execute_context
    cursor, statement, parameters, context
  File "/Library/Frameworks/Python.framework/Versions/3.7/lib/python3.7/site-packages/sqlalchemy/engine/default.py", line 552, in do_execute
    cursor.execute(statement, parameters)
sqlite3.OperationalError: no such table: user

The above exception was the direct cause of the following exception:

Traceback (most recent call last):
  File "/Library/Frameworks/Python.framework/Versions/3.7/lib/python3.7/site-packages/flask/app.py", line 2292, in wsgi_app
    response = self.full_dispatch_request()
  File "/Library/Frameworks/Python.framework/Versions/3.7/lib/python3.7/site-packages/flask/app.py", line 1815, in full_dispatch_request
    rv = self.handle_user_exception(e)
  File "/Library/Frameworks/Python.framework/Versions/3.7/lib/python3.7/site-packages/flask/app.py", line 1718, in handle_user_exception
    reraise(exc_type, exc_value, tb)
  File "/Library/Frameworks/Python.framework/Versions/3.7/lib/python3.7/site-packages/flask/_compat.py", line 35, in reraise
    raise value
  File "/Library/Frameworks/Python.framework/Versions/3.7/lib/python3.7/site-packages/flask/app.py", line 1811, in full_dispatch_request
    rv = self.preprocess_request()
  File "/Library/Frameworks/Python.framework/Versions/3.7/lib/python3.7/site-packages/flask/app.py", line 2087, in preprocess_request
    rv = func()
  File "/Users/yhz/Desktop/pypy/Flask_Learn/app/main/routes.py", line 21, in before_request
    if current_user.is_authenticated:
  File "/Library/Frameworks/Python.framework/Versions/3.7/lib/python3.7/site-packages/werkzeug/local.py", line 347, in __getattr__
    return getattr(self._get_current_object(), name)
  File "/Library/Frameworks/Python.framework/Versions/3.7/lib/python3.7/site-packages/werkzeug/local.py", line 306, in _get_current_object
    return self.__local()
  File "/Library/Frameworks/Python.framework/Versions/3.7/lib/python3.7/site-packages/flask_login/utils.py", line 26, in <lambda>
    current_user = LocalProxy(lambda: _get_user())
  File "/Library/Frameworks/Python.framework/Versions/3.7/lib/python3.7/site-packages/flask_login/utils.py", line 335, in _get_user
    current_app.login_manager._load_user()
  File "/Library/Frameworks/Python.framework/Versions/3.7/lib/python3.7/site-packages/flask_login/login_manager.py", line 359, in _load_user
    return self.reload_user()
  File "/Library/Frameworks/Python.framework/Versions/3.7/lib/python3.7/site-packages/flask_login/login_manager.py", line 321, in reload_user
    user = self.user_callback(user_id)
  File "/Users/yhz/Desktop/pypy/Flask_Learn/app/models.py", line 269, in load_user
    return User.query.get(int(id))  # 传入字符串类型，使用数字ID的数据库需要将字符串转换为整数。
  File "/Library/Frameworks/Python.framework/Versions/3.7/lib/python3.7/site-packages/sqlalchemy/orm/query.py", line 959, in get
    return self._get_impl(ident, loading.load_on_pk_identity)
  File "/Library/Frameworks/Python.framework/Versions/3.7/lib/python3.7/site-packages/sqlalchemy/orm/query.py", line 1069, in _get_impl
    return db_load_fn(self, primary_key_identity)
  File "/Library/Frameworks/Python.framework/Versions/3.7/lib/python3.7/site-packages/sqlalchemy/orm/loading.py", line 282, in load_on_pk_identity
    return q.one()
  File "/Library/Frameworks/Python.framework/Versions/3.7/lib/python3.7/site-packages/sqlalchemy/orm/query.py", line 3292, in one
    ret = self.one_or_none()
  File "/Library/Frameworks/Python.framework/Versions/3.7/lib/python3.7/site-packages/sqlalchemy/orm/query.py", line 3261, in one_or_none
    ret = list(self)
  File "/Library/Frameworks/Python.framework/Versions/3.7/lib/python3.7/site-packages/sqlalchemy/orm/query.py", line 3334, in __iter__
    return self._execute_and_instances(context)
  File "/Library/Frameworks/Python.framework/Versions/3.7/lib/python3.7/site-packages/sqlalchemy/orm/query.py", line 3359, in _execute_and_instances
    result = conn.execute(querycontext.statement, self._params)
  File "/Library/Frameworks/Python.framework/Versions/3.7/lib/python3.7/site-packages/sqlalchemy/engine/base.py", line 988, in execute
    return meth(self, multiparams, params)
  File "/Library/Frameworks/Python.framework/Versions/3.7/lib/python3.7/site-packages/sqlalchemy/sql/elements.py", line 287, in _execute_on_connection
    return connection._execute_clauseelement(self, multiparams, params)
  File "/Library/Frameworks/Python.framework/Versions/3.7/lib/python3.7/site-packages/sqlalchemy/engine/base.py", line 1107, in _execute_clauseelement
    distilled_params,
  File "/Library/Frameworks/Python.framework/Versions/3.7/lib/python3.7/site-packages/sqlalchemy/engine/base.py", line 1253, in _execute_context
    e, statement, parameters, cursor, context
  File "/Library/Frameworks/Python.framework/Versions/3.7/lib/python3.7/site-packages/sqlalchemy/engine/base.py", line 1473, in _handle_dbapi_exception
    util.raise_from_cause(sqlalchemy_exception, exc_info)
  File "/Library/Frameworks/Python.framework/Versions/3.7/lib/python3.7/site-packages/sqlalchemy/util/compat.py", line 398, in raise_from_cause
    reraise(type(exception), exception, tb=exc_tb, cause=cause)
  File "/Library/Frameworks/Python.framework/Versions/3.7/lib/python3.7/site-packages/sqlalchemy/util/compat.py", line 152, in reraise
    raise value.with_traceback(tb)
  File "/Library/Frameworks/Python.framework/Versions/3.7/lib/python3.7/site-packages/sqlalchemy/engine/base.py", line 1249, in _execute_context
    cursor, statement, parameters, context
  File "/Library/Frameworks/Python.framework/Versions/3.7/lib/python3.7/site-packages/sqlalchemy/engine/default.py", line 552, in do_execute
    cursor.execute(statement, parameters)
sqlalchemy.exc.OperationalError: (sqlite3.OperationalError) no such table: user
[SQL: SELECT user.id AS user_id, user.username AS user_username, user.email AS user_email, user.password_hash AS user_password_hash, user.about_me AS user_about_me, user.last_seen AS user_last_seen, user.token AS user_token, user.token_expiration AS user_token_expiration, user.last_message_read_time AS user_last_message_read_time 
FROM user 
WHERE user.id = ?]
[parameters: (1,)]
(Background on this error at: http://sqlalche.me/e/e3q8)
2020-02-10 17:22:14,865 INFO: Microblog startup [in /Users/yhz/Desktop/pypy/Flask_Learn/app/__init__.py:104]
2020-02-10 17:22:15,823 ERROR: Exception on /explore [GET] [in /Library/Frameworks/Python.framework/Versions/3.7/lib/python3.7/site-packages/flask/app.py:1761]
Traceback (most recent call last):
  File "/Library/Frameworks/Python.framework/Versions/3.7/lib/python3.7/site-packages/sqlalchemy/engine/base.py", line 1249, in _execute_context
    cursor, statement, parameters, context
  File "/Library/Frameworks/Python.framework/Versions/3.7/lib/python3.7/site-packages/sqlalchemy/engine/default.py", line 552, in do_execute
    cursor.execute(statement, parameters)
sqlite3.OperationalError: no such table: user

The above exception was the direct cause of the following exception:

Traceback (most recent call last):
  File "/Library/Frameworks/Python.framework/Versions/3.7/lib/python3.7/site-packages/flask/app.py", line 2292, in wsgi_app
    response = self.full_dispatch_request()
  File "/Library/Frameworks/Python.framework/Versions/3.7/lib/python3.7/site-packages/flask/app.py", line 1815, in full_dispatch_request
    rv = self.handle_user_exception(e)
  File "/Library/Frameworks/Python.framework/Versions/3.7/lib/python3.7/site-packages/flask/app.py", line 1718, in handle_user_exception
    reraise(exc_type, exc_value, tb)
  File "/Library/Frameworks/Python.framework/Versions/3.7/lib/python3.7/site-packages/flask/_compat.py", line 35, in reraise
    raise value
  File "/Library/Frameworks/Python.framework/Versions/3.7/lib/python3.7/site-packages/flask/app.py", line 1811, in full_dispatch_request
    rv = self.preprocess_request()
  File "/Library/Frameworks/Python.framework/Versions/3.7/lib/python3.7/site-packages/flask/app.py", line 2087, in preprocess_request
    rv = func()
  File "/Users/yhz/Desktop/pypy/Flask_Learn/app/main/routes.py", line 21, in before_request
    if current_user.is_authenticated:
  File "/Library/Frameworks/Python.framework/Versions/3.7/lib/python3.7/site-packages/werkzeug/local.py", line 347, in __getattr__
    return getattr(self._get_current_object(), name)
  File "/Library/Frameworks/Python.framework/Versions/3.7/lib/python3.7/site-packages/werkzeug/local.py", line 306, in _get_current_object
    return self.__local()
  File "/Library/Frameworks/Python.framework/Versions/3.7/lib/python3.7/site-packages/flask_login/utils.py", line 26, in <lambda>
    current_user = LocalProxy(lambda: _get_user())
  File "/Library/Frameworks/Python.framework/Versions/3.7/lib/python3.7/site-packages/flask_login/utils.py", line 335, in _get_user
    current_app.login_manager._load_user()
  File "/Library/Frameworks/Python.framework/Versions/3.7/lib/python3.7/site-packages/flask_login/login_manager.py", line 359, in _load_user
    return self.reload_user()
  File "/Library/Frameworks/Python.framework/Versions/3.7/lib/python3.7/site-packages/flask_login/login_manager.py", line 321, in reload_user
    user = self.user_callback(user_id)
  File "/Users/yhz/Desktop/pypy/Flask_Learn/app/models.py", line 269, in load_user
    return User.query.get(int(id))  # 传入字符串类型，使用数字ID的数据库需要将字符串转换为整数。
  File "/Library/Frameworks/Python.framework/Versions/3.7/lib/python3.7/site-packages/sqlalchemy/orm/query.py", line 959, in get
    return self._get_impl(ident, loading.load_on_pk_identity)
  File "/Library/Frameworks/Python.framework/Versions/3.7/lib/python3.7/site-packages/sqlalchemy/orm/query.py", line 1069, in _get_impl
    return db_load_fn(self, primary_key_identity)
  File "/Library/Frameworks/Python.framework/Versions/3.7/lib/python3.7/site-packages/sqlalchemy/orm/loading.py", line 282, in load_on_pk_identity
    return q.one()
  File "/Library/Frameworks/Python.framework/Versions/3.7/lib/python3.7/site-packages/sqlalchemy/orm/query.py", line 3292, in one
    ret = self.one_or_none()
  File "/Library/Frameworks/Python.framework/Versions/3.7/lib/python3.7/site-packages/sqlalchemy/orm/query.py", line 3261, in one_or_none
    ret = list(self)
  File "/Library/Frameworks/Python.framework/Versions/3.7/lib/python3.7/site-packages/sqlalchemy/orm/query.py", line 3334, in __iter__
    return self._execute_and_instances(context)
  File "/Library/Frameworks/Python.framework/Versions/3.7/lib/python3.7/site-packages/sqlalchemy/orm/query.py", line 3359, in _execute_and_instances
    result = conn.execute(querycontext.statement, self._params)
  File "/Library/Frameworks/Python.framework/Versions/3.7/lib/python3.7/site-packages/sqlalchemy/engine/base.py", line 988, in execute
    return meth(self, multiparams, params)
  File "/Library/Frameworks/Python.framework/Versions/3.7/lib/python3.7/site-packages/sqlalchemy/sql/elements.py", line 287, in _execute_on_connection
    return connection._execute_clauseelement(self, multiparams, params)
  File "/Library/Frameworks/Python.framework/Versions/3.7/lib/python3.7/site-packages/sqlalchemy/engine/base.py", line 1107, in _execute_clauseelement
    distilled_params,
  File "/Library/Frameworks/Python.framework/Versions/3.7/lib/python3.7/site-packages/sqlalchemy/engine/base.py", line 1253, in _execute_context
    e, statement, parameters, cursor, context
  File "/Library/Frameworks/Python.framework/Versions/3.7/lib/python3.7/site-packages/sqlalchemy/engine/base.py", line 1473, in _handle_dbapi_exception
    util.raise_from_cause(sqlalchemy_exception, exc_info)
  File "/Library/Frameworks/Python.framework/Versions/3.7/lib/python3.7/site-packages/sqlalchemy/util/compat.py", line 398, in raise_from_cause
    reraise(type(exception), exception, tb=exc_tb, cause=cause)
  File "/Library/Frameworks/Python.framework/Versions/3.7/lib/python3.7/site-packages/sqlalchemy/util/compat.py", line 152, in reraise
    raise value.with_traceback(tb)
  File "/Library/Frameworks/Python.framework/Versions/3.7/lib/python3.7/site-packages/sqlalchemy/engine/base.py", line 1249, in _execute_context
    cursor, statement, parameters, context
  File "/Library/Frameworks/Python.framework/Versions/3.7/lib/python3.7/site-packages/sqlalchemy/engine/default.py", line 552, in do_execute
    cursor.execute(statement, parameters)
sqlalchemy.exc.OperationalError: (sqlite3.OperationalError) no such table: user
[SQL: SELECT user.id AS user_id, user.username AS user_username, user.email AS user_email, user.password_hash AS user_password_hash, user.about_me AS user_about_me, user.last_seen AS user_last_seen, user.token AS user_token, user.token_expiration AS user_token_expiration, user.last_message_read_time AS user_last_message_read_time 
FROM user 
WHERE user.id = ?]
[parameters: (1,)]
(Background on this error at: http://sqlalche.me/e/e3q8)
2020-02-10 17:22:16,540 ERROR: Exception on /explore [GET] [in /Library/Frameworks/Python.framework/Versions/3.7/lib/python3.7/site-packages/flask/app.py:1761]
Traceback (most recent call last):
  File "/Library/Frameworks/Python.framework/Versions/3.7/lib/python3.7/site-packages/sqlalchemy/engine/base.py", line 1249, in _execute_context
    cursor, statement, parameters, context
  File "/Library/Frameworks/Python.framework/Versions/3.7/lib/python3.7/site-packages/sqlalchemy/engine/default.py", line 552, in do_execute
    cursor.execute(statement, parameters)
sqlite3.OperationalError: no such table: user

The above exception was the direct cause of the following exception:

Traceback (most recent call last):
  File "/Library/Frameworks/Python.framework/Versions/3.7/lib/python3.7/site-packages/flask/app.py", line 2292, in wsgi_app
    response = self.full_dispatch_request()
  File "/Library/Frameworks/Python.framework/Versions/3.7/lib/python3.7/site-packages/flask/app.py", line 1815, in full_dispatch_request
    rv = self.handle_user_exception(e)
  File "/Library/Frameworks/Python.framework/Versions/3.7/lib/python3.7/site-packages/flask/app.py", line 1718, in handle_user_exception
    reraise(exc_type, exc_value, tb)
  File "/Library/Frameworks/Python.framework/Versions/3.7/lib/python3.7/site-packages/flask/_compat.py", line 35, in reraise
    raise value
  File "/Library/Frameworks/Python.framework/Versions/3.7/lib/python3.7/site-packages/flask/app.py", line 1811, in full_dispatch_request
    rv = self.preprocess_request()
  File "/Library/Frameworks/Python.framework/Versions/3.7/lib/python3.7/site-packages/flask/app.py", line 2087, in preprocess_request
    rv = func()
  File "/Users/yhz/Desktop/pypy/Flask_Learn/app/main/routes.py", line 21, in before_request
    if current_user.is_authenticated:
  File "/Library/Frameworks/Python.framework/Versions/3.7/lib/python3.7/site-packages/werkzeug/local.py", line 347, in __getattr__
    return getattr(self._get_current_object(), name)
  File "/Library/Frameworks/Python.framework/Versions/3.7/lib/python3.7/site-packages/werkzeug/local.py", line 306, in _get_current_object
    return self.__local()
  File "/Library/Frameworks/Python.framework/Versions/3.7/lib/python3.7/site-packages/flask_login/utils.py", line 26, in <lambda>
    current_user = LocalProxy(lambda: _get_user())
  File "/Library/Frameworks/Python.framework/Versions/3.7/lib/python3.7/site-packages/flask_login/utils.py", line 335, in _get_user
    current_app.login_manager._load_user()
  File "/Library/Frameworks/Python.framework/Versions/3.7/lib/python3.7/site-packages/flask_login/login_manager.py", line 359, in _load_user
    return self.reload_user()
  File "/Library/Frameworks/Python.framework/Versions/3.7/lib/python3.7/site-packages/flask_login/login_manager.py", line 321, in reload_user
    user = self.user_callback(user_id)
  File "/Users/yhz/Desktop/pypy/Flask_Learn/app/models.py", line 269, in load_user
    return User.query.get(int(id))  # 传入字符串类型，使用数字ID的数据库需要将字符串转换为整数。
  File "/Library/Frameworks/Python.framework/Versions/3.7/lib/python3.7/site-packages/sqlalchemy/orm/query.py", line 959, in get
    return self._get_impl(ident, loading.load_on_pk_identity)
  File "/Library/Frameworks/Python.framework/Versions/3.7/lib/python3.7/site-packages/sqlalchemy/orm/query.py", line 1069, in _get_impl
    return db_load_fn(self, primary_key_identity)
  File "/Library/Frameworks/Python.framework/Versions/3.7/lib/python3.7/site-packages/sqlalchemy/orm/loading.py", line 282, in load_on_pk_identity
    return q.one()
  File "/Library/Frameworks/Python.framework/Versions/3.7/lib/python3.7/site-packages/sqlalchemy/orm/query.py", line 3292, in one
    ret = self.one_or_none()
  File "/Library/Frameworks/Python.framework/Versions/3.7/lib/python3.7/site-packages/sqlalchemy/orm/query.py", line 3261, in one_or_none
    ret = list(self)
  File "/Library/Frameworks/Python.framework/Versions/3.7/lib/python3.7/site-packages/sqlalchemy/orm/query.py", line 3334, in __iter__
    return self._execute_and_instances(context)
  File "/Library/Frameworks/Python.framework/Versions/3.7/lib/python3.7/site-packages/sqlalchemy/orm/query.py", line 3359, in _execute_and_instances
    result = conn.execute(querycontext.statement, self._params)
  File "/Library/Frameworks/Python.framework/Versions/3.7/lib/python3.7/site-packages/sqlalchemy/engine/base.py", line 988, in execute
    return meth(self, multiparams, params)
  File "/Library/Frameworks/Python.framework/Versions/3.7/lib/python3.7/site-packages/sqlalchemy/sql/elements.py", line 287, in _execute_on_connection
    return connection._execute_clauseelement(self, multiparams, params)
  File "/Library/Frameworks/Python.framework/Versions/3.7/lib/python3.7/site-packages/sqlalchemy/engine/base.py", line 1107, in _execute_clauseelement
    distilled_params,
  File "/Library/Frameworks/Python.framework/Versions/3.7/lib/python3.7/site-packages/sqlalchemy/engine/base.py", line 1253, in _execute_context
    e, statement, parameters, cursor, context
  File "/Library/Frameworks/Python.framework/Versions/3.7/lib/python3.7/site-packages/sqlalchemy/engine/base.py", line 1473, in _handle_dbapi_exception
    util.raise_from_cause(sqlalchemy_exception, exc_info)
  File "/Library/Frameworks/Python.framework/Versions/3.7/lib/python3.7/site-packages/sqlalchemy/util/compat.py", line 398, in raise_from_cause
    reraise(type(exception), exception, tb=exc_tb, cause=cause)
  File "/Library/Frameworks/Python.framework/Versions/3.7/lib/python3.7/site-packages/sqlalchemy/util/compat.py", line 152, in reraise
    raise value.with_traceback(tb)
  File "/Library/Frameworks/Python.framework/Versions/3.7/lib/python3.7/site-packages/sqlalchemy/engine/base.py", line 1249, in _execute_context
    cursor, statement, parameters, context
  File "/Library/Frameworks/Python.framework/Versions/3.7/lib/python3.7/site-packages/sqlalchemy/engine/default.py", line 552, in do_execute
    cursor.execute(statement, parameters)
sqlalchemy.exc.OperationalError: (sqlite3.OperationalError) no such table: user
[SQL: SELECT user.id AS user_id, user.username AS user_username, user.email AS user_email, user.password_hash AS user_password_hash, user.about_me AS user_about_me, user.last_seen AS user_last_seen, user.token AS user_token, user.token_expiration AS user_token_expiration, user.last_message_read_time AS user_last_message_read_time 
FROM user 
WHERE user.id = ?]
[parameters: (1,)]
(Background on this error at: http://sqlalche.me/e/e3q8)
2020-02-10 17:22:17,784 ERROR: Exception on /explore [GET] [in /Library/Frameworks/Python.framework/Versions/3.7/lib/python3.7/site-packages/flask/app.py:1761]
Traceback (most recent call last):
  File "/Library/Frameworks/Python.framework/Versions/3.7/lib/python3.7/site-packages/sqlalchemy/engine/base.py", line 1249, in _execute_context
    cursor, statement, parameters, context
  File "/Library/Frameworks/Python.framework/Versions/3.7/lib/python3.7/site-packages/sqlalchemy/engine/default.py", line 552, in do_execute
    cursor.execute(statement, parameters)
sqlite3.OperationalError: no such table: user

The above exception was the direct cause of the following exception:

Traceback (most recent call last):
  File "/Library/Frameworks/Python.framework/Versions/3.7/lib/python3.7/site-packages/flask/app.py", line 2292, in wsgi_app
    response = self.full_dispatch_request()
  File "/Library/Frameworks/Python.framework/Versions/3.7/lib/python3.7/site-packages/flask/app.py", line 1815, in full_dispatch_request
    rv = self.handle_user_exception(e)
  File "/Library/Frameworks/Python.framework/Versions/3.7/lib/python3.7/site-packages/flask/app.py", line 1718, in handle_user_exception
    reraise(exc_type, exc_value, tb)
  File "/Library/Frameworks/Python.framework/Versions/3.7/lib/python3.7/site-packages/flask/_compat.py", line 35, in reraise
    raise value
  File "/Library/Frameworks/Python.framework/Versions/3.7/lib/python3.7/site-packages/flask/app.py", line 1811, in full_dispatch_request
    rv = self.preprocess_request()
  File "/Library/Frameworks/Python.framework/Versions/3.7/lib/python3.7/site-packages/flask/app.py", line 2087, in preprocess_request
    rv = func()
  File "/Users/yhz/Desktop/pypy/Flask_Learn/app/main/routes.py", line 21, in before_request
    if current_user.is_authenticated:
  File "/Library/Frameworks/Python.framework/Versions/3.7/lib/python3.7/site-packages/werkzeug/local.py", line 347, in __getattr__
    return getattr(self._get_current_object(), name)
  File "/Library/Frameworks/Python.framework/Versions/3.7/lib/python3.7/site-packages/werkzeug/local.py", line 306, in _get_current_object
    return self.__local()
  File "/Library/Frameworks/Python.framework/Versions/3.7/lib/python3.7/site-packages/flask_login/utils.py", line 26, in <lambda>
    current_user = LocalProxy(lambda: _get_user())
  File "/Library/Frameworks/Python.framework/Versions/3.7/lib/python3.7/site-packages/flask_login/utils.py", line 335, in _get_user
    current_app.login_manager._load_user()
  File "/Library/Frameworks/Python.framework/Versions/3.7/lib/python3.7/site-packages/flask_login/login_manager.py", line 359, in _load_user
    return self.reload_user()
  File "/Library/Frameworks/Python.framework/Versions/3.7/lib/python3.7/site-packages/flask_login/login_manager.py", line 321, in reload_user
    user = self.user_callback(user_id)
  File "/Users/yhz/Desktop/pypy/Flask_Learn/app/models.py", line 269, in load_user
    return User.query.get(int(id))  # 传入字符串类型，使用数字ID的数据库需要将字符串转换为整数。
  File "/Library/Frameworks/Python.framework/Versions/3.7/lib/python3.7/site-packages/sqlalchemy/orm/query.py", line 959, in get
    return self._get_impl(ident, loading.load_on_pk_identity)
  File "/Library/Frameworks/Python.framework/Versions/3.7/lib/python3.7/site-packages/sqlalchemy/orm/query.py", line 1069, in _get_impl
    return db_load_fn(self, primary_key_identity)
  File "/Library/Frameworks/Python.framework/Versions/3.7/lib/python3.7/site-packages/sqlalchemy/orm/loading.py", line 282, in load_on_pk_identity
    return q.one()
  File "/Library/Frameworks/Python.framework/Versions/3.7/lib/python3.7/site-packages/sqlalchemy/orm/query.py", line 3292, in one
    ret = self.one_or_none()
  File "/Library/Frameworks/Python.framework/Versions/3.7/lib/python3.7/site-packages/sqlalchemy/orm/query.py", line 3261, in one_or_none
    ret = list(self)
  File "/Library/Frameworks/Python.framework/Versions/3.7/lib/python3.7/site-packages/sqlalchemy/orm/query.py", line 3334, in __iter__
    return self._execute_and_instances(context)
  File "/Library/Frameworks/Python.framework/Versions/3.7/lib/python3.7/site-packages/sqlalchemy/orm/query.py", line 3359, in _execute_and_instances
    result = conn.execute(querycontext.statement, self._params)
  File "/Library/Frameworks/Python.framework/Versions/3.7/lib/python3.7/site-packages/sqlalchemy/engine/base.py", line 988, in execute
    return meth(self, multiparams, params)
  File "/Library/Frameworks/Python.framework/Versions/3.7/lib/python3.7/site-packages/sqlalchemy/sql/elements.py", line 287, in _execute_on_connection
    return connection._execute_clauseelement(self, multiparams, params)
  File "/Library/Frameworks/Python.framework/Versions/3.7/lib/python3.7/site-packages/sqlalchemy/engine/base.py", line 1107, in _execute_clauseelement
    distilled_params,
  File "/Library/Frameworks/Python.framework/Versions/3.7/lib/python3.7/site-packages/sqlalchemy/engine/base.py", line 1253, in _execute_context
    e, statement, parameters, cursor, context
  File "/Library/Frameworks/Python.framework/Versions/3.7/lib/python3.7/site-packages/sqlalchemy/engine/base.py", line 1473, in _handle_dbapi_exception
    util.raise_from_cause(sqlalchemy_exception, exc_info)
  File "/Library/Frameworks/Python.framework/Versions/3.7/lib/python3.7/site-packages/sqlalchemy/util/compat.py", line 398, in raise_from_cause
    reraise(type(exception), exception, tb=exc_tb, cause=cause)
  File "/Library/Frameworks/Python.framework/Versions/3.7/lib/python3.7/site-packages/sqlalchemy/util/compat.py", line 152, in reraise
    raise value.with_traceback(tb)
  File "/Library/Frameworks/Python.framework/Versions/3.7/lib/python3.7/site-packages/sqlalchemy/engine/base.py", line 1249, in _execute_context
    cursor, statement, parameters, context
  File "/Library/Frameworks/Python.framework/Versions/3.7/lib/python3.7/site-packages/sqlalchemy/engine/default.py", line 552, in do_execute
    cursor.execute(statement, parameters)
sqlalchemy.exc.OperationalError: (sqlite3.OperationalError) no such table: user
[SQL: SELECT user.id AS user_id, user.username AS user_username, user.email AS user_email, user.password_hash AS user_password_hash, user.about_me AS user_about_me, user.last_seen AS user_last_seen, user.token AS user_token, user.token_expiration AS user_token_expiration, user.last_message_read_time AS user_last_message_read_time 
FROM user 
WHERE user.id = ?]
[parameters: (1,)]
(Background on this error at: http://sqlalche.me/e/e3q8)
2020-02-10 17:22:19,916 ERROR: Exception on /messages [GET] [in /Library/Frameworks/Python.framework/Versions/3.7/lib/python3.7/site-packages/flask/app.py:1761]
Traceback (most recent call last):
  File "/Library/Frameworks/Python.framework/Versions/3.7/lib/python3.7/site-packages/sqlalchemy/engine/base.py", line 1249, in _execute_context
    cursor, statement, parameters, context
  File "/Library/Frameworks/Python.framework/Versions/3.7/lib/python3.7/site-packages/sqlalchemy/engine/default.py", line 552, in do_execute
    cursor.execute(statement, parameters)
sqlite3.OperationalError: no such table: user

The above exception was the direct cause of the following exception:

Traceback (most recent call last):
  File "/Library/Frameworks/Python.framework/Versions/3.7/lib/python3.7/site-packages/flask/app.py", line 2292, in wsgi_app
    response = self.full_dispatch_request()
  File "/Library/Frameworks/Python.framework/Versions/3.7/lib/python3.7/site-packages/flask/app.py", line 1815, in full_dispatch_request
    rv = self.handle_user_exception(e)
  File "/Library/Frameworks/Python.framework/Versions/3.7/lib/python3.7/site-packages/flask/app.py", line 1718, in handle_user_exception
    reraise(exc_type, exc_value, tb)
  File "/Library/Frameworks/Python.framework/Versions/3.7/lib/python3.7/site-packages/flask/_compat.py", line 35, in reraise
    raise value
  File "/Library/Frameworks/Python.framework/Versions/3.7/lib/python3.7/site-packages/flask/app.py", line 1811, in full_dispatch_request
    rv = self.preprocess_request()
  File "/Library/Frameworks/Python.framework/Versions/3.7/lib/python3.7/site-packages/flask/app.py", line 2087, in preprocess_request
    rv = func()
  File "/Users/yhz/Desktop/pypy/Flask_Learn/app/main/routes.py", line 21, in before_request
    if current_user.is_authenticated:
  File "/Library/Frameworks/Python.framework/Versions/3.7/lib/python3.7/site-packages/werkzeug/local.py", line 347, in __getattr__
    return getattr(self._get_current_object(), name)
  File "/Library/Frameworks/Python.framework/Versions/3.7/lib/python3.7/site-packages/werkzeug/local.py", line 306, in _get_current_object
    return self.__local()
  File "/Library/Frameworks/Python.framework/Versions/3.7/lib/python3.7/site-packages/flask_login/utils.py", line 26, in <lambda>
    current_user = LocalProxy(lambda: _get_user())
  File "/Library/Frameworks/Python.framework/Versions/3.7/lib/python3.7/site-packages/flask_login/utils.py", line 335, in _get_user
    current_app.login_manager._load_user()
  File "/Library/Frameworks/Python.framework/Versions/3.7/lib/python3.7/site-packages/flask_login/login_manager.py", line 359, in _load_user
    return self.reload_user()
  File "/Library/Frameworks/Python.framework/Versions/3.7/lib/python3.7/site-packages/flask_login/login_manager.py", line 321, in reload_user
    user = self.user_callback(user_id)
  File "/Users/yhz/Desktop/pypy/Flask_Learn/app/models.py", line 269, in load_user
    return User.query.get(int(id))  # 传入字符串类型，使用数字ID的数据库需要将字符串转换为整数。
  File "/Library/Frameworks/Python.framework/Versions/3.7/lib/python3.7/site-packages/sqlalchemy/orm/query.py", line 959, in get
    return self._get_impl(ident, loading.load_on_pk_identity)
  File "/Library/Frameworks/Python.framework/Versions/3.7/lib/python3.7/site-packages/sqlalchemy/orm/query.py", line 1069, in _get_impl
    return db_load_fn(self, primary_key_identity)
  File "/Library/Frameworks/Python.framework/Versions/3.7/lib/python3.7/site-packages/sqlalchemy/orm/loading.py", line 282, in load_on_pk_identity
    return q.one()
  File "/Library/Frameworks/Python.framework/Versions/3.7/lib/python3.7/site-packages/sqlalchemy/orm/query.py", line 3292, in one
    ret = self.one_or_none()
  File "/Library/Frameworks/Python.framework/Versions/3.7/lib/python3.7/site-packages/sqlalchemy/orm/query.py", line 3261, in one_or_none
    ret = list(self)
  File "/Library/Frameworks/Python.framework/Versions/3.7/lib/python3.7/site-packages/sqlalchemy/orm/query.py", line 3334, in __iter__
    return self._execute_and_instances(context)
  File "/Library/Frameworks/Python.framework/Versions/3.7/lib/python3.7/site-packages/sqlalchemy/orm/query.py", line 3359, in _execute_and_instances
    result = conn.execute(querycontext.statement, self._params)
  File "/Library/Frameworks/Python.framework/Versions/3.7/lib/python3.7/site-packages/sqlalchemy/engine/base.py", line 988, in execute
    return meth(self, multiparams, params)
  File "/Library/Frameworks/Python.framework/Versions/3.7/lib/python3.7/site-packages/sqlalchemy/sql/elements.py", line 287, in _execute_on_connection
    return connection._execute_clauseelement(self, multiparams, params)
  File "/Library/Frameworks/Python.framework/Versions/3.7/lib/python3.7/site-packages/sqlalchemy/engine/base.py", line 1107, in _execute_clauseelement
    distilled_params,
  File "/Library/Frameworks/Python.framework/Versions/3.7/lib/python3.7/site-packages/sqlalchemy/engine/base.py", line 1253, in _execute_context
    e, statement, parameters, cursor, context
  File "/Library/Frameworks/Python.framework/Versions/3.7/lib/python3.7/site-packages/sqlalchemy/engine/base.py", line 1473, in _handle_dbapi_exception
    util.raise_from_cause(sqlalchemy_exception, exc_info)
  File "/Library/Frameworks/Python.framework/Versions/3.7/lib/python3.7/site-packages/sqlalchemy/util/compat.py", line 398, in raise_from_cause
    reraise(type(exception), exception, tb=exc_tb, cause=cause)
  File "/Library/Frameworks/Python.framework/Versions/3.7/lib/python3.7/site-packages/sqlalchemy/util/compat.py", line 152, in reraise
    raise value.with_traceback(tb)
  File "/Library/Frameworks/Python.framework/Versions/3.7/lib/python3.7/site-packages/sqlalchemy/engine/base.py", line 1249, in _execute_context
    cursor, statement, parameters, context
  File "/Library/Frameworks/Python.framework/Versions/3.7/lib/python3.7/site-packages/sqlalchemy/engine/default.py", line 552, in do_execute
    cursor.execute(statement, parameters)
sqlalchemy.exc.OperationalError: (sqlite3.OperationalError) no such table: user
[SQL: SELECT user.id AS user_id, user.username AS user_username, user.email AS user_email, user.password_hash AS user_password_hash, user.about_me AS user_about_me, user.last_seen AS user_last_seen, user.token AS user_token, user.token_expiration AS user_token_expiration, user.last_message_read_time AS user_last_message_read_time 
FROM user 
WHERE user.id = ?]
[parameters: (1,)]
(Background on this error at: http://sqlalche.me/e/e3q8)
2020-02-10 17:24:54,808 ERROR: Exception on /messages [GET] [in /Library/Frameworks/Python.framework/Versions/3.7/lib/python3.7/site-packages/flask/app.py:1761]
Traceback (most recent call last):
  File "/Library/Frameworks/Python.framework/Versions/3.7/lib/python3.7/site-packages/sqlalchemy/engine/base.py", line 1249, in _execute_context
    cursor, statement, parameters, context
  File "/Library/Frameworks/Python.framework/Versions/3.7/lib/python3.7/site-packages/sqlalchemy/engine/default.py", line 552, in do_execute
    cursor.execute(statement, parameters)
sqlite3.OperationalError: no such table: user

The above exception was the direct cause of the following exception:

Traceback (most recent call last):
  File "/Library/Frameworks/Python.framework/Versions/3.7/lib/python3.7/site-packages/flask/app.py", line 2292, in wsgi_app
    response = self.full_dispatch_request()
  File "/Library/Frameworks/Python.framework/Versions/3.7/lib/python3.7/site-packages/flask/app.py", line 1815, in full_dispatch_request
    rv = self.handle_user_exception(e)
  File "/Library/Frameworks/Python.framework/Versions/3.7/lib/python3.7/site-packages/flask/app.py", line 1718, in handle_user_exception
    reraise(exc_type, exc_value, tb)
  File "/Library/Frameworks/Python.framework/Versions/3.7/lib/python3.7/site-packages/flask/_compat.py", line 35, in reraise
    raise value
  File "/Library/Frameworks/Python.framework/Versions/3.7/lib/python3.7/site-packages/flask/app.py", line 1811, in full_dispatch_request
    rv = self.preprocess_request()
  File "/Library/Frameworks/Python.framework/Versions/3.7/lib/python3.7/site-packages/flask/app.py", line 2087, in preprocess_request
    rv = func()
  File "/Users/yhz/Desktop/pypy/Flask_Learn/app/main/routes.py", line 21, in before_request
    if current_user.is_authenticated:
  File "/Library/Frameworks/Python.framework/Versions/3.7/lib/python3.7/site-packages/werkzeug/local.py", line 347, in __getattr__
    return getattr(self._get_current_object(), name)
  File "/Library/Frameworks/Python.framework/Versions/3.7/lib/python3.7/site-packages/werkzeug/local.py", line 306, in _get_current_object
    return self.__local()
  File "/Library/Frameworks/Python.framework/Versions/3.7/lib/python3.7/site-packages/flask_login/utils.py", line 26, in <lambda>
    current_user = LocalProxy(lambda: _get_user())
  File "/Library/Frameworks/Python.framework/Versions/3.7/lib/python3.7/site-packages/flask_login/utils.py", line 335, in _get_user
    current_app.login_manager._load_user()
  File "/Library/Frameworks/Python.framework/Versions/3.7/lib/python3.7/site-packages/flask_login/login_manager.py", line 359, in _load_user
    return self.reload_user()
  File "/Library/Frameworks/Python.framework/Versions/3.7/lib/python3.7/site-packages/flask_login/login_manager.py", line 321, in reload_user
    user = self.user_callback(user_id)
  File "/Users/yhz/Desktop/pypy/Flask_Learn/app/models.py", line 269, in load_user
    return User.query.get(int(id))  # 传入字符串类型，使用数字ID的数据库需要将字符串转换为整数。
  File "/Library/Frameworks/Python.framework/Versions/3.7/lib/python3.7/site-packages/sqlalchemy/orm/query.py", line 959, in get
    return self._get_impl(ident, loading.load_on_pk_identity)
  File "/Library/Frameworks/Python.framework/Versions/3.7/lib/python3.7/site-packages/sqlalchemy/orm/query.py", line 1069, in _get_impl
    return db_load_fn(self, primary_key_identity)
  File "/Library/Frameworks/Python.framework/Versions/3.7/lib/python3.7/site-packages/sqlalchemy/orm/loading.py", line 282, in load_on_pk_identity
    return q.one()
  File "/Library/Frameworks/Python.framework/Versions/3.7/lib/python3.7/site-packages/sqlalchemy/orm/query.py", line 3292, in one
    ret = self.one_or_none()
  File "/Library/Frameworks/Python.framework/Versions/3.7/lib/python3.7/site-packages/sqlalchemy/orm/query.py", line 3261, in one_or_none
    ret = list(self)
  File "/Library/Frameworks/Python.framework/Versions/3.7/lib/python3.7/site-packages/sqlalchemy/orm/query.py", line 3334, in __iter__
    return self._execute_and_instances(context)
  File "/Library/Frameworks/Python.framework/Versions/3.7/lib/python3.7/site-packages/sqlalchemy/orm/query.py", line 3359, in _execute_and_instances
    result = conn.execute(querycontext.statement, self._params)
  File "/Library/Frameworks/Python.framework/Versions/3.7/lib/python3.7/site-packages/sqlalchemy/engine/base.py", line 988, in execute
    return meth(self, multiparams, params)
  File "/Library/Frameworks/Python.framework/Versions/3.7/lib/python3.7/site-packages/sqlalchemy/sql/elements.py", line 287, in _execute_on_connection
    return connection._execute_clauseelement(self, multiparams, params)
  File "/Library/Frameworks/Python.framework/Versions/3.7/lib/python3.7/site-packages/sqlalchemy/engine/base.py", line 1107, in _execute_clauseelement
    distilled_params,
  File "/Library/Frameworks/Python.framework/Versions/3.7/lib/python3.7/site-packages/sqlalchemy/engine/base.py", line 1253, in _execute_context
    e, statement, parameters, cursor, context
  File "/Library/Frameworks/Python.framework/Versions/3.7/lib/python3.7/site-packages/sqlalchemy/engine/base.py", line 1473, in _handle_dbapi_exception
    util.raise_from_cause(sqlalchemy_exception, exc_info)
  File "/Library/Frameworks/Python.framework/Versions/3.7/lib/python3.7/site-packages/sqlalchemy/util/compat.py", line 398, in raise_from_cause
    reraise(type(exception), exception, tb=exc_tb, cause=cause)
  File "/Library/Frameworks/Python.framework/Versions/3.7/lib/python3.7/site-packages/sqlalchemy/util/compat.py", line 152, in reraise
    raise value.with_traceback(tb)
  File "/Library/Frameworks/Python.framework/Versions/3.7/lib/python3.7/site-packages/sqlalchemy/engine/base.py", line 1249, in _execute_context
    cursor, statement, parameters, context
  File "/Library/Frameworks/Python.framework/Versions/3.7/lib/python3.7/site-packages/sqlalchemy/engine/default.py", line 552, in do_execute
    cursor.execute(statement, parameters)
sqlalchemy.exc.OperationalError: (sqlite3.OperationalError) no such table: user
[SQL: SELECT user.id AS user_id, user.username AS user_username, user.email AS user_email, user.password_hash AS user_password_hash, user.about_me AS user_about_me, user.last_seen AS user_last_seen, user.token AS user_token, user.token_expiration AS user_token_expiration, user.last_message_read_time AS user_last_message_read_time 
FROM user 
WHERE user.id = ?]
[parameters: (1,)]
(Background on this error at: http://sqlalche.me/e/e3q8)
2020-02-10 17:24:54,922 ERROR: Exception on /favicon.ico [GET] [in /Library/Frameworks/Python.framework/Versions/3.7/lib/python3.7/site-packages/flask/app.py:1761]
Traceback (most recent call last):
  File "/Library/Frameworks/Python.framework/Versions/3.7/lib/python3.7/site-packages/sqlalchemy/engine/base.py", line 1249, in _execute_context
    cursor, statement, parameters, context
  File "/Library/Frameworks/Python.framework/Versions/3.7/lib/python3.7/site-packages/sqlalchemy/engine/default.py", line 552, in do_execute
    cursor.execute(statement, parameters)
sqlite3.OperationalError: no such table: user

The above exception was the direct cause of the following exception:

Traceback (most recent call last):
  File "/Library/Frameworks/Python.framework/Versions/3.7/lib/python3.7/site-packages/flask/app.py", line 2292, in wsgi_app
    response = self.full_dispatch_request()
  File "/Library/Frameworks/Python.framework/Versions/3.7/lib/python3.7/site-packages/flask/app.py", line 1815, in full_dispatch_request
    rv = self.handle_user_exception(e)
  File "/Library/Frameworks/Python.framework/Versions/3.7/lib/python3.7/site-packages/flask/app.py", line 1718, in handle_user_exception
    reraise(exc_type, exc_value, tb)
  File "/Library/Frameworks/Python.framework/Versions/3.7/lib/python3.7/site-packages/flask/_compat.py", line 35, in reraise
    raise value
  File "/Library/Frameworks/Python.framework/Versions/3.7/lib/python3.7/site-packages/flask/app.py", line 1811, in full_dispatch_request
    rv = self.preprocess_request()
  File "/Library/Frameworks/Python.framework/Versions/3.7/lib/python3.7/site-packages/flask/app.py", line 2087, in preprocess_request
    rv = func()
  File "/Users/yhz/Desktop/pypy/Flask_Learn/app/main/routes.py", line 21, in before_request
    if current_user.is_authenticated:
  File "/Library/Frameworks/Python.framework/Versions/3.7/lib/python3.7/site-packages/werkzeug/local.py", line 347, in __getattr__
    return getattr(self._get_current_object(), name)
  File "/Library/Frameworks/Python.framework/Versions/3.7/lib/python3.7/site-packages/werkzeug/local.py", line 306, in _get_current_object
    return self.__local()
  File "/Library/Frameworks/Python.framework/Versions/3.7/lib/python3.7/site-packages/flask_login/utils.py", line 26, in <lambda>
    current_user = LocalProxy(lambda: _get_user())
  File "/Library/Frameworks/Python.framework/Versions/3.7/lib/python3.7/site-packages/flask_login/utils.py", line 335, in _get_user
    current_app.login_manager._load_user()
  File "/Library/Frameworks/Python.framework/Versions/3.7/lib/python3.7/site-packages/flask_login/login_manager.py", line 359, in _load_user
    return self.reload_user()
  File "/Library/Frameworks/Python.framework/Versions/3.7/lib/python3.7/site-packages/flask_login/login_manager.py", line 321, in reload_user
    user = self.user_callback(user_id)
  File "/Users/yhz/Desktop/pypy/Flask_Learn/app/models.py", line 269, in load_user
    return User.query.get(int(id))  # 传入字符串类型，使用数字ID的数据库需要将字符串转换为整数。
  File "/Library/Frameworks/Python.framework/Versions/3.7/lib/python3.7/site-packages/sqlalchemy/orm/query.py", line 959, in get
    return self._get_impl(ident, loading.load_on_pk_identity)
  File "/Library/Frameworks/Python.framework/Versions/3.7/lib/python3.7/site-packages/sqlalchemy/orm/query.py", line 1069, in _get_impl
    return db_load_fn(self, primary_key_identity)
  File "/Library/Frameworks/Python.framework/Versions/3.7/lib/python3.7/site-packages/sqlalchemy/orm/loading.py", line 282, in load_on_pk_identity
    return q.one()
  File "/Library/Frameworks/Python.framework/Versions/3.7/lib/python3.7/site-packages/sqlalchemy/orm/query.py", line 3292, in one
    ret = self.one_or_none()
  File "/Library/Frameworks/Python.framework/Versions/3.7/lib/python3.7/site-packages/sqlalchemy/orm/query.py", line 3261, in one_or_none
    ret = list(self)
  File "/Library/Frameworks/Python.framework/Versions/3.7/lib/python3.7/site-packages/sqlalchemy/orm/query.py", line 3334, in __iter__
    return self._execute_and_instances(context)
  File "/Library/Frameworks/Python.framework/Versions/3.7/lib/python3.7/site-packages/sqlalchemy/orm/query.py", line 3359, in _execute_and_instances
    result = conn.execute(querycontext.statement, self._params)
  File "/Library/Frameworks/Python.framework/Versions/3.7/lib/python3.7/site-packages/sqlalchemy/engine/base.py", line 988, in execute
    return meth(self, multiparams, params)
  File "/Library/Frameworks/Python.framework/Versions/3.7/lib/python3.7/site-packages/sqlalchemy/sql/elements.py", line 287, in _execute_on_connection
    return connection._execute_clauseelement(self, multiparams, params)
  File "/Library/Frameworks/Python.framework/Versions/3.7/lib/python3.7/site-packages/sqlalchemy/engine/base.py", line 1107, in _execute_clauseelement
    distilled_params,
  File "/Library/Frameworks/Python.framework/Versions/3.7/lib/python3.7/site-packages/sqlalchemy/engine/base.py", line 1253, in _execute_context
    e, statement, parameters, cursor, context
  File "/Library/Frameworks/Python.framework/Versions/3.7/lib/python3.7/site-packages/sqlalchemy/engine/base.py", line 1473, in _handle_dbapi_exception
    util.raise_from_cause(sqlalchemy_exception, exc_info)
  File "/Library/Frameworks/Python.framework/Versions/3.7/lib/python3.7/site-packages/sqlalchemy/util/compat.py", line 398, in raise_from_cause
    reraise(type(exception), exception, tb=exc_tb, cause=cause)
  File "/Library/Frameworks/Python.framework/Versions/3.7/lib/python3.7/site-packages/sqlalchemy/util/compat.py", line 152, in reraise
    raise value.with_traceback(tb)
  File "/Library/Frameworks/Python.framework/Versions/3.7/lib/python3.7/site-packages/sqlalchemy/engine/base.py", line 1249, in _execute_context
    cursor, statement, parameters, context
  File "/Library/Frameworks/Python.framework/Versions/3.7/lib/python3.7/site-packages/sqlalchemy/engine/default.py", line 552, in do_execute
    cursor.execute(statement, parameters)
sqlalchemy.exc.OperationalError: (sqlite3.OperationalError) no such table: user
[SQL: SELECT user.id AS user_id, user.username AS user_username, user.email AS user_email, user.password_hash AS user_password_hash, user.about_me AS user_about_me, user.last_seen AS user_last_seen, user.token AS user_token, user.token_expiration AS user_token_expiration, user.last_message_read_time AS user_last_message_read_time 
FROM user 
WHERE user.id = ?]
[parameters: (1,)]
(Background on this error at: http://sqlalche.me/e/e3q8)
2020-02-10 17:24:57,054 ERROR: Exception on /favicon.ico [GET] [in /Library/Frameworks/Python.framework/Versions/3.7/lib/python3.7/site-packages/flask/app.py:1761]
Traceback (most recent call last):
  File "/Library/Frameworks/Python.framework/Versions/3.7/lib/python3.7/site-packages/sqlalchemy/engine/base.py", line 1249, in _execute_context
    cursor, statement, parameters, context
  File "/Library/Frameworks/Python.framework/Versions/3.7/lib/python3.7/site-packages/sqlalchemy/engine/default.py", line 552, in do_execute
    cursor.execute(statement, parameters)
sqlite3.OperationalError: no such table: user

The above exception was the direct cause of the following exception:

Traceback (most recent call last):
  File "/Library/Frameworks/Python.framework/Versions/3.7/lib/python3.7/site-packages/flask/app.py", line 2292, in wsgi_app
    response = self.full_dispatch_request()
  File "/Library/Frameworks/Python.framework/Versions/3.7/lib/python3.7/site-packages/flask/app.py", line 1815, in full_dispatch_request
    rv = self.handle_user_exception(e)
  File "/Library/Frameworks/Python.framework/Versions/3.7/lib/python3.7/site-packages/flask/app.py", line 1718, in handle_user_exception
    reraise(exc_type, exc_value, tb)
  File "/Library/Frameworks/Python.framework/Versions/3.7/lib/python3.7/site-packages/flask/_compat.py", line 35, in reraise
    raise value
  File "/Library/Frameworks/Python.framework/Versions/3.7/lib/python3.7/site-packages/flask/app.py", line 1811, in full_dispatch_request
    rv = self.preprocess_request()
  File "/Library/Frameworks/Python.framework/Versions/3.7/lib/python3.7/site-packages/flask/app.py", line 2087, in preprocess_request
    rv = func()
  File "/Users/yhz/Desktop/pypy/Flask_Learn/app/main/routes.py", line 21, in before_request
    if current_user.is_authenticated:
  File "/Library/Frameworks/Python.framework/Versions/3.7/lib/python3.7/site-packages/werkzeug/local.py", line 347, in __getattr__
    return getattr(self._get_current_object(), name)
  File "/Library/Frameworks/Python.framework/Versions/3.7/lib/python3.7/site-packages/werkzeug/local.py", line 306, in _get_current_object
    return self.__local()
  File "/Library/Frameworks/Python.framework/Versions/3.7/lib/python3.7/site-packages/flask_login/utils.py", line 26, in <lambda>
    current_user = LocalProxy(lambda: _get_user())
  File "/Library/Frameworks/Python.framework/Versions/3.7/lib/python3.7/site-packages/flask_login/utils.py", line 335, in _get_user
    current_app.login_manager._load_user()
  File "/Library/Frameworks/Python.framework/Versions/3.7/lib/python3.7/site-packages/flask_login/login_manager.py", line 359, in _load_user
    return self.reload_user()
  File "/Library/Frameworks/Python.framework/Versions/3.7/lib/python3.7/site-packages/flask_login/login_manager.py", line 321, in reload_user
    user = self.user_callback(user_id)
  File "/Users/yhz/Desktop/pypy/Flask_Learn/app/models.py", line 269, in load_user
    return User.query.get(int(id))  # 传入字符串类型，使用数字ID的数据库需要将字符串转换为整数。
  File "/Library/Frameworks/Python.framework/Versions/3.7/lib/python3.7/site-packages/sqlalchemy/orm/query.py", line 959, in get
    return self._get_impl(ident, loading.load_on_pk_identity)
  File "/Library/Frameworks/Python.framework/Versions/3.7/lib/python3.7/site-packages/sqlalchemy/orm/query.py", line 1069, in _get_impl
    return db_load_fn(self, primary_key_identity)
  File "/Library/Frameworks/Python.framework/Versions/3.7/lib/python3.7/site-packages/sqlalchemy/orm/loading.py", line 282, in load_on_pk_identity
    return q.one()
  File "/Library/Frameworks/Python.framework/Versions/3.7/lib/python3.7/site-packages/sqlalchemy/orm/query.py", line 3292, in one
    ret = self.one_or_none()
  File "/Library/Frameworks/Python.framework/Versions/3.7/lib/python3.7/site-packages/sqlalchemy/orm/query.py", line 3261, in one_or_none
    ret = list(self)
  File "/Library/Frameworks/Python.framework/Versions/3.7/lib/python3.7/site-packages/sqlalchemy/orm/query.py", line 3334, in __iter__
    return self._execute_and_instances(context)
  File "/Library/Frameworks/Python.framework/Versions/3.7/lib/python3.7/site-packages/sqlalchemy/orm/query.py", line 3359, in _execute_and_instances
    result = conn.execute(querycontext.statement, self._params)
  File "/Library/Frameworks/Python.framework/Versions/3.7/lib/python3.7/site-packages/sqlalchemy/engine/base.py", line 988, in execute
    return meth(self, multiparams, params)
  File "/Library/Frameworks/Python.framework/Versions/3.7/lib/python3.7/site-packages/sqlalchemy/sql/elements.py", line 287, in _execute_on_connection
    return connection._execute_clauseelement(self, multiparams, params)
  File "/Library/Frameworks/Python.framework/Versions/3.7/lib/python3.7/site-packages/sqlalchemy/engine/base.py", line 1107, in _execute_clauseelement
    distilled_params,
  File "/Library/Frameworks/Python.framework/Versions/3.7/lib/python3.7/site-packages/sqlalchemy/engine/base.py", line 1253, in _execute_context
    e, statement, parameters, cursor, context
  File "/Library/Frameworks/Python.framework/Versions/3.7/lib/python3.7/site-packages/sqlalchemy/engine/base.py", line 1473, in _handle_dbapi_exception
    util.raise_from_cause(sqlalchemy_exception, exc_info)
  File "/Library/Frameworks/Python.framework/Versions/3.7/lib/python3.7/site-packages/sqlalchemy/util/compat.py", line 398, in raise_from_cause
    reraise(type(exception), exception, tb=exc_tb, cause=cause)
  File "/Library/Frameworks/Python.framework/Versions/3.7/lib/python3.7/site-packages/sqlalchemy/util/compat.py", line 152, in reraise
    raise value.with_traceback(tb)
  File "/Library/Frameworks/Python.framework/Versions/3.7/lib/python3.7/site-packages/sqlalchemy/engine/base.py", line 1249, in _execute_context
    cursor, statement, parameters, context
  File "/Library/Frameworks/Python.framework/Versions/3.7/lib/python3.7/site-packages/sqlalchemy/engine/default.py", line 552, in do_execute
    cursor.execute(statement, parameters)
sqlalchemy.exc.OperationalError: (sqlite3.OperationalError) no such table: user
[SQL: SELECT user.id AS user_id, user.username AS user_username, user.email AS user_email, user.password_hash AS user_password_hash, user.about_me AS user_about_me, user.last_seen AS user_last_seen, user.token AS user_token, user.token_expiration AS user_token_expiration, user.last_message_read_time AS user_last_message_read_time 
FROM user 
WHERE user.id = ?]
[parameters: (1,)]
(Background on this error at: http://sqlalche.me/e/e3q8)
2020-02-10 17:24:57,994 ERROR: Exception on /auth/logout [GET] [in /Library/Frameworks/Python.framework/Versions/3.7/lib/python3.7/site-packages/flask/app.py:1761]
Traceback (most recent call last):
  File "/Library/Frameworks/Python.framework/Versions/3.7/lib/python3.7/site-packages/sqlalchemy/engine/base.py", line 1249, in _execute_context
    cursor, statement, parameters, context
  File "/Library/Frameworks/Python.framework/Versions/3.7/lib/python3.7/site-packages/sqlalchemy/engine/default.py", line 552, in do_execute
    cursor.execute(statement, parameters)
sqlite3.OperationalError: no such table: user

The above exception was the direct cause of the following exception:

Traceback (most recent call last):
  File "/Library/Frameworks/Python.framework/Versions/3.7/lib/python3.7/site-packages/flask/app.py", line 2292, in wsgi_app
    response = self.full_dispatch_request()
  File "/Library/Frameworks/Python.framework/Versions/3.7/lib/python3.7/site-packages/flask/app.py", line 1815, in full_dispatch_request
    rv = self.handle_user_exception(e)
  File "/Library/Frameworks/Python.framework/Versions/3.7/lib/python3.7/site-packages/flask/app.py", line 1718, in handle_user_exception
    reraise(exc_type, exc_value, tb)
  File "/Library/Frameworks/Python.framework/Versions/3.7/lib/python3.7/site-packages/flask/_compat.py", line 35, in reraise
    raise value
  File "/Library/Frameworks/Python.framework/Versions/3.7/lib/python3.7/site-packages/flask/app.py", line 1811, in full_dispatch_request
    rv = self.preprocess_request()
  File "/Library/Frameworks/Python.framework/Versions/3.7/lib/python3.7/site-packages/flask/app.py", line 2087, in preprocess_request
    rv = func()
  File "/Users/yhz/Desktop/pypy/Flask_Learn/app/main/routes.py", line 21, in before_request
    if current_user.is_authenticated:
  File "/Library/Frameworks/Python.framework/Versions/3.7/lib/python3.7/site-packages/werkzeug/local.py", line 347, in __getattr__
    return getattr(self._get_current_object(), name)
  File "/Library/Frameworks/Python.framework/Versions/3.7/lib/python3.7/site-packages/werkzeug/local.py", line 306, in _get_current_object
    return self.__local()
  File "/Library/Frameworks/Python.framework/Versions/3.7/lib/python3.7/site-packages/flask_login/utils.py", line 26, in <lambda>
    current_user = LocalProxy(lambda: _get_user())
  File "/Library/Frameworks/Python.framework/Versions/3.7/lib/python3.7/site-packages/flask_login/utils.py", line 335, in _get_user
    current_app.login_manager._load_user()
  File "/Library/Frameworks/Python.framework/Versions/3.7/lib/python3.7/site-packages/flask_login/login_manager.py", line 359, in _load_user
    return self.reload_user()
  File "/Library/Frameworks/Python.framework/Versions/3.7/lib/python3.7/site-packages/flask_login/login_manager.py", line 321, in reload_user
    user = self.user_callback(user_id)
  File "/Users/yhz/Desktop/pypy/Flask_Learn/app/models.py", line 269, in load_user
    return User.query.get(int(id))  # 传入字符串类型，使用数字ID的数据库需要将字符串转换为整数。
  File "/Library/Frameworks/Python.framework/Versions/3.7/lib/python3.7/site-packages/sqlalchemy/orm/query.py", line 959, in get
    return self._get_impl(ident, loading.load_on_pk_identity)
  File "/Library/Frameworks/Python.framework/Versions/3.7/lib/python3.7/site-packages/sqlalchemy/orm/query.py", line 1069, in _get_impl
    return db_load_fn(self, primary_key_identity)
  File "/Library/Frameworks/Python.framework/Versions/3.7/lib/python3.7/site-packages/sqlalchemy/orm/loading.py", line 282, in load_on_pk_identity
    return q.one()
  File "/Library/Frameworks/Python.framework/Versions/3.7/lib/python3.7/site-packages/sqlalchemy/orm/query.py", line 3292, in one
    ret = self.one_or_none()
  File "/Library/Frameworks/Python.framework/Versions/3.7/lib/python3.7/site-packages/sqlalchemy/orm/query.py", line 3261, in one_or_none
    ret = list(self)
  File "/Library/Frameworks/Python.framework/Versions/3.7/lib/python3.7/site-packages/sqlalchemy/orm/query.py", line 3334, in __iter__
    return self._execute_and_instances(context)
  File "/Library/Frameworks/Python.framework/Versions/3.7/lib/python3.7/site-packages/sqlalchemy/orm/query.py", line 3359, in _execute_and_instances
    result = conn.execute(querycontext.statement, self._params)
  File "/Library/Frameworks/Python.framework/Versions/3.7/lib/python3.7/site-packages/sqlalchemy/engine/base.py", line 988, in execute
    return meth(self, multiparams, params)
  File "/Library/Frameworks/Python.framework/Versions/3.7/lib/python3.7/site-packages/sqlalchemy/sql/elements.py", line 287, in _execute_on_connection
    return connection._execute_clauseelement(self, multiparams, params)
  File "/Library/Frameworks/Python.framework/Versions/3.7/lib/python3.7/site-packages/sqlalchemy/engine/base.py", line 1107, in _execute_clauseelement
    distilled_params,
  File "/Library/Frameworks/Python.framework/Versions/3.7/lib/python3.7/site-packages/sqlalchemy/engine/base.py", line 1253, in _execute_context
    e, statement, parameters, cursor, context
  File "/Library/Frameworks/Python.framework/Versions/3.7/lib/python3.7/site-packages/sqlalchemy/engine/base.py", line 1473, in _handle_dbapi_exception
    util.raise_from_cause(sqlalchemy_exception, exc_info)
  File "/Library/Frameworks/Python.framework/Versions/3.7/lib/python3.7/site-packages/sqlalchemy/util/compat.py", line 398, in raise_from_cause
    reraise(type(exception), exception, tb=exc_tb, cause=cause)
  File "/Library/Frameworks/Python.framework/Versions/3.7/lib/python3.7/site-packages/sqlalchemy/util/compat.py", line 152, in reraise
    raise value.with_traceback(tb)
  File "/Library/Frameworks/Python.framework/Versions/3.7/lib/python3.7/site-packages/sqlalchemy/engine/base.py", line 1249, in _execute_context
    cursor, statement, parameters, context
  File "/Library/Frameworks/Python.framework/Versions/3.7/lib/python3.7/site-packages/sqlalchemy/engine/default.py", line 552, in do_execute
    cursor.execute(statement, parameters)
sqlalchemy.exc.OperationalError: (sqlite3.OperationalError) no such table: user
[SQL: SELECT user.id AS user_id, user.username AS user_username, user.email AS user_email, user.password_hash AS user_password_hash, user.about_me AS user_about_me, user.last_seen AS user_last_seen, user.token AS user_token, user.token_expiration AS user_token_expiration, user.last_message_read_time AS user_last_message_read_time 
FROM user 
WHERE user.id = ?]
[parameters: (1,)]
(Background on this error at: http://sqlalche.me/e/e3q8)
2020-02-10 17:24:58,080 ERROR: Exception on /favicon.ico [GET] [in /Library/Frameworks/Python.framework/Versions/3.7/lib/python3.7/site-packages/flask/app.py:1761]
Traceback (most recent call last):
  File "/Library/Frameworks/Python.framework/Versions/3.7/lib/python3.7/site-packages/sqlalchemy/engine/base.py", line 1249, in _execute_context
    cursor, statement, parameters, context
  File "/Library/Frameworks/Python.framework/Versions/3.7/lib/python3.7/site-packages/sqlalchemy/engine/default.py", line 552, in do_execute
    cursor.execute(statement, parameters)
sqlite3.OperationalError: no such table: user

The above exception was the direct cause of the following exception:

Traceback (most recent call last):
  File "/Library/Frameworks/Python.framework/Versions/3.7/lib/python3.7/site-packages/flask/app.py", line 2292, in wsgi_app
    response = self.full_dispatch_request()
  File "/Library/Frameworks/Python.framework/Versions/3.7/lib/python3.7/site-packages/flask/app.py", line 1815, in full_dispatch_request
    rv = self.handle_user_exception(e)
  File "/Library/Frameworks/Python.framework/Versions/3.7/lib/python3.7/site-packages/flask/app.py", line 1718, in handle_user_exception
    reraise(exc_type, exc_value, tb)
  File "/Library/Frameworks/Python.framework/Versions/3.7/lib/python3.7/site-packages/flask/_compat.py", line 35, in reraise
    raise value
  File "/Library/Frameworks/Python.framework/Versions/3.7/lib/python3.7/site-packages/flask/app.py", line 1811, in full_dispatch_request
    rv = self.preprocess_request()
  File "/Library/Frameworks/Python.framework/Versions/3.7/lib/python3.7/site-packages/flask/app.py", line 2087, in preprocess_request
    rv = func()
  File "/Users/yhz/Desktop/pypy/Flask_Learn/app/main/routes.py", line 21, in before_request
    if current_user.is_authenticated:
  File "/Library/Frameworks/Python.framework/Versions/3.7/lib/python3.7/site-packages/werkzeug/local.py", line 347, in __getattr__
    return getattr(self._get_current_object(), name)
  File "/Library/Frameworks/Python.framework/Versions/3.7/lib/python3.7/site-packages/werkzeug/local.py", line 306, in _get_current_object
    return self.__local()
  File "/Library/Frameworks/Python.framework/Versions/3.7/lib/python3.7/site-packages/flask_login/utils.py", line 26, in <lambda>
    current_user = LocalProxy(lambda: _get_user())
  File "/Library/Frameworks/Python.framework/Versions/3.7/lib/python3.7/site-packages/flask_login/utils.py", line 335, in _get_user
    current_app.login_manager._load_user()
  File "/Library/Frameworks/Python.framework/Versions/3.7/lib/python3.7/site-packages/flask_login/login_manager.py", line 359, in _load_user
    return self.reload_user()
  File "/Library/Frameworks/Python.framework/Versions/3.7/lib/python3.7/site-packages/flask_login/login_manager.py", line 321, in reload_user
    user = self.user_callback(user_id)
  File "/Users/yhz/Desktop/pypy/Flask_Learn/app/models.py", line 269, in load_user
    return User.query.get(int(id))  # 传入字符串类型，使用数字ID的数据库需要将字符串转换为整数。
  File "/Library/Frameworks/Python.framework/Versions/3.7/lib/python3.7/site-packages/sqlalchemy/orm/query.py", line 959, in get
    return self._get_impl(ident, loading.load_on_pk_identity)
  File "/Library/Frameworks/Python.framework/Versions/3.7/lib/python3.7/site-packages/sqlalchemy/orm/query.py", line 1069, in _get_impl
    return db_load_fn(self, primary_key_identity)
  File "/Library/Frameworks/Python.framework/Versions/3.7/lib/python3.7/site-packages/sqlalchemy/orm/loading.py", line 282, in load_on_pk_identity
    return q.one()
  File "/Library/Frameworks/Python.framework/Versions/3.7/lib/python3.7/site-packages/sqlalchemy/orm/query.py", line 3292, in one
    ret = self.one_or_none()
  File "/Library/Frameworks/Python.framework/Versions/3.7/lib/python3.7/site-packages/sqlalchemy/orm/query.py", line 3261, in one_or_none
    ret = list(self)
  File "/Library/Frameworks/Python.framework/Versions/3.7/lib/python3.7/site-packages/sqlalchemy/orm/query.py", line 3334, in __iter__
    return self._execute_and_instances(context)
  File "/Library/Frameworks/Python.framework/Versions/3.7/lib/python3.7/site-packages/sqlalchemy/orm/query.py", line 3359, in _execute_and_instances
    result = conn.execute(querycontext.statement, self._params)
  File "/Library/Frameworks/Python.framework/Versions/3.7/lib/python3.7/site-packages/sqlalchemy/engine/base.py", line 988, in execute
    return meth(self, multiparams, params)
  File "/Library/Frameworks/Python.framework/Versions/3.7/lib/python3.7/site-packages/sqlalchemy/sql/elements.py", line 287, in _execute_on_connection
    return connection._execute_clauseelement(self, multiparams, params)
  File "/Library/Frameworks/Python.framework/Versions/3.7/lib/python3.7/site-packages/sqlalchemy/engine/base.py", line 1107, in _execute_clauseelement
    distilled_params,
  File "/Library/Frameworks/Python.framework/Versions/3.7/lib/python3.7/site-packages/sqlalchemy/engine/base.py", line 1253, in _execute_context
    e, statement, parameters, cursor, context
  File "/Library/Frameworks/Python.framework/Versions/3.7/lib/python3.7/site-packages/sqlalchemy/engine/base.py", line 1473, in _handle_dbapi_exception
    util.raise_from_cause(sqlalchemy_exception, exc_info)
  File "/Library/Frameworks/Python.framework/Versions/3.7/lib/python3.7/site-packages/sqlalchemy/util/compat.py", line 398, in raise_from_cause
    reraise(type(exception), exception, tb=exc_tb, cause=cause)
  File "/Library/Frameworks/Python.framework/Versions/3.7/lib/python3.7/site-packages/sqlalchemy/util/compat.py", line 152, in reraise
    raise value.with_traceback(tb)
  File "/Library/Frameworks/Python.framework/Versions/3.7/lib/python3.7/site-packages/sqlalchemy/engine/base.py", line 1249, in _execute_context
    cursor, statement, parameters, context
  File "/Library/Frameworks/Python.framework/Versions/3.7/lib/python3.7/site-packages/sqlalchemy/engine/default.py", line 552, in do_execute
    cursor.execute(statement, parameters)
sqlalchemy.exc.OperationalError: (sqlite3.OperationalError) no such table: user
[SQL: SELECT user.id AS user_id, user.username AS user_username, user.email AS user_email, user.password_hash AS user_password_hash, user.about_me AS user_about_me, user.last_seen AS user_last_seen, user.token AS user_token, user.token_expiration AS user_token_expiration, user.last_message_read_time AS user_last_message_read_time 
FROM user 
WHERE user.id = ?]
[parameters: (1,)]
(Background on this error at: http://sqlalche.me/e/e3q8)
2020-02-10 17:25:00,545 ERROR: Exception on /favicon.ico [GET] [in /Library/Frameworks/Python.framework/Versions/3.7/lib/python3.7/site-packages/flask/app.py:1761]
Traceback (most recent call last):
  File "/Library/Frameworks/Python.framework/Versions/3.7/lib/python3.7/site-packages/sqlalchemy/engine/base.py", line 1249, in _execute_context
    cursor, statement, parameters, context
  File "/Library/Frameworks/Python.framework/Versions/3.7/lib/python3.7/site-packages/sqlalchemy/engine/default.py", line 552, in do_execute
    cursor.execute(statement, parameters)
sqlite3.OperationalError: no such table: user

The above exception was the direct cause of the following exception:

Traceback (most recent call last):
  File "/Library/Frameworks/Python.framework/Versions/3.7/lib/python3.7/site-packages/flask/app.py", line 2292, in wsgi_app
    response = self.full_dispatch_request()
  File "/Library/Frameworks/Python.framework/Versions/3.7/lib/python3.7/site-packages/flask/app.py", line 1815, in full_dispatch_request
    rv = self.handle_user_exception(e)
  File "/Library/Frameworks/Python.framework/Versions/3.7/lib/python3.7/site-packages/flask/app.py", line 1718, in handle_user_exception
    reraise(exc_type, exc_value, tb)
  File "/Library/Frameworks/Python.framework/Versions/3.7/lib/python3.7/site-packages/flask/_compat.py", line 35, in reraise
    raise value
  File "/Library/Frameworks/Python.framework/Versions/3.7/lib/python3.7/site-packages/flask/app.py", line 1811, in full_dispatch_request
    rv = self.preprocess_request()
  File "/Library/Frameworks/Python.framework/Versions/3.7/lib/python3.7/site-packages/flask/app.py", line 2087, in preprocess_request
    rv = func()
  File "/Users/yhz/Desktop/pypy/Flask_Learn/app/main/routes.py", line 21, in before_request
    if current_user.is_authenticated:
  File "/Library/Frameworks/Python.framework/Versions/3.7/lib/python3.7/site-packages/werkzeug/local.py", line 347, in __getattr__
    return getattr(self._get_current_object(), name)
  File "/Library/Frameworks/Python.framework/Versions/3.7/lib/python3.7/site-packages/werkzeug/local.py", line 306, in _get_current_object
    return self.__local()
  File "/Library/Frameworks/Python.framework/Versions/3.7/lib/python3.7/site-packages/flask_login/utils.py", line 26, in <lambda>
    current_user = LocalProxy(lambda: _get_user())
  File "/Library/Frameworks/Python.framework/Versions/3.7/lib/python3.7/site-packages/flask_login/utils.py", line 335, in _get_user
    current_app.login_manager._load_user()
  File "/Library/Frameworks/Python.framework/Versions/3.7/lib/python3.7/site-packages/flask_login/login_manager.py", line 359, in _load_user
    return self.reload_user()
  File "/Library/Frameworks/Python.framework/Versions/3.7/lib/python3.7/site-packages/flask_login/login_manager.py", line 321, in reload_user
    user = self.user_callback(user_id)
  File "/Users/yhz/Desktop/pypy/Flask_Learn/app/models.py", line 269, in load_user
    return User.query.get(int(id))  # 传入字符串类型，使用数字ID的数据库需要将字符串转换为整数。
  File "/Library/Frameworks/Python.framework/Versions/3.7/lib/python3.7/site-packages/sqlalchemy/orm/query.py", line 959, in get
    return self._get_impl(ident, loading.load_on_pk_identity)
  File "/Library/Frameworks/Python.framework/Versions/3.7/lib/python3.7/site-packages/sqlalchemy/orm/query.py", line 1069, in _get_impl
    return db_load_fn(self, primary_key_identity)
  File "/Library/Frameworks/Python.framework/Versions/3.7/lib/python3.7/site-packages/sqlalchemy/orm/loading.py", line 282, in load_on_pk_identity
    return q.one()
  File "/Library/Frameworks/Python.framework/Versions/3.7/lib/python3.7/site-packages/sqlalchemy/orm/query.py", line 3292, in one
    ret = self.one_or_none()
  File "/Library/Frameworks/Python.framework/Versions/3.7/lib/python3.7/site-packages/sqlalchemy/orm/query.py", line 3261, in one_or_none
    ret = list(self)
  File "/Library/Frameworks/Python.framework/Versions/3.7/lib/python3.7/site-packages/sqlalchemy/orm/query.py", line 3334, in __iter__
    return self._execute_and_instances(context)
  File "/Library/Frameworks/Python.framework/Versions/3.7/lib/python3.7/site-packages/sqlalchemy/orm/query.py", line 3359, in _execute_and_instances
    result = conn.execute(querycontext.statement, self._params)
  File "/Library/Frameworks/Python.framework/Versions/3.7/lib/python3.7/site-packages/sqlalchemy/engine/base.py", line 988, in execute
    return meth(self, multiparams, params)
  File "/Library/Frameworks/Python.framework/Versions/3.7/lib/python3.7/site-packages/sqlalchemy/sql/elements.py", line 287, in _execute_on_connection
    return connection._execute_clauseelement(self, multiparams, params)
  File "/Library/Frameworks/Python.framework/Versions/3.7/lib/python3.7/site-packages/sqlalchemy/engine/base.py", line 1107, in _execute_clauseelement
    distilled_params,
  File "/Library/Frameworks/Python.framework/Versions/3.7/lib/python3.7/site-packages/sqlalchemy/engine/base.py", line 1253, in _execute_context
    e, statement, parameters, cursor, context
  File "/Library/Frameworks/Python.framework/Versions/3.7/lib/python3.7/site-packages/sqlalchemy/engine/base.py", line 1473, in _handle_dbapi_exception
    util.raise_from_cause(sqlalchemy_exception, exc_info)
  File "/Library/Frameworks/Python.framework/Versions/3.7/lib/python3.7/site-packages/sqlalchemy/util/compat.py", line 398, in raise_from_cause
    reraise(type(exception), exception, tb=exc_tb, cause=cause)
  File "/Library/Frameworks/Python.framework/Versions/3.7/lib/python3.7/site-packages/sqlalchemy/util/compat.py", line 152, in reraise
    raise value.with_traceback(tb)
  File "/Library/Frameworks/Python.framework/Versions/3.7/lib/python3.7/site-packages/sqlalchemy/engine/base.py", line 1249, in _execute_context
    cursor, statement, parameters, context
  File "/Library/Frameworks/Python.framework/Versions/3.7/lib/python3.7/site-packages/sqlalchemy/engine/default.py", line 552, in do_execute
    cursor.execute(statement, parameters)
sqlalchemy.exc.OperationalError: (sqlite3.OperationalError) no such table: user
[SQL: SELECT user.id AS user_id, user.username AS user_username, user.email AS user_email, user.password_hash AS user_password_hash, user.about_me AS user_about_me, user.last_seen AS user_last_seen, user.token AS user_token, user.token_expiration AS user_token_expiration, user.last_message_read_time AS user_last_message_read_time 
FROM user 
WHERE user.id = ?]
[parameters: (1,)]
(Background on this error at: http://sqlalche.me/e/e3q8)
2020-02-10 17:25:08,054 INFO: Microblog startup [in /Users/yhz/Desktop/pypy/Flask_Learn/app/__init__.py:104]
2020-02-10 17:25:08,978 ERROR: Exception on / [GET] [in /Library/Frameworks/Python.framework/Versions/3.7/lib/python3.7/site-packages/flask/app.py:1761]
Traceback (most recent call last):
  File "/Library/Frameworks/Python.framework/Versions/3.7/lib/python3.7/site-packages/sqlalchemy/engine/base.py", line 1249, in _execute_context
    cursor, statement, parameters, context
  File "/Library/Frameworks/Python.framework/Versions/3.7/lib/python3.7/site-packages/sqlalchemy/engine/default.py", line 552, in do_execute
    cursor.execute(statement, parameters)
sqlite3.OperationalError: no such table: user

The above exception was the direct cause of the following exception:

Traceback (most recent call last):
  File "/Library/Frameworks/Python.framework/Versions/3.7/lib/python3.7/site-packages/flask/app.py", line 2292, in wsgi_app
    response = self.full_dispatch_request()
  File "/Library/Frameworks/Python.framework/Versions/3.7/lib/python3.7/site-packages/flask/app.py", line 1815, in full_dispatch_request
    rv = self.handle_user_exception(e)
  File "/Library/Frameworks/Python.framework/Versions/3.7/lib/python3.7/site-packages/flask/app.py", line 1718, in handle_user_exception
    reraise(exc_type, exc_value, tb)
  File "/Library/Frameworks/Python.framework/Versions/3.7/lib/python3.7/site-packages/flask/_compat.py", line 35, in reraise
    raise value
  File "/Library/Frameworks/Python.framework/Versions/3.7/lib/python3.7/site-packages/flask/app.py", line 1811, in full_dispatch_request
    rv = self.preprocess_request()
  File "/Library/Frameworks/Python.framework/Versions/3.7/lib/python3.7/site-packages/flask/app.py", line 2087, in preprocess_request
    rv = func()
  File "/Users/yhz/Desktop/pypy/Flask_Learn/app/main/routes.py", line 21, in before_request
    if current_user.is_authenticated:
  File "/Library/Frameworks/Python.framework/Versions/3.7/lib/python3.7/site-packages/werkzeug/local.py", line 347, in __getattr__
    return getattr(self._get_current_object(), name)
  File "/Library/Frameworks/Python.framework/Versions/3.7/lib/python3.7/site-packages/werkzeug/local.py", line 306, in _get_current_object
    return self.__local()
  File "/Library/Frameworks/Python.framework/Versions/3.7/lib/python3.7/site-packages/flask_login/utils.py", line 26, in <lambda>
    current_user = LocalProxy(lambda: _get_user())
  File "/Library/Frameworks/Python.framework/Versions/3.7/lib/python3.7/site-packages/flask_login/utils.py", line 335, in _get_user
    current_app.login_manager._load_user()
  File "/Library/Frameworks/Python.framework/Versions/3.7/lib/python3.7/site-packages/flask_login/login_manager.py", line 359, in _load_user
    return self.reload_user()
  File "/Library/Frameworks/Python.framework/Versions/3.7/lib/python3.7/site-packages/flask_login/login_manager.py", line 321, in reload_user
    user = self.user_callback(user_id)
  File "/Users/yhz/Desktop/pypy/Flask_Learn/app/models.py", line 269, in load_user
    return User.query.get(int(id))  # 传入字符串类型，使用数字ID的数据库需要将字符串转换为整数。
  File "/Library/Frameworks/Python.framework/Versions/3.7/lib/python3.7/site-packages/sqlalchemy/orm/query.py", line 959, in get
    return self._get_impl(ident, loading.load_on_pk_identity)
  File "/Library/Frameworks/Python.framework/Versions/3.7/lib/python3.7/site-packages/sqlalchemy/orm/query.py", line 1069, in _get_impl
    return db_load_fn(self, primary_key_identity)
  File "/Library/Frameworks/Python.framework/Versions/3.7/lib/python3.7/site-packages/sqlalchemy/orm/loading.py", line 282, in load_on_pk_identity
    return q.one()
  File "/Library/Frameworks/Python.framework/Versions/3.7/lib/python3.7/site-packages/sqlalchemy/orm/query.py", line 3292, in one
    ret = self.one_or_none()
  File "/Library/Frameworks/Python.framework/Versions/3.7/lib/python3.7/site-packages/sqlalchemy/orm/query.py", line 3261, in one_or_none
    ret = list(self)
  File "/Library/Frameworks/Python.framework/Versions/3.7/lib/python3.7/site-packages/sqlalchemy/orm/query.py", line 3334, in __iter__
    return self._execute_and_instances(context)
  File "/Library/Frameworks/Python.framework/Versions/3.7/lib/python3.7/site-packages/sqlalchemy/orm/query.py", line 3359, in _execute_and_instances
    result = conn.execute(querycontext.statement, self._params)
  File "/Library/Frameworks/Python.framework/Versions/3.7/lib/python3.7/site-packages/sqlalchemy/engine/base.py", line 988, in execute
    return meth(self, multiparams, params)
  File "/Library/Frameworks/Python.framework/Versions/3.7/lib/python3.7/site-packages/sqlalchemy/sql/elements.py", line 287, in _execute_on_connection
    return connection._execute_clauseelement(self, multiparams, params)
  File "/Library/Frameworks/Python.framework/Versions/3.7/lib/python3.7/site-packages/sqlalchemy/engine/base.py", line 1107, in _execute_clauseelement
    distilled_params,
  File "/Library/Frameworks/Python.framework/Versions/3.7/lib/python3.7/site-packages/sqlalchemy/engine/base.py", line 1253, in _execute_context
    e, statement, parameters, cursor, context
  File "/Library/Frameworks/Python.framework/Versions/3.7/lib/python3.7/site-packages/sqlalchemy/engine/base.py", line 1473, in _handle_dbapi_exception
    util.raise_from_cause(sqlalchemy_exception, exc_info)
  File "/Library/Frameworks/Python.framework/Versions/3.7/lib/python3.7/site-packages/sqlalchemy/util/compat.py", line 398, in raise_from_cause
    reraise(type(exception), exception, tb=exc_tb, cause=cause)
  File "/Library/Frameworks/Python.framework/Versions/3.7/lib/python3.7/site-packages/sqlalchemy/util/compat.py", line 152, in reraise
    raise value.with_traceback(tb)
  File "/Library/Frameworks/Python.framework/Versions/3.7/lib/python3.7/site-packages/sqlalchemy/engine/base.py", line 1249, in _execute_context
    cursor, statement, parameters, context
  File "/Library/Frameworks/Python.framework/Versions/3.7/lib/python3.7/site-packages/sqlalchemy/engine/default.py", line 552, in do_execute
    cursor.execute(statement, parameters)
sqlalchemy.exc.OperationalError: (sqlite3.OperationalError) no such table: user
[SQL: SELECT user.id AS user_id, user.username AS user_username, user.email AS user_email, user.password_hash AS user_password_hash, user.about_me AS user_about_me, user.last_seen AS user_last_seen, user.token AS user_token, user.token_expiration AS user_token_expiration, user.last_message_read_time AS user_last_message_read_time 
FROM user 
WHERE user.id = ?]
[parameters: (1,)]
(Background on this error at: http://sqlalche.me/e/e3q8)
2020-02-10 17:25:10,552 ERROR: Exception on /notifications [GET] [in /Library/Frameworks/Python.framework/Versions/3.7/lib/python3.7/site-packages/flask/app.py:1761]
Traceback (most recent call last):
  File "/Library/Frameworks/Python.framework/Versions/3.7/lib/python3.7/site-packages/sqlalchemy/engine/base.py", line 1249, in _execute_context
    cursor, statement, parameters, context
  File "/Library/Frameworks/Python.framework/Versions/3.7/lib/python3.7/site-packages/sqlalchemy/engine/default.py", line 552, in do_execute
    cursor.execute(statement, parameters)
sqlite3.OperationalError: no such table: user

The above exception was the direct cause of the following exception:

Traceback (most recent call last):
  File "/Library/Frameworks/Python.framework/Versions/3.7/lib/python3.7/site-packages/flask/app.py", line 2292, in wsgi_app
    response = self.full_dispatch_request()
  File "/Library/Frameworks/Python.framework/Versions/3.7/lib/python3.7/site-packages/flask/app.py", line 1815, in full_dispatch_request
    rv = self.handle_user_exception(e)
  File "/Library/Frameworks/Python.framework/Versions/3.7/lib/python3.7/site-packages/flask/app.py", line 1718, in handle_user_exception
    reraise(exc_type, exc_value, tb)
  File "/Library/Frameworks/Python.framework/Versions/3.7/lib/python3.7/site-packages/flask/_compat.py", line 35, in reraise
    raise value
  File "/Library/Frameworks/Python.framework/Versions/3.7/lib/python3.7/site-packages/flask/app.py", line 1811, in full_dispatch_request
    rv = self.preprocess_request()
  File "/Library/Frameworks/Python.framework/Versions/3.7/lib/python3.7/site-packages/flask/app.py", line 2087, in preprocess_request
    rv = func()
  File "/Users/yhz/Desktop/pypy/Flask_Learn/app/main/routes.py", line 21, in before_request
    if current_user.is_authenticated:
  File "/Library/Frameworks/Python.framework/Versions/3.7/lib/python3.7/site-packages/werkzeug/local.py", line 347, in __getattr__
    return getattr(self._get_current_object(), name)
  File "/Library/Frameworks/Python.framework/Versions/3.7/lib/python3.7/site-packages/werkzeug/local.py", line 306, in _get_current_object
    return self.__local()
  File "/Library/Frameworks/Python.framework/Versions/3.7/lib/python3.7/site-packages/flask_login/utils.py", line 26, in <lambda>
    current_user = LocalProxy(lambda: _get_user())
  File "/Library/Frameworks/Python.framework/Versions/3.7/lib/python3.7/site-packages/flask_login/utils.py", line 335, in _get_user
    current_app.login_manager._load_user()
  File "/Library/Frameworks/Python.framework/Versions/3.7/lib/python3.7/site-packages/flask_login/login_manager.py", line 359, in _load_user
    return self.reload_user()
  File "/Library/Frameworks/Python.framework/Versions/3.7/lib/python3.7/site-packages/flask_login/login_manager.py", line 321, in reload_user
    user = self.user_callback(user_id)
  File "/Users/yhz/Desktop/pypy/Flask_Learn/app/models.py", line 269, in load_user
    return User.query.get(int(id))  # 传入字符串类型，使用数字ID的数据库需要将字符串转换为整数。
  File "/Library/Frameworks/Python.framework/Versions/3.7/lib/python3.7/site-packages/sqlalchemy/orm/query.py", line 959, in get
    return self._get_impl(ident, loading.load_on_pk_identity)
  File "/Library/Frameworks/Python.framework/Versions/3.7/lib/python3.7/site-packages/sqlalchemy/orm/query.py", line 1069, in _get_impl
    return db_load_fn(self, primary_key_identity)
  File "/Library/Frameworks/Python.framework/Versions/3.7/lib/python3.7/site-packages/sqlalchemy/orm/loading.py", line 282, in load_on_pk_identity
    return q.one()
  File "/Library/Frameworks/Python.framework/Versions/3.7/lib/python3.7/site-packages/sqlalchemy/orm/query.py", line 3292, in one
    ret = self.one_or_none()
  File "/Library/Frameworks/Python.framework/Versions/3.7/lib/python3.7/site-packages/sqlalchemy/orm/query.py", line 3261, in one_or_none
    ret = list(self)
  File "/Library/Frameworks/Python.framework/Versions/3.7/lib/python3.7/site-packages/sqlalchemy/orm/query.py", line 3334, in __iter__
    return self._execute_and_instances(context)
  File "/Library/Frameworks/Python.framework/Versions/3.7/lib/python3.7/site-packages/sqlalchemy/orm/query.py", line 3359, in _execute_and_instances
    result = conn.execute(querycontext.statement, self._params)
  File "/Library/Frameworks/Python.framework/Versions/3.7/lib/python3.7/site-packages/sqlalchemy/engine/base.py", line 988, in execute
    return meth(self, multiparams, params)
  File "/Library/Frameworks/Python.framework/Versions/3.7/lib/python3.7/site-packages/sqlalchemy/sql/elements.py", line 287, in _execute_on_connection
    return connection._execute_clauseelement(self, multiparams, params)
  File "/Library/Frameworks/Python.framework/Versions/3.7/lib/python3.7/site-packages/sqlalchemy/engine/base.py", line 1107, in _execute_clauseelement
    distilled_params,
  File "/Library/Frameworks/Python.framework/Versions/3.7/lib/python3.7/site-packages/sqlalchemy/engine/base.py", line 1253, in _execute_context
    e, statement, parameters, cursor, context
  File "/Library/Frameworks/Python.framework/Versions/3.7/lib/python3.7/site-packages/sqlalchemy/engine/base.py", line 1473, in _handle_dbapi_exception
    util.raise_from_cause(sqlalchemy_exception, exc_info)
  File "/Library/Frameworks/Python.framework/Versions/3.7/lib/python3.7/site-packages/sqlalchemy/util/compat.py", line 398, in raise_from_cause
    reraise(type(exception), exception, tb=exc_tb, cause=cause)
  File "/Library/Frameworks/Python.framework/Versions/3.7/lib/python3.7/site-packages/sqlalchemy/util/compat.py", line 152, in reraise
    raise value.with_traceback(tb)
  File "/Library/Frameworks/Python.framework/Versions/3.7/lib/python3.7/site-packages/sqlalchemy/engine/base.py", line 1249, in _execute_context
    cursor, statement, parameters, context
  File "/Library/Frameworks/Python.framework/Versions/3.7/lib/python3.7/site-packages/sqlalchemy/engine/default.py", line 552, in do_execute
    cursor.execute(statement, parameters)
sqlalchemy.exc.OperationalError: (sqlite3.OperationalError) no such table: user
[SQL: SELECT user.id AS user_id, user.username AS user_username, user.email AS user_email, user.password_hash AS user_password_hash, user.about_me AS user_about_me, user.last_seen AS user_last_seen, user.token AS user_token, user.token_expiration AS user_token_expiration, user.last_message_read_time AS user_last_message_read_time 
FROM user 
WHERE user.id = ?]
[parameters: (1,)]
(Background on this error at: http://sqlalche.me/e/e3q8)
