2020-02-10 18:15:38,727 ERROR: Exception on /auth/logout [GET] [in /Library/Frameworks/Python.framework/Versions/3.7/lib/python3.7/site-packages/flask/app.py:1761]
Traceback (most recent call last):
  File "/Library/Frameworks/Python.framework/Versions/3.7/lib/python3.7/site-packages/sqlalchemy/engine/base.py", line 1249, in _execute_context
    cursor, statement, parameters, context
  File "/Library/Frameworks/Python.framework/Versions/3.7/lib/python3.7/site-packages/sqlalchemy/engine/default.py", line 552, in do_execute
    cursor.execute(statement, parameters)
sqlite3.OperationalError: no such table: user

The above exception was the direct cause of the following exception:

Traceback (most recent call last):
  File "/Library/Frameworks/Python.framework/Versions/3.7/lib/python3.7/site-packages/flask/app.py", line 2292, in wsgi_app
    response = self.full_dispatch_request()
  File "/Library/Frameworks/Python.framework/Versions/3.7/lib/python3.7/site-packages/flask/app.py", line 1815, in full_dispatch_request
    rv = self.handle_user_exception(e)
  File "/Library/Frameworks/Python.framework/Versions/3.7/lib/python3.7/site-packages/flask/app.py", line 1718, in handle_user_exception
    reraise(exc_type, exc_value, tb)
  File "/Library/Frameworks/Python.framework/Versions/3.7/lib/python3.7/site-packages/flask/_compat.py", line 35, in reraise
    raise value
  File "/Library/Frameworks/Python.framework/Versions/3.7/lib/python3.7/site-packages/flask/app.py", line 1811, in full_dispatch_request
    rv = self.preprocess_request()
  File "/Library/Frameworks/Python.framework/Versions/3.7/lib/python3.7/site-packages/flask/app.py", line 2087, in preprocess_request
    rv = func()
  File "/Users/yhz/Desktop/pypy/Flask_Learn/app/main/routes.py", line 21, in before_request
    if current_user.is_authenticated:
  File "/Library/Frameworks/Python.framework/Versions/3.7/lib/python3.7/site-packages/werkzeug/local.py", line 347, in __getattr__
    return getattr(self._get_current_object(), name)
  File "/Library/Frameworks/Python.framework/Versions/3.7/lib/python3.7/site-packages/werkzeug/local.py", line 306, in _get_current_object
    return self.__local()
  File "/Library/Frameworks/Python.framework/Versions/3.7/lib/python3.7/site-packages/flask_login/utils.py", line 26, in <lambda>
    current_user = LocalProxy(lambda: _get_user())
  File "/Library/Frameworks/Python.framework/Versions/3.7/lib/python3.7/site-packages/flask_login/utils.py", line 335, in _get_user
    current_app.login_manager._load_user()
  File "/Library/Frameworks/Python.framework/Versions/3.7/lib/python3.7/site-packages/flask_login/login_manager.py", line 359, in _load_user
    return self.reload_user()
  File "/Library/Frameworks/Python.framework/Versions/3.7/lib/python3.7/site-packages/flask_login/login_manager.py", line 321, in reload_user
    user = self.user_callback(user_id)
  File "/Users/yhz/Desktop/pypy/Flask_Learn/app/models.py", line 269, in load_user
    return User.query.get(int(id))  # 传入字符串类型，使用数字ID的数据库需要将字符串转换为整数。
  File "/Library/Frameworks/Python.framework/Versions/3.7/lib/python3.7/site-packages/sqlalchemy/orm/query.py", line 959, in get
    return self._get_impl(ident, loading.load_on_pk_identity)
  File "/Library/Frameworks/Python.framework/Versions/3.7/lib/python3.7/site-packages/sqlalchemy/orm/query.py", line 1069, in _get_impl
    return db_load_fn(self, primary_key_identity)
  File "/Library/Frameworks/Python.framework/Versions/3.7/lib/python3.7/site-packages/sqlalchemy/orm/loading.py", line 282, in load_on_pk_identity
    return q.one()
  File "/Library/Frameworks/Python.framework/Versions/3.7/lib/python3.7/site-packages/sqlalchemy/orm/query.py", line 3292, in one
    ret = self.one_or_none()
  File "/Library/Frameworks/Python.framework/Versions/3.7/lib/python3.7/site-packages/sqlalchemy/orm/query.py", line 3261, in one_or_none
    ret = list(self)
  File "/Library/Frameworks/Python.framework/Versions/3.7/lib/python3.7/site-packages/sqlalchemy/orm/query.py", line 3334, in __iter__
    return self._execute_and_instances(context)
  File "/Library/Frameworks/Python.framework/Versions/3.7/lib/python3.7/site-packages/sqlalchemy/orm/query.py", line 3359, in _execute_and_instances
    result = conn.execute(querycontext.statement, self._params)
  File "/Library/Frameworks/Python.framework/Versions/3.7/lib/python3.7/site-packages/sqlalchemy/engine/base.py", line 988, in execute
    return meth(self, multiparams, params)
  File "/Library/Frameworks/Python.framework/Versions/3.7/lib/python3.7/site-packages/sqlalchemy/sql/elements.py", line 287, in _execute_on_connection
    return connection._execute_clauseelement(self, multiparams, params)
  File "/Library/Frameworks/Python.framework/Versions/3.7/lib/python3.7/site-packages/sqlalchemy/engine/base.py", line 1107, in _execute_clauseelement
    distilled_params,
  File "/Library/Frameworks/Python.framework/Versions/3.7/lib/python3.7/site-packages/sqlalchemy/engine/base.py", line 1253, in _execute_context
    e, statement, parameters, cursor, context
  File "/Library/Frameworks/Python.framework/Versions/3.7/lib/python3.7/site-packages/sqlalchemy/engine/base.py", line 1473, in _handle_dbapi_exception
    util.raise_from_cause(sqlalchemy_exception, exc_info)
  File "/Library/Frameworks/Python.framework/Versions/3.7/lib/python3.7/site-packages/sqlalchemy/util/compat.py", line 398, in raise_from_cause
    reraise(type(exception), exception, tb=exc_tb, cause=cause)
  File "/Library/Frameworks/Python.framework/Versions/3.7/lib/python3.7/site-packages/sqlalchemy/util/compat.py", line 152, in reraise
    raise value.with_traceback(tb)
  File "/Library/Frameworks/Python.framework/Versions/3.7/lib/python3.7/site-packages/sqlalchemy/engine/base.py", line 1249, in _execute_context
    cursor, statement, parameters, context
  File "/Library/Frameworks/Python.framework/Versions/3.7/lib/python3.7/site-packages/sqlalchemy/engine/default.py", line 552, in do_execute
    cursor.execute(statement, parameters)
sqlalchemy.exc.OperationalError: (sqlite3.OperationalError) no such table: user
[SQL: SELECT user.id AS user_id, user.username AS user_username, user.email AS user_email, user.password_hash AS user_password_hash, user.about_me AS user_about_me, user.last_seen AS user_last_seen, user.token AS user_token, user.token_expiration AS user_token_expiration, user.last_message_read_time AS user_last_message_read_time 
FROM user 
WHERE user.id = ?]
[parameters: (1,)]
(Background on this error at: http://sqlalche.me/e/e3q8)
2020-02-10 18:15:39,305 ERROR: Exception on /auth/logout [GET] [in /Library/Frameworks/Python.framework/Versions/3.7/lib/python3.7/site-packages/flask/app.py:1761]
Traceback (most recent call last):
  File "/Library/Frameworks/Python.framework/Versions/3.7/lib/python3.7/site-packages/sqlalchemy/engine/base.py", line 1249, in _execute_context
    cursor, statement, parameters, context
  File "/Library/Frameworks/Python.framework/Versions/3.7/lib/python3.7/site-packages/sqlalchemy/engine/default.py", line 552, in do_execute
    cursor.execute(statement, parameters)
sqlite3.OperationalError: no such table: user

The above exception was the direct cause of the following exception:

Traceback (most recent call last):
  File "/Library/Frameworks/Python.framework/Versions/3.7/lib/python3.7/site-packages/flask/app.py", line 2292, in wsgi_app
    response = self.full_dispatch_request()
  File "/Library/Frameworks/Python.framework/Versions/3.7/lib/python3.7/site-packages/flask/app.py", line 1815, in full_dispatch_request
    rv = self.handle_user_exception(e)
  File "/Library/Frameworks/Python.framework/Versions/3.7/lib/python3.7/site-packages/flask/app.py", line 1718, in handle_user_exception
    reraise(exc_type, exc_value, tb)
  File "/Library/Frameworks/Python.framework/Versions/3.7/lib/python3.7/site-packages/flask/_compat.py", line 35, in reraise
    raise value
  File "/Library/Frameworks/Python.framework/Versions/3.7/lib/python3.7/site-packages/flask/app.py", line 1811, in full_dispatch_request
    rv = self.preprocess_request()
  File "/Library/Frameworks/Python.framework/Versions/3.7/lib/python3.7/site-packages/flask/app.py", line 2087, in preprocess_request
    rv = func()
  File "/Users/yhz/Desktop/pypy/Flask_Learn/app/main/routes.py", line 21, in before_request
    if current_user.is_authenticated:
  File "/Library/Frameworks/Python.framework/Versions/3.7/lib/python3.7/site-packages/werkzeug/local.py", line 347, in __getattr__
    return getattr(self._get_current_object(), name)
  File "/Library/Frameworks/Python.framework/Versions/3.7/lib/python3.7/site-packages/werkzeug/local.py", line 306, in _get_current_object
    return self.__local()
  File "/Library/Frameworks/Python.framework/Versions/3.7/lib/python3.7/site-packages/flask_login/utils.py", line 26, in <lambda>
    current_user = LocalProxy(lambda: _get_user())
  File "/Library/Frameworks/Python.framework/Versions/3.7/lib/python3.7/site-packages/flask_login/utils.py", line 335, in _get_user
    current_app.login_manager._load_user()
  File "/Library/Frameworks/Python.framework/Versions/3.7/lib/python3.7/site-packages/flask_login/login_manager.py", line 359, in _load_user
    return self.reload_user()
  File "/Library/Frameworks/Python.framework/Versions/3.7/lib/python3.7/site-packages/flask_login/login_manager.py", line 321, in reload_user
    user = self.user_callback(user_id)
  File "/Users/yhz/Desktop/pypy/Flask_Learn/app/models.py", line 269, in load_user
    return User.query.get(int(id))  # 传入字符串类型，使用数字ID的数据库需要将字符串转换为整数。
  File "/Library/Frameworks/Python.framework/Versions/3.7/lib/python3.7/site-packages/sqlalchemy/orm/query.py", line 959, in get
    return self._get_impl(ident, loading.load_on_pk_identity)
  File "/Library/Frameworks/Python.framework/Versions/3.7/lib/python3.7/site-packages/sqlalchemy/orm/query.py", line 1069, in _get_impl
    return db_load_fn(self, primary_key_identity)
  File "/Library/Frameworks/Python.framework/Versions/3.7/lib/python3.7/site-packages/sqlalchemy/orm/loading.py", line 282, in load_on_pk_identity
    return q.one()
  File "/Library/Frameworks/Python.framework/Versions/3.7/lib/python3.7/site-packages/sqlalchemy/orm/query.py", line 3292, in one
    ret = self.one_or_none()
  File "/Library/Frameworks/Python.framework/Versions/3.7/lib/python3.7/site-packages/sqlalchemy/orm/query.py", line 3261, in one_or_none
    ret = list(self)
  File "/Library/Frameworks/Python.framework/Versions/3.7/lib/python3.7/site-packages/sqlalchemy/orm/query.py", line 3334, in __iter__
    return self._execute_and_instances(context)
  File "/Library/Frameworks/Python.framework/Versions/3.7/lib/python3.7/site-packages/sqlalchemy/orm/query.py", line 3359, in _execute_and_instances
    result = conn.execute(querycontext.statement, self._params)
  File "/Library/Frameworks/Python.framework/Versions/3.7/lib/python3.7/site-packages/sqlalchemy/engine/base.py", line 988, in execute
    return meth(self, multiparams, params)
  File "/Library/Frameworks/Python.framework/Versions/3.7/lib/python3.7/site-packages/sqlalchemy/sql/elements.py", line 287, in _execute_on_connection
    return connection._execute_clauseelement(self, multiparams, params)
  File "/Library/Frameworks/Python.framework/Versions/3.7/lib/python3.7/site-packages/sqlalchemy/engine/base.py", line 1107, in _execute_clauseelement
    distilled_params,
  File "/Library/Frameworks/Python.framework/Versions/3.7/lib/python3.7/site-packages/sqlalchemy/engine/base.py", line 1253, in _execute_context
    e, statement, parameters, cursor, context
  File "/Library/Frameworks/Python.framework/Versions/3.7/lib/python3.7/site-packages/sqlalchemy/engine/base.py", line 1473, in _handle_dbapi_exception
    util.raise_from_cause(sqlalchemy_exception, exc_info)
  File "/Library/Frameworks/Python.framework/Versions/3.7/lib/python3.7/site-packages/sqlalchemy/util/compat.py", line 398, in raise_from_cause
    reraise(type(exception), exception, tb=exc_tb, cause=cause)
  File "/Library/Frameworks/Python.framework/Versions/3.7/lib/python3.7/site-packages/sqlalchemy/util/compat.py", line 152, in reraise
    raise value.with_traceback(tb)
  File "/Library/Frameworks/Python.framework/Versions/3.7/lib/python3.7/site-packages/sqlalchemy/engine/base.py", line 1249, in _execute_context
    cursor, statement, parameters, context
  File "/Library/Frameworks/Python.framework/Versions/3.7/lib/python3.7/site-packages/sqlalchemy/engine/default.py", line 552, in do_execute
    cursor.execute(statement, parameters)
sqlalchemy.exc.OperationalError: (sqlite3.OperationalError) no such table: user
[SQL: SELECT user.id AS user_id, user.username AS user_username, user.email AS user_email, user.password_hash AS user_password_hash, user.about_me AS user_about_me, user.last_seen AS user_last_seen, user.token AS user_token, user.token_expiration AS user_token_expiration, user.last_message_read_time AS user_last_message_read_time 
FROM user 
WHERE user.id = ?]
[parameters: (1,)]
(Background on this error at: http://sqlalche.me/e/e3q8)
2020-02-10 18:15:41,956 ERROR: Exception on /index [GET] [in /Library/Frameworks/Python.framework/Versions/3.7/lib/python3.7/site-packages/flask/app.py:1761]
Traceback (most recent call last):
  File "/Library/Frameworks/Python.framework/Versions/3.7/lib/python3.7/site-packages/sqlalchemy/engine/base.py", line 1249, in _execute_context
    cursor, statement, parameters, context
  File "/Library/Frameworks/Python.framework/Versions/3.7/lib/python3.7/site-packages/sqlalchemy/engine/default.py", line 552, in do_execute
    cursor.execute(statement, parameters)
sqlite3.OperationalError: no such table: user

The above exception was the direct cause of the following exception:

Traceback (most recent call last):
  File "/Library/Frameworks/Python.framework/Versions/3.7/lib/python3.7/site-packages/flask/app.py", line 2292, in wsgi_app
    response = self.full_dispatch_request()
  File "/Library/Frameworks/Python.framework/Versions/3.7/lib/python3.7/site-packages/flask/app.py", line 1815, in full_dispatch_request
    rv = self.handle_user_exception(e)
  File "/Library/Frameworks/Python.framework/Versions/3.7/lib/python3.7/site-packages/flask/app.py", line 1718, in handle_user_exception
    reraise(exc_type, exc_value, tb)
  File "/Library/Frameworks/Python.framework/Versions/3.7/lib/python3.7/site-packages/flask/_compat.py", line 35, in reraise
    raise value
  File "/Library/Frameworks/Python.framework/Versions/3.7/lib/python3.7/site-packages/flask/app.py", line 1811, in full_dispatch_request
    rv = self.preprocess_request()
  File "/Library/Frameworks/Python.framework/Versions/3.7/lib/python3.7/site-packages/flask/app.py", line 2087, in preprocess_request
    rv = func()
  File "/Users/yhz/Desktop/pypy/Flask_Learn/app/main/routes.py", line 21, in before_request
    if current_user.is_authenticated:
  File "/Library/Frameworks/Python.framework/Versions/3.7/lib/python3.7/site-packages/werkzeug/local.py", line 347, in __getattr__
    return getattr(self._get_current_object(), name)
  File "/Library/Frameworks/Python.framework/Versions/3.7/lib/python3.7/site-packages/werkzeug/local.py", line 306, in _get_current_object
    return self.__local()
  File "/Library/Frameworks/Python.framework/Versions/3.7/lib/python3.7/site-packages/flask_login/utils.py", line 26, in <lambda>
    current_user = LocalProxy(lambda: _get_user())
  File "/Library/Frameworks/Python.framework/Versions/3.7/lib/python3.7/site-packages/flask_login/utils.py", line 335, in _get_user
    current_app.login_manager._load_user()
  File "/Library/Frameworks/Python.framework/Versions/3.7/lib/python3.7/site-packages/flask_login/login_manager.py", line 359, in _load_user
    return self.reload_user()
  File "/Library/Frameworks/Python.framework/Versions/3.7/lib/python3.7/site-packages/flask_login/login_manager.py", line 321, in reload_user
    user = self.user_callback(user_id)
  File "/Users/yhz/Desktop/pypy/Flask_Learn/app/models.py", line 269, in load_user
    return User.query.get(int(id))  # 传入字符串类型，使用数字ID的数据库需要将字符串转换为整数。
  File "/Library/Frameworks/Python.framework/Versions/3.7/lib/python3.7/site-packages/sqlalchemy/orm/query.py", line 959, in get
    return self._get_impl(ident, loading.load_on_pk_identity)
  File "/Library/Frameworks/Python.framework/Versions/3.7/lib/python3.7/site-packages/sqlalchemy/orm/query.py", line 1069, in _get_impl
    return db_load_fn(self, primary_key_identity)
  File "/Library/Frameworks/Python.framework/Versions/3.7/lib/python3.7/site-packages/sqlalchemy/orm/loading.py", line 282, in load_on_pk_identity
    return q.one()
  File "/Library/Frameworks/Python.framework/Versions/3.7/lib/python3.7/site-packages/sqlalchemy/orm/query.py", line 3292, in one
    ret = self.one_or_none()
  File "/Library/Frameworks/Python.framework/Versions/3.7/lib/python3.7/site-packages/sqlalchemy/orm/query.py", line 3261, in one_or_none
    ret = list(self)
  File "/Library/Frameworks/Python.framework/Versions/3.7/lib/python3.7/site-packages/sqlalchemy/orm/query.py", line 3334, in __iter__
    return self._execute_and_instances(context)
  File "/Library/Frameworks/Python.framework/Versions/3.7/lib/python3.7/site-packages/sqlalchemy/orm/query.py", line 3359, in _execute_and_instances
    result = conn.execute(querycontext.statement, self._params)
  File "/Library/Frameworks/Python.framework/Versions/3.7/lib/python3.7/site-packages/sqlalchemy/engine/base.py", line 988, in execute
    return meth(self, multiparams, params)
  File "/Library/Frameworks/Python.framework/Versions/3.7/lib/python3.7/site-packages/sqlalchemy/sql/elements.py", line 287, in _execute_on_connection
    return connection._execute_clauseelement(self, multiparams, params)
  File "/Library/Frameworks/Python.framework/Versions/3.7/lib/python3.7/site-packages/sqlalchemy/engine/base.py", line 1107, in _execute_clauseelement
    distilled_params,
  File "/Library/Frameworks/Python.framework/Versions/3.7/lib/python3.7/site-packages/sqlalchemy/engine/base.py", line 1253, in _execute_context
    e, statement, parameters, cursor, context
  File "/Library/Frameworks/Python.framework/Versions/3.7/lib/python3.7/site-packages/sqlalchemy/engine/base.py", line 1473, in _handle_dbapi_exception
    util.raise_from_cause(sqlalchemy_exception, exc_info)
  File "/Library/Frameworks/Python.framework/Versions/3.7/lib/python3.7/site-packages/sqlalchemy/util/compat.py", line 398, in raise_from_cause
    reraise(type(exception), exception, tb=exc_tb, cause=cause)
  File "/Library/Frameworks/Python.framework/Versions/3.7/lib/python3.7/site-packages/sqlalchemy/util/compat.py", line 152, in reraise
    raise value.with_traceback(tb)
  File "/Library/Frameworks/Python.framework/Versions/3.7/lib/python3.7/site-packages/sqlalchemy/engine/base.py", line 1249, in _execute_context
    cursor, statement, parameters, context
  File "/Library/Frameworks/Python.framework/Versions/3.7/lib/python3.7/site-packages/sqlalchemy/engine/default.py", line 552, in do_execute
    cursor.execute(statement, parameters)
sqlalchemy.exc.OperationalError: (sqlite3.OperationalError) no such table: user
[SQL: SELECT user.id AS user_id, user.username AS user_username, user.email AS user_email, user.password_hash AS user_password_hash, user.about_me AS user_about_me, user.last_seen AS user_last_seen, user.token AS user_token, user.token_expiration AS user_token_expiration, user.last_message_read_time AS user_last_message_read_time 
FROM user 
WHERE user.id = ?]
[parameters: (1,)]
(Background on this error at: http://sqlalche.me/e/e3q8)
2020-02-10 18:56:39,288 INFO: Microblog startup [in /Users/yhz/Desktop/pypy/Flask_Learn/app/__init__.py:104]
2020-02-10 18:56:52,858 INFO: Microblog startup [in /Users/yhz/Desktop/pypy/Flask_Learn/app/__init__.py:104]
2020-02-10 18:57:52,807 INFO: Microblog startup [in /Users/yhz/Desktop/pypy/Flask_Learn/app/__init__.py:104]
2020-02-10 18:58:01,823 INFO: Microblog startup [in /Users/yhz/Desktop/pypy/Flask_Learn/app/__init__.py:104]
2020-02-10 19:15:06,261 INFO: Microblog startup [in /Users/yhz/Desktop/pypy/Flask_Learn/app/__init__.py:104]
2020-02-10 19:36:05,988 INFO: Microblog startup [in /Users/yhz/Desktop/pypy/Flask_Learn/app/__init__.py:104]
2020-02-10 19:37:49,491 INFO: Microblog startup [in /Users/yhz/Desktop/pypy/Flask_Learn/app/__init__.py:104]
2020-02-10 19:37:50,921 ERROR: Exception on /auth/login [GET] [in /Library/Frameworks/Python.framework/Versions/3.7/lib/python3.7/site-packages/flask/app.py:1761]
Traceback (most recent call last):
  File "/Library/Frameworks/Python.framework/Versions/3.7/lib/python3.7/site-packages/flask/app.py", line 2292, in wsgi_app
    response = self.full_dispatch_request()
  File "/Library/Frameworks/Python.framework/Versions/3.7/lib/python3.7/site-packages/flask/app.py", line 1815, in full_dispatch_request
    rv = self.handle_user_exception(e)
  File "/Library/Frameworks/Python.framework/Versions/3.7/lib/python3.7/site-packages/flask/app.py", line 1718, in handle_user_exception
    reraise(exc_type, exc_value, tb)
  File "/Library/Frameworks/Python.framework/Versions/3.7/lib/python3.7/site-packages/flask/_compat.py", line 35, in reraise
    raise value
  File "/Library/Frameworks/Python.framework/Versions/3.7/lib/python3.7/site-packages/flask/app.py", line 1813, in full_dispatch_request
    rv = self.dispatch_request()
  File "/Library/Frameworks/Python.framework/Versions/3.7/lib/python3.7/site-packages/flask/app.py", line 1799, in dispatch_request
    return self.view_functions[rule.endpoint](**req.view_args)
  File "/Users/yhz/Desktop/pypy/Flask_Learn/app/auth/routes.py", line 43, in login
    return render_template('auth/login.html', title=_('Sign In'), form=form)
  File "/Library/Frameworks/Python.framework/Versions/3.7/lib/python3.7/site-packages/flask/templating.py", line 135, in render_template
    context, ctx.app)
  File "/Library/Frameworks/Python.framework/Versions/3.7/lib/python3.7/site-packages/flask/templating.py", line 117, in _render
    rv = template.render(context)
  File "/Library/Frameworks/Python.framework/Versions/3.7/lib/python3.7/site-packages/jinja2/asyncsupport.py", line 76, in render
    return original_render(self, *args, **kwargs)
  File "/Library/Frameworks/Python.framework/Versions/3.7/lib/python3.7/site-packages/jinja2/environment.py", line 1008, in render
    return self.environment.handle_exception(exc_info, True)
  File "/Library/Frameworks/Python.framework/Versions/3.7/lib/python3.7/site-packages/jinja2/environment.py", line 780, in handle_exception
    reraise(exc_type, exc_value, tb)
  File "/Library/Frameworks/Python.framework/Versions/3.7/lib/python3.7/site-packages/jinja2/_compat.py", line 37, in reraise
    raise value.with_traceback(tb)
  File "/Users/yhz/Desktop/pypy/Flask_Learn/app/templates/auth/login.html", line 4, in top-level template code
    {% import 'bootstrap/wtf.html' as wtf %}
  File "/Users/yhz/Desktop/pypy/Flask_Learn/app/templates/base.html", line 2, in top-level template code
    {% extends 'bootstrap/base.html' %}
  File "/Library/Frameworks/Python.framework/Versions/3.7/lib/python3.7/site-packages/flask_bootstrap/templates/bootstrap/base.html", line 1, in top-level template code
    {% block doc -%}
  File "/Library/Frameworks/Python.framework/Versions/3.7/lib/python3.7/site-packages/flask_bootstrap/templates/bootstrap/base.html", line 4, in block "doc"
    {%- block html %}
  File "/Library/Frameworks/Python.framework/Versions/3.7/lib/python3.7/site-packages/flask_bootstrap/templates/bootstrap/base.html", line 20, in block "html"
    {% block body -%}
  File "/Library/Frameworks/Python.framework/Versions/3.7/lib/python3.7/site-packages/flask_bootstrap/templates/bootstrap/base.html", line 21, in block "body"
    {% block navbar %}
  File "/Users/yhz/Desktop/pypy/Flask_Learn/app/templates/base.html", line 24, in block "navbar"
    <a class="navbar-brand" href="{{ url_for('yhz.yhz1') }}">测试</a>
  File "/Library/Frameworks/Python.framework/Versions/3.7/lib/python3.7/site-packages/flask/helpers.py", line 356, in url_for
    return appctx.app.handle_url_build_error(error, endpoint, values)
  File "/Library/Frameworks/Python.framework/Versions/3.7/lib/python3.7/site-packages/flask/app.py", line 2061, in handle_url_build_error
    reraise(exc_type, exc_value, tb)
  File "/Library/Frameworks/Python.framework/Versions/3.7/lib/python3.7/site-packages/flask/_compat.py", line 35, in reraise
    raise value
  File "/Library/Frameworks/Python.framework/Versions/3.7/lib/python3.7/site-packages/flask/helpers.py", line 345, in url_for
    force_external=external)
  File "/Library/Frameworks/Python.framework/Versions/3.7/lib/python3.7/site-packages/werkzeug/routing.py", line 1776, in build
    raise BuildError(endpoint, values, method, self)
werkzeug.routing.BuildError: Could not build url for endpoint 'yhz.yhz1'. Did you mean 'auth.login' instead?
2020-02-10 19:39:57,072 INFO: Microblog startup [in /Users/yhz/Desktop/pypy/Flask_Learn/app/__init__.py:104]
2020-02-10 19:39:59,794 ERROR: Exception on /auth/login [GET] [in /Library/Frameworks/Python.framework/Versions/3.7/lib/python3.7/site-packages/flask/app.py:1761]
Traceback (most recent call last):
  File "/Library/Frameworks/Python.framework/Versions/3.7/lib/python3.7/site-packages/flask/app.py", line 2292, in wsgi_app
    response = self.full_dispatch_request()
  File "/Library/Frameworks/Python.framework/Versions/3.7/lib/python3.7/site-packages/flask/app.py", line 1815, in full_dispatch_request
    rv = self.handle_user_exception(e)
  File "/Library/Frameworks/Python.framework/Versions/3.7/lib/python3.7/site-packages/flask/app.py", line 1718, in handle_user_exception
    reraise(exc_type, exc_value, tb)
  File "/Library/Frameworks/Python.framework/Versions/3.7/lib/python3.7/site-packages/flask/_compat.py", line 35, in reraise
    raise value
  File "/Library/Frameworks/Python.framework/Versions/3.7/lib/python3.7/site-packages/flask/app.py", line 1813, in full_dispatch_request
    rv = self.dispatch_request()
  File "/Library/Frameworks/Python.framework/Versions/3.7/lib/python3.7/site-packages/flask/app.py", line 1799, in dispatch_request
    return self.view_functions[rule.endpoint](**req.view_args)
  File "/Users/yhz/Desktop/pypy/Flask_Learn/app/auth/routes.py", line 43, in login
    return render_template('auth/login.html', title=_('Sign In'), form=form)
  File "/Library/Frameworks/Python.framework/Versions/3.7/lib/python3.7/site-packages/flask/templating.py", line 135, in render_template
    context, ctx.app)
  File "/Library/Frameworks/Python.framework/Versions/3.7/lib/python3.7/site-packages/flask/templating.py", line 117, in _render
    rv = template.render(context)
  File "/Library/Frameworks/Python.framework/Versions/3.7/lib/python3.7/site-packages/jinja2/asyncsupport.py", line 76, in render
    return original_render(self, *args, **kwargs)
  File "/Library/Frameworks/Python.framework/Versions/3.7/lib/python3.7/site-packages/jinja2/environment.py", line 1008, in render
    return self.environment.handle_exception(exc_info, True)
  File "/Library/Frameworks/Python.framework/Versions/3.7/lib/python3.7/site-packages/jinja2/environment.py", line 780, in handle_exception
    reraise(exc_type, exc_value, tb)
  File "/Library/Frameworks/Python.framework/Versions/3.7/lib/python3.7/site-packages/jinja2/_compat.py", line 37, in reraise
    raise value.with_traceback(tb)
  File "/Users/yhz/Desktop/pypy/Flask_Learn/app/templates/auth/login.html", line 4, in top-level template code
    {% import 'bootstrap/wtf.html' as wtf %}
  File "/Users/yhz/Desktop/pypy/Flask_Learn/app/templates/base.html", line 2, in top-level template code
    {% extends 'bootstrap/base.html' %}
  File "/Library/Frameworks/Python.framework/Versions/3.7/lib/python3.7/site-packages/flask_bootstrap/templates/bootstrap/base.html", line 1, in top-level template code
    {% block doc -%}
  File "/Library/Frameworks/Python.framework/Versions/3.7/lib/python3.7/site-packages/flask_bootstrap/templates/bootstrap/base.html", line 4, in block "doc"
    {%- block html %}
  File "/Library/Frameworks/Python.framework/Versions/3.7/lib/python3.7/site-packages/flask_bootstrap/templates/bootstrap/base.html", line 20, in block "html"
    {% block body -%}
  File "/Library/Frameworks/Python.framework/Versions/3.7/lib/python3.7/site-packages/flask_bootstrap/templates/bootstrap/base.html", line 21, in block "body"
    {% block navbar %}
  File "/Users/yhz/Desktop/pypy/Flask_Learn/app/templates/base.html", line 24, in block "navbar"
    <a class="navbar-brand" href="{{ url_for('yhz.yhz1') }}">测试</a>
  File "/Library/Frameworks/Python.framework/Versions/3.7/lib/python3.7/site-packages/flask/helpers.py", line 356, in url_for
    return appctx.app.handle_url_build_error(error, endpoint, values)
  File "/Library/Frameworks/Python.framework/Versions/3.7/lib/python3.7/site-packages/flask/app.py", line 2061, in handle_url_build_error
    reraise(exc_type, exc_value, tb)
  File "/Library/Frameworks/Python.framework/Versions/3.7/lib/python3.7/site-packages/flask/_compat.py", line 35, in reraise
    raise value
  File "/Library/Frameworks/Python.framework/Versions/3.7/lib/python3.7/site-packages/flask/helpers.py", line 345, in url_for
    force_external=external)
  File "/Library/Frameworks/Python.framework/Versions/3.7/lib/python3.7/site-packages/werkzeug/routing.py", line 1776, in build
    raise BuildError(endpoint, values, method, self)
werkzeug.routing.BuildError: Could not build url for endpoint 'yhz.yhz1'. Did you mean 'auth.login' instead?
2020-02-10 19:40:02,657 ERROR: Exception on /auth/login [GET] [in /Library/Frameworks/Python.framework/Versions/3.7/lib/python3.7/site-packages/flask/app.py:1761]
Traceback (most recent call last):
  File "/Library/Frameworks/Python.framework/Versions/3.7/lib/python3.7/site-packages/flask/app.py", line 2292, in wsgi_app
    response = self.full_dispatch_request()
  File "/Library/Frameworks/Python.framework/Versions/3.7/lib/python3.7/site-packages/flask/app.py", line 1815, in full_dispatch_request
    rv = self.handle_user_exception(e)
  File "/Library/Frameworks/Python.framework/Versions/3.7/lib/python3.7/site-packages/flask/app.py", line 1718, in handle_user_exception
    reraise(exc_type, exc_value, tb)
  File "/Library/Frameworks/Python.framework/Versions/3.7/lib/python3.7/site-packages/flask/_compat.py", line 35, in reraise
    raise value
  File "/Library/Frameworks/Python.framework/Versions/3.7/lib/python3.7/site-packages/flask/app.py", line 1813, in full_dispatch_request
    rv = self.dispatch_request()
  File "/Library/Frameworks/Python.framework/Versions/3.7/lib/python3.7/site-packages/flask/app.py", line 1799, in dispatch_request
    return self.view_functions[rule.endpoint](**req.view_args)
  File "/Users/yhz/Desktop/pypy/Flask_Learn/app/auth/routes.py", line 43, in login
    return render_template('auth/login.html', title=_('Sign In'), form=form)
  File "/Library/Frameworks/Python.framework/Versions/3.7/lib/python3.7/site-packages/flask/templating.py", line 135, in render_template
    context, ctx.app)
  File "/Library/Frameworks/Python.framework/Versions/3.7/lib/python3.7/site-packages/flask/templating.py", line 117, in _render
    rv = template.render(context)
  File "/Library/Frameworks/Python.framework/Versions/3.7/lib/python3.7/site-packages/jinja2/asyncsupport.py", line 76, in render
    return original_render(self, *args, **kwargs)
  File "/Library/Frameworks/Python.framework/Versions/3.7/lib/python3.7/site-packages/jinja2/environment.py", line 1008, in render
    return self.environment.handle_exception(exc_info, True)
  File "/Library/Frameworks/Python.framework/Versions/3.7/lib/python3.7/site-packages/jinja2/environment.py", line 780, in handle_exception
    reraise(exc_type, exc_value, tb)
  File "/Library/Frameworks/Python.framework/Versions/3.7/lib/python3.7/site-packages/jinja2/_compat.py", line 37, in reraise
    raise value.with_traceback(tb)
  File "/Users/yhz/Desktop/pypy/Flask_Learn/app/templates/auth/login.html", line 4, in top-level template code
    {% import 'bootstrap/wtf.html' as wtf %}
  File "/Users/yhz/Desktop/pypy/Flask_Learn/app/templates/base.html", line 2, in top-level template code
    {% extends 'bootstrap/base.html' %}
  File "/Library/Frameworks/Python.framework/Versions/3.7/lib/python3.7/site-packages/flask_bootstrap/templates/bootstrap/base.html", line 1, in top-level template code
    {% block doc -%}
  File "/Library/Frameworks/Python.framework/Versions/3.7/lib/python3.7/site-packages/flask_bootstrap/templates/bootstrap/base.html", line 4, in block "doc"
    {%- block html %}
  File "/Library/Frameworks/Python.framework/Versions/3.7/lib/python3.7/site-packages/flask_bootstrap/templates/bootstrap/base.html", line 20, in block "html"
    {% block body -%}
  File "/Library/Frameworks/Python.framework/Versions/3.7/lib/python3.7/site-packages/flask_bootstrap/templates/bootstrap/base.html", line 21, in block "body"
    {% block navbar %}
  File "/Users/yhz/Desktop/pypy/Flask_Learn/app/templates/base.html", line 24, in block "navbar"
    <a class="navbar-brand" href="{{ url_for('yhz.yhz1') }}">测试</a>
  File "/Library/Frameworks/Python.framework/Versions/3.7/lib/python3.7/site-packages/flask/helpers.py", line 356, in url_for
    return appctx.app.handle_url_build_error(error, endpoint, values)
  File "/Library/Frameworks/Python.framework/Versions/3.7/lib/python3.7/site-packages/flask/app.py", line 2061, in handle_url_build_error
    reraise(exc_type, exc_value, tb)
  File "/Library/Frameworks/Python.framework/Versions/3.7/lib/python3.7/site-packages/flask/_compat.py", line 35, in reraise
    raise value
  File "/Library/Frameworks/Python.framework/Versions/3.7/lib/python3.7/site-packages/flask/helpers.py", line 345, in url_for
    force_external=external)
  File "/Library/Frameworks/Python.framework/Versions/3.7/lib/python3.7/site-packages/werkzeug/routing.py", line 1776, in build
    raise BuildError(endpoint, values, method, self)
werkzeug.routing.BuildError: Could not build url for endpoint 'yhz.yhz1'. Did you mean 'auth.login' instead?
2020-02-10 19:40:05,355 ERROR: Exception on /auth/login [GET] [in /Library/Frameworks/Python.framework/Versions/3.7/lib/python3.7/site-packages/flask/app.py:1761]
Traceback (most recent call last):
  File "/Library/Frameworks/Python.framework/Versions/3.7/lib/python3.7/site-packages/flask/app.py", line 2292, in wsgi_app
    response = self.full_dispatch_request()
  File "/Library/Frameworks/Python.framework/Versions/3.7/lib/python3.7/site-packages/flask/app.py", line 1815, in full_dispatch_request
    rv = self.handle_user_exception(e)
  File "/Library/Frameworks/Python.framework/Versions/3.7/lib/python3.7/site-packages/flask/app.py", line 1718, in handle_user_exception
    reraise(exc_type, exc_value, tb)
  File "/Library/Frameworks/Python.framework/Versions/3.7/lib/python3.7/site-packages/flask/_compat.py", line 35, in reraise
    raise value
  File "/Library/Frameworks/Python.framework/Versions/3.7/lib/python3.7/site-packages/flask/app.py", line 1813, in full_dispatch_request
    rv = self.dispatch_request()
  File "/Library/Frameworks/Python.framework/Versions/3.7/lib/python3.7/site-packages/flask/app.py", line 1799, in dispatch_request
    return self.view_functions[rule.endpoint](**req.view_args)
  File "/Users/yhz/Desktop/pypy/Flask_Learn/app/auth/routes.py", line 43, in login
    return render_template('auth/login.html', title=_('Sign In'), form=form)
  File "/Library/Frameworks/Python.framework/Versions/3.7/lib/python3.7/site-packages/flask/templating.py", line 135, in render_template
    context, ctx.app)
  File "/Library/Frameworks/Python.framework/Versions/3.7/lib/python3.7/site-packages/flask/templating.py", line 117, in _render
    rv = template.render(context)
  File "/Library/Frameworks/Python.framework/Versions/3.7/lib/python3.7/site-packages/jinja2/asyncsupport.py", line 76, in render
    return original_render(self, *args, **kwargs)
  File "/Library/Frameworks/Python.framework/Versions/3.7/lib/python3.7/site-packages/jinja2/environment.py", line 1008, in render
    return self.environment.handle_exception(exc_info, True)
  File "/Library/Frameworks/Python.framework/Versions/3.7/lib/python3.7/site-packages/jinja2/environment.py", line 780, in handle_exception
    reraise(exc_type, exc_value, tb)
  File "/Library/Frameworks/Python.framework/Versions/3.7/lib/python3.7/site-packages/jinja2/_compat.py", line 37, in reraise
    raise value.with_traceback(tb)
  File "/Users/yhz/Desktop/pypy/Flask_Learn/app/templates/auth/login.html", line 4, in top-level template code
    {% import 'bootstrap/wtf.html' as wtf %}
  File "/Users/yhz/Desktop/pypy/Flask_Learn/app/templates/base.html", line 2, in top-level template code
    {% extends 'bootstrap/base.html' %}
  File "/Library/Frameworks/Python.framework/Versions/3.7/lib/python3.7/site-packages/flask_bootstrap/templates/bootstrap/base.html", line 1, in top-level template code
    {% block doc -%}
  File "/Library/Frameworks/Python.framework/Versions/3.7/lib/python3.7/site-packages/flask_bootstrap/templates/bootstrap/base.html", line 4, in block "doc"
    {%- block html %}
  File "/Library/Frameworks/Python.framework/Versions/3.7/lib/python3.7/site-packages/flask_bootstrap/templates/bootstrap/base.html", line 20, in block "html"
    {% block body -%}
  File "/Library/Frameworks/Python.framework/Versions/3.7/lib/python3.7/site-packages/flask_bootstrap/templates/bootstrap/base.html", line 21, in block "body"
    {% block navbar %}
  File "/Users/yhz/Desktop/pypy/Flask_Learn/app/templates/base.html", line 24, in block "navbar"
    <a class="navbar-brand" href="{{ url_for('yhz.yhz1') }}">测试</a>
  File "/Library/Frameworks/Python.framework/Versions/3.7/lib/python3.7/site-packages/flask/helpers.py", line 356, in url_for
    return appctx.app.handle_url_build_error(error, endpoint, values)
  File "/Library/Frameworks/Python.framework/Versions/3.7/lib/python3.7/site-packages/flask/app.py", line 2061, in handle_url_build_error
    reraise(exc_type, exc_value, tb)
  File "/Library/Frameworks/Python.framework/Versions/3.7/lib/python3.7/site-packages/flask/_compat.py", line 35, in reraise
    raise value
  File "/Library/Frameworks/Python.framework/Versions/3.7/lib/python3.7/site-packages/flask/helpers.py", line 345, in url_for
    force_external=external)
  File "/Library/Frameworks/Python.framework/Versions/3.7/lib/python3.7/site-packages/werkzeug/routing.py", line 1776, in build
    raise BuildError(endpoint, values, method, self)
werkzeug.routing.BuildError: Could not build url for endpoint 'yhz.yhz1'. Did you mean 'auth.login' instead?
2020-02-10 19:40:12,605 ERROR: Exception on /auth/register [POST] [in /Library/Frameworks/Python.framework/Versions/3.7/lib/python3.7/site-packages/flask/app.py:1761]
Traceback (most recent call last):
  File "/Library/Frameworks/Python.framework/Versions/3.7/lib/python3.7/site-packages/flask/app.py", line 2292, in wsgi_app
    response = self.full_dispatch_request()
  File "/Library/Frameworks/Python.framework/Versions/3.7/lib/python3.7/site-packages/flask/app.py", line 1815, in full_dispatch_request
    rv = self.handle_user_exception(e)
  File "/Library/Frameworks/Python.framework/Versions/3.7/lib/python3.7/site-packages/flask/app.py", line 1718, in handle_user_exception
    reraise(exc_type, exc_value, tb)
  File "/Library/Frameworks/Python.framework/Versions/3.7/lib/python3.7/site-packages/flask/_compat.py", line 35, in reraise
    raise value
  File "/Library/Frameworks/Python.framework/Versions/3.7/lib/python3.7/site-packages/flask/app.py", line 1813, in full_dispatch_request
    rv = self.dispatch_request()
  File "/Library/Frameworks/Python.framework/Versions/3.7/lib/python3.7/site-packages/flask/app.py", line 1799, in dispatch_request
    return self.view_functions[rule.endpoint](**req.view_args)
  File "/Users/yhz/Desktop/pypy/Flask_Learn/app/auth/routes.py", line 64, in register
    return render_template('auth/register.html', title=_('Register'), form=form)
  File "/Library/Frameworks/Python.framework/Versions/3.7/lib/python3.7/site-packages/flask/templating.py", line 135, in render_template
    context, ctx.app)
  File "/Library/Frameworks/Python.framework/Versions/3.7/lib/python3.7/site-packages/flask/templating.py", line 117, in _render
    rv = template.render(context)
  File "/Library/Frameworks/Python.framework/Versions/3.7/lib/python3.7/site-packages/jinja2/asyncsupport.py", line 76, in render
    return original_render(self, *args, **kwargs)
  File "/Library/Frameworks/Python.framework/Versions/3.7/lib/python3.7/site-packages/jinja2/environment.py", line 1008, in render
    return self.environment.handle_exception(exc_info, True)
  File "/Library/Frameworks/Python.framework/Versions/3.7/lib/python3.7/site-packages/jinja2/environment.py", line 780, in handle_exception
    reraise(exc_type, exc_value, tb)
  File "/Library/Frameworks/Python.framework/Versions/3.7/lib/python3.7/site-packages/jinja2/_compat.py", line 37, in reraise
    raise value.with_traceback(tb)
  File "/Users/yhz/Desktop/pypy/Flask_Learn/app/templates/auth/register.html", line 4, in top-level template code
    {% import 'bootstrap/wtf.html' as wtf %}
  File "/Users/yhz/Desktop/pypy/Flask_Learn/app/templates/base.html", line 2, in top-level template code
    {% extends 'bootstrap/base.html' %}
  File "/Library/Frameworks/Python.framework/Versions/3.7/lib/python3.7/site-packages/flask_bootstrap/templates/bootstrap/base.html", line 1, in top-level template code
    {% block doc -%}
  File "/Library/Frameworks/Python.framework/Versions/3.7/lib/python3.7/site-packages/flask_bootstrap/templates/bootstrap/base.html", line 4, in block "doc"
    {%- block html %}
  File "/Library/Frameworks/Python.framework/Versions/3.7/lib/python3.7/site-packages/flask_bootstrap/templates/bootstrap/base.html", line 20, in block "html"
    {% block body -%}
  File "/Library/Frameworks/Python.framework/Versions/3.7/lib/python3.7/site-packages/flask_bootstrap/templates/bootstrap/base.html", line 21, in block "body"
    {% block navbar %}
  File "/Users/yhz/Desktop/pypy/Flask_Learn/app/templates/base.html", line 24, in block "navbar"
    <a class="navbar-brand" href="{{ url_for('yhz.yhz1') }}">测试</a>
  File "/Library/Frameworks/Python.framework/Versions/3.7/lib/python3.7/site-packages/flask/helpers.py", line 356, in url_for
    return appctx.app.handle_url_build_error(error, endpoint, values)
  File "/Library/Frameworks/Python.framework/Versions/3.7/lib/python3.7/site-packages/flask/app.py", line 2061, in handle_url_build_error
    reraise(exc_type, exc_value, tb)
  File "/Library/Frameworks/Python.framework/Versions/3.7/lib/python3.7/site-packages/flask/_compat.py", line 35, in reraise
    raise value
  File "/Library/Frameworks/Python.framework/Versions/3.7/lib/python3.7/site-packages/flask/helpers.py", line 345, in url_for
    force_external=external)
  File "/Library/Frameworks/Python.framework/Versions/3.7/lib/python3.7/site-packages/werkzeug/routing.py", line 1776, in build
    raise BuildError(endpoint, values, method, self)
werkzeug.routing.BuildError: Could not build url for endpoint 'yhz.yhz1'. Did you mean 'auth.login' instead?
2020-02-10 19:42:19,934 INFO: Microblog startup [in /Users/yhz/Desktop/pypy/Flask_Learn/app/__init__.py:104]
2020-02-10 19:42:36,525 ERROR: Exception on /auth/register [POST] [in /Library/Frameworks/Python.framework/Versions/3.7/lib/python3.7/site-packages/flask/app.py:1761]
Traceback (most recent call last):
  File "/Library/Frameworks/Python.framework/Versions/3.7/lib/python3.7/site-packages/flask/app.py", line 2292, in wsgi_app
    response = self.full_dispatch_request()
  File "/Library/Frameworks/Python.framework/Versions/3.7/lib/python3.7/site-packages/flask/app.py", line 1815, in full_dispatch_request
    rv = self.handle_user_exception(e)
  File "/Library/Frameworks/Python.framework/Versions/3.7/lib/python3.7/site-packages/flask/app.py", line 1718, in handle_user_exception
    reraise(exc_type, exc_value, tb)
  File "/Library/Frameworks/Python.framework/Versions/3.7/lib/python3.7/site-packages/flask/_compat.py", line 35, in reraise
    raise value
  File "/Library/Frameworks/Python.framework/Versions/3.7/lib/python3.7/site-packages/flask/app.py", line 1813, in full_dispatch_request
    rv = self.dispatch_request()
  File "/Library/Frameworks/Python.framework/Versions/3.7/lib/python3.7/site-packages/flask/app.py", line 1799, in dispatch_request
    return self.view_functions[rule.endpoint](**req.view_args)
  File "/Users/yhz/Desktop/pypy/Flask_Learn/app/auth/routes.py", line 64, in register
    return render_template('auth/register.html', title=_('Register'), form=form)
  File "/Library/Frameworks/Python.framework/Versions/3.7/lib/python3.7/site-packages/flask/templating.py", line 135, in render_template
    context, ctx.app)
  File "/Library/Frameworks/Python.framework/Versions/3.7/lib/python3.7/site-packages/flask/templating.py", line 117, in _render
    rv = template.render(context)
  File "/Library/Frameworks/Python.framework/Versions/3.7/lib/python3.7/site-packages/jinja2/asyncsupport.py", line 76, in render
    return original_render(self, *args, **kwargs)
  File "/Library/Frameworks/Python.framework/Versions/3.7/lib/python3.7/site-packages/jinja2/environment.py", line 1008, in render
    return self.environment.handle_exception(exc_info, True)
  File "/Library/Frameworks/Python.framework/Versions/3.7/lib/python3.7/site-packages/jinja2/environment.py", line 780, in handle_exception
    reraise(exc_type, exc_value, tb)
  File "/Library/Frameworks/Python.framework/Versions/3.7/lib/python3.7/site-packages/jinja2/_compat.py", line 37, in reraise
    raise value.with_traceback(tb)
  File "/Users/yhz/Desktop/pypy/Flask_Learn/app/templates/auth/register.html", line 4, in top-level template code
    {% import 'bootstrap/wtf.html' as wtf %}
  File "/Users/yhz/Desktop/pypy/Flask_Learn/app/templates/base.html", line 2, in top-level template code
    {% extends 'bootstrap/base.html' %}
  File "/Library/Frameworks/Python.framework/Versions/3.7/lib/python3.7/site-packages/flask_bootstrap/templates/bootstrap/base.html", line 1, in top-level template code
    {% block doc -%}
  File "/Library/Frameworks/Python.framework/Versions/3.7/lib/python3.7/site-packages/flask_bootstrap/templates/bootstrap/base.html", line 4, in block "doc"
    {%- block html %}
  File "/Library/Frameworks/Python.framework/Versions/3.7/lib/python3.7/site-packages/flask_bootstrap/templates/bootstrap/base.html", line 20, in block "html"
    {% block body -%}
  File "/Library/Frameworks/Python.framework/Versions/3.7/lib/python3.7/site-packages/flask_bootstrap/templates/bootstrap/base.html", line 21, in block "body"
    {% block navbar %}
  File "/Users/yhz/Desktop/pypy/Flask_Learn/app/templates/base.html", line 24, in block "navbar"
    <a class="navbar-brand" href="{{ url_for('yhz.yhz1') }}">测试</a>
  File "/Library/Frameworks/Python.framework/Versions/3.7/lib/python3.7/site-packages/flask/helpers.py", line 356, in url_for
    return appctx.app.handle_url_build_error(error, endpoint, values)
  File "/Library/Frameworks/Python.framework/Versions/3.7/lib/python3.7/site-packages/flask/app.py", line 2061, in handle_url_build_error
    reraise(exc_type, exc_value, tb)
  File "/Library/Frameworks/Python.framework/Versions/3.7/lib/python3.7/site-packages/flask/_compat.py", line 35, in reraise
    raise value
  File "/Library/Frameworks/Python.framework/Versions/3.7/lib/python3.7/site-packages/flask/helpers.py", line 345, in url_for
    force_external=external)
  File "/Library/Frameworks/Python.framework/Versions/3.7/lib/python3.7/site-packages/werkzeug/routing.py", line 1776, in build
    raise BuildError(endpoint, values, method, self)
werkzeug.routing.BuildError: Could not build url for endpoint 'yhz.yhz1'. Did you mean 'auth.login' instead?
2020-02-10 19:42:45,954 INFO: Microblog startup [in /Users/yhz/Desktop/pypy/Flask_Learn/app/__init__.py:104]
2020-02-10 19:42:48,797 ERROR: Exception on /auth/register [POST] [in /Library/Frameworks/Python.framework/Versions/3.7/lib/python3.7/site-packages/flask/app.py:1761]
Traceback (most recent call last):
  File "/Library/Frameworks/Python.framework/Versions/3.7/lib/python3.7/site-packages/flask/app.py", line 2292, in wsgi_app
    response = self.full_dispatch_request()
  File "/Library/Frameworks/Python.framework/Versions/3.7/lib/python3.7/site-packages/flask/app.py", line 1815, in full_dispatch_request
    rv = self.handle_user_exception(e)
  File "/Library/Frameworks/Python.framework/Versions/3.7/lib/python3.7/site-packages/flask/app.py", line 1718, in handle_user_exception
    reraise(exc_type, exc_value, tb)
  File "/Library/Frameworks/Python.framework/Versions/3.7/lib/python3.7/site-packages/flask/_compat.py", line 35, in reraise
    raise value
  File "/Library/Frameworks/Python.framework/Versions/3.7/lib/python3.7/site-packages/flask/app.py", line 1813, in full_dispatch_request
    rv = self.dispatch_request()
  File "/Library/Frameworks/Python.framework/Versions/3.7/lib/python3.7/site-packages/flask/app.py", line 1799, in dispatch_request
    return self.view_functions[rule.endpoint](**req.view_args)
  File "/Users/yhz/Desktop/pypy/Flask_Learn/app/auth/routes.py", line 64, in register
    return render_template('auth/register.html', title=_('Register'), form=form)
  File "/Library/Frameworks/Python.framework/Versions/3.7/lib/python3.7/site-packages/flask/templating.py", line 135, in render_template
    context, ctx.app)
  File "/Library/Frameworks/Python.framework/Versions/3.7/lib/python3.7/site-packages/flask/templating.py", line 117, in _render
    rv = template.render(context)
  File "/Library/Frameworks/Python.framework/Versions/3.7/lib/python3.7/site-packages/jinja2/asyncsupport.py", line 76, in render
    return original_render(self, *args, **kwargs)
  File "/Library/Frameworks/Python.framework/Versions/3.7/lib/python3.7/site-packages/jinja2/environment.py", line 1008, in render
    return self.environment.handle_exception(exc_info, True)
  File "/Library/Frameworks/Python.framework/Versions/3.7/lib/python3.7/site-packages/jinja2/environment.py", line 780, in handle_exception
    reraise(exc_type, exc_value, tb)
  File "/Library/Frameworks/Python.framework/Versions/3.7/lib/python3.7/site-packages/jinja2/_compat.py", line 37, in reraise
    raise value.with_traceback(tb)
  File "/Users/yhz/Desktop/pypy/Flask_Learn/app/templates/auth/register.html", line 4, in top-level template code
    {% import 'bootstrap/wtf.html' as wtf %}
  File "/Users/yhz/Desktop/pypy/Flask_Learn/app/templates/base.html", line 2, in top-level template code
    {% extends 'bootstrap/base.html' %}
  File "/Library/Frameworks/Python.framework/Versions/3.7/lib/python3.7/site-packages/flask_bootstrap/templates/bootstrap/base.html", line 1, in top-level template code
    {% block doc -%}
  File "/Library/Frameworks/Python.framework/Versions/3.7/lib/python3.7/site-packages/flask_bootstrap/templates/bootstrap/base.html", line 4, in block "doc"
    {%- block html %}
  File "/Library/Frameworks/Python.framework/Versions/3.7/lib/python3.7/site-packages/flask_bootstrap/templates/bootstrap/base.html", line 20, in block "html"
    {% block body -%}
  File "/Library/Frameworks/Python.framework/Versions/3.7/lib/python3.7/site-packages/flask_bootstrap/templates/bootstrap/base.html", line 21, in block "body"
    {% block navbar %}
  File "/Users/yhz/Desktop/pypy/Flask_Learn/app/templates/base.html", line 24, in block "navbar"
    <a class="navbar-brand" href="{{ url_for('yhz.yhz1') }}">测试</a>
  File "/Library/Frameworks/Python.framework/Versions/3.7/lib/python3.7/site-packages/flask/helpers.py", line 356, in url_for
    return appctx.app.handle_url_build_error(error, endpoint, values)
  File "/Library/Frameworks/Python.framework/Versions/3.7/lib/python3.7/site-packages/flask/app.py", line 2061, in handle_url_build_error
    reraise(exc_type, exc_value, tb)
  File "/Library/Frameworks/Python.framework/Versions/3.7/lib/python3.7/site-packages/flask/_compat.py", line 35, in reraise
    raise value
  File "/Library/Frameworks/Python.framework/Versions/3.7/lib/python3.7/site-packages/flask/helpers.py", line 345, in url_for
    force_external=external)
  File "/Library/Frameworks/Python.framework/Versions/3.7/lib/python3.7/site-packages/werkzeug/routing.py", line 1776, in build
    raise BuildError(endpoint, values, method, self)
werkzeug.routing.BuildError: Could not build url for endpoint 'yhz.yhz1'. Did you mean 'auth.login' instead?
2020-02-10 19:43:20,993 INFO: Microblog startup [in /Users/yhz/Desktop/pypy/Flask_Learn/app/__init__.py:104]
2020-02-10 19:43:29,190 ERROR: Exception on /auth/register [POST] [in /Library/Frameworks/Python.framework/Versions/3.7/lib/python3.7/site-packages/flask/app.py:1761]
Traceback (most recent call last):
  File "/Library/Frameworks/Python.framework/Versions/3.7/lib/python3.7/site-packages/flask/app.py", line 2292, in wsgi_app
    response = self.full_dispatch_request()
  File "/Library/Frameworks/Python.framework/Versions/3.7/lib/python3.7/site-packages/flask/app.py", line 1815, in full_dispatch_request
    rv = self.handle_user_exception(e)
  File "/Library/Frameworks/Python.framework/Versions/3.7/lib/python3.7/site-packages/flask/app.py", line 1718, in handle_user_exception
    reraise(exc_type, exc_value, tb)
  File "/Library/Frameworks/Python.framework/Versions/3.7/lib/python3.7/site-packages/flask/_compat.py", line 35, in reraise
    raise value
  File "/Library/Frameworks/Python.framework/Versions/3.7/lib/python3.7/site-packages/flask/app.py", line 1813, in full_dispatch_request
    rv = self.dispatch_request()
  File "/Library/Frameworks/Python.framework/Versions/3.7/lib/python3.7/site-packages/flask/app.py", line 1799, in dispatch_request
    return self.view_functions[rule.endpoint](**req.view_args)
  File "/Users/yhz/Desktop/pypy/Flask_Learn/app/auth/routes.py", line 64, in register
    return render_template('auth/register.html', title=_('Register'), form=form)
  File "/Library/Frameworks/Python.framework/Versions/3.7/lib/python3.7/site-packages/flask/templating.py", line 135, in render_template
    context, ctx.app)
  File "/Library/Frameworks/Python.framework/Versions/3.7/lib/python3.7/site-packages/flask/templating.py", line 117, in _render
    rv = template.render(context)
  File "/Library/Frameworks/Python.framework/Versions/3.7/lib/python3.7/site-packages/jinja2/asyncsupport.py", line 76, in render
    return original_render(self, *args, **kwargs)
  File "/Library/Frameworks/Python.framework/Versions/3.7/lib/python3.7/site-packages/jinja2/environment.py", line 1008, in render
    return self.environment.handle_exception(exc_info, True)
  File "/Library/Frameworks/Python.framework/Versions/3.7/lib/python3.7/site-packages/jinja2/environment.py", line 780, in handle_exception
    reraise(exc_type, exc_value, tb)
  File "/Library/Frameworks/Python.framework/Versions/3.7/lib/python3.7/site-packages/jinja2/_compat.py", line 37, in reraise
    raise value.with_traceback(tb)
  File "/Users/yhz/Desktop/pypy/Flask_Learn/app/templates/auth/register.html", line 4, in top-level template code
    {% import 'bootstrap/wtf.html' as wtf %}
  File "/Users/yhz/Desktop/pypy/Flask_Learn/app/templates/base.html", line 2, in top-level template code
    {% extends 'bootstrap/base.html' %}
  File "/Library/Frameworks/Python.framework/Versions/3.7/lib/python3.7/site-packages/flask_bootstrap/templates/bootstrap/base.html", line 1, in top-level template code
    {% block doc -%}
  File "/Library/Frameworks/Python.framework/Versions/3.7/lib/python3.7/site-packages/flask_bootstrap/templates/bootstrap/base.html", line 4, in block "doc"
    {%- block html %}
  File "/Library/Frameworks/Python.framework/Versions/3.7/lib/python3.7/site-packages/flask_bootstrap/templates/bootstrap/base.html", line 20, in block "html"
    {% block body -%}
  File "/Library/Frameworks/Python.framework/Versions/3.7/lib/python3.7/site-packages/flask_bootstrap/templates/bootstrap/base.html", line 21, in block "body"
    {% block navbar %}
  File "/Users/yhz/Desktop/pypy/Flask_Learn/app/templates/base.html", line 24, in block "navbar"
    <a class="navbar-brand" href="{{ url_for('yhz.yhz1') }}">测试</a>
  File "/Library/Frameworks/Python.framework/Versions/3.7/lib/python3.7/site-packages/flask/helpers.py", line 356, in url_for
    return appctx.app.handle_url_build_error(error, endpoint, values)
  File "/Library/Frameworks/Python.framework/Versions/3.7/lib/python3.7/site-packages/flask/app.py", line 2061, in handle_url_build_error
    reraise(exc_type, exc_value, tb)
  File "/Library/Frameworks/Python.framework/Versions/3.7/lib/python3.7/site-packages/flask/_compat.py", line 35, in reraise
    raise value
  File "/Library/Frameworks/Python.framework/Versions/3.7/lib/python3.7/site-packages/flask/helpers.py", line 345, in url_for
    force_external=external)
  File "/Library/Frameworks/Python.framework/Versions/3.7/lib/python3.7/site-packages/werkzeug/routing.py", line 1776, in build
    raise BuildError(endpoint, values, method, self)
werkzeug.routing.BuildError: Could not build url for endpoint 'yhz.yhz1'. Did you mean 'auth.login' instead?
2020-02-10 19:44:29,650 INFO: Microblog startup [in /Users/yhz/Desktop/pypy/Flask_Learn/app/__init__.py:104]
2020-02-10 19:44:32,451 ERROR: Exception on /auth/register [POST] [in /Library/Frameworks/Python.framework/Versions/3.7/lib/python3.7/site-packages/flask/app.py:1761]
Traceback (most recent call last):
  File "/Library/Frameworks/Python.framework/Versions/3.7/lib/python3.7/site-packages/flask/app.py", line 2292, in wsgi_app
    response = self.full_dispatch_request()
  File "/Library/Frameworks/Python.framework/Versions/3.7/lib/python3.7/site-packages/flask/app.py", line 1815, in full_dispatch_request
    rv = self.handle_user_exception(e)
  File "/Library/Frameworks/Python.framework/Versions/3.7/lib/python3.7/site-packages/flask/app.py", line 1718, in handle_user_exception
    reraise(exc_type, exc_value, tb)
  File "/Library/Frameworks/Python.framework/Versions/3.7/lib/python3.7/site-packages/flask/_compat.py", line 35, in reraise
    raise value
  File "/Library/Frameworks/Python.framework/Versions/3.7/lib/python3.7/site-packages/flask/app.py", line 1813, in full_dispatch_request
    rv = self.dispatch_request()
  File "/Library/Frameworks/Python.framework/Versions/3.7/lib/python3.7/site-packages/flask/app.py", line 1799, in dispatch_request
    return self.view_functions[rule.endpoint](**req.view_args)
  File "/Users/yhz/Desktop/pypy/Flask_Learn/app/auth/routes.py", line 64, in register
    return render_template('auth/register.html', title=_('Register'), form=form)
  File "/Library/Frameworks/Python.framework/Versions/3.7/lib/python3.7/site-packages/flask/templating.py", line 135, in render_template
    context, ctx.app)
  File "/Library/Frameworks/Python.framework/Versions/3.7/lib/python3.7/site-packages/flask/templating.py", line 117, in _render
    rv = template.render(context)
  File "/Library/Frameworks/Python.framework/Versions/3.7/lib/python3.7/site-packages/jinja2/asyncsupport.py", line 76, in render
    return original_render(self, *args, **kwargs)
  File "/Library/Frameworks/Python.framework/Versions/3.7/lib/python3.7/site-packages/jinja2/environment.py", line 1008, in render
    return self.environment.handle_exception(exc_info, True)
  File "/Library/Frameworks/Python.framework/Versions/3.7/lib/python3.7/site-packages/jinja2/environment.py", line 780, in handle_exception
    reraise(exc_type, exc_value, tb)
  File "/Library/Frameworks/Python.framework/Versions/3.7/lib/python3.7/site-packages/jinja2/_compat.py", line 37, in reraise
    raise value.with_traceback(tb)
  File "/Users/yhz/Desktop/pypy/Flask_Learn/app/templates/base.html", line 25, in template
    <a class="navbar-brand" href="{{ url_for('main.index') }}">Leo</a>
  File "/Library/Frameworks/Python.framework/Versions/3.7/lib/python3.7/site-packages/jinja2/environment.py", line 1005, in render
    return concat(self.root_render_func(self.new_context(vars)))
  File "/Users/yhz/Desktop/pypy/Flask_Learn/app/templates/auth/register.html", line 3, in top-level template code
    {% extends "base.html" %}
  File "/Library/Frameworks/Python.framework/Versions/3.7/lib/python3.7/site-packages/jinja2/environment.py", line 780, in handle_exception
    reraise(exc_type, exc_value, tb)
  File "/Library/Frameworks/Python.framework/Versions/3.7/lib/python3.7/site-packages/jinja2/_compat.py", line 37, in reraise
    raise value.with_traceback(tb)
  File "/Users/yhz/Desktop/pypy/Flask_Learn/app/templates/base.html", line 25, in template
    <a class="navbar-brand" href="{{ url_for('main.index') }}">Leo</a>
  File "/Library/Frameworks/Python.framework/Versions/3.7/lib/python3.7/site-packages/jinja2/environment.py", line 497, in _parse
    return Parser(self, source, name, encode_filename(filename)).parse()
  File "/Library/Frameworks/Python.framework/Versions/3.7/lib/python3.7/site-packages/jinja2/parser.py", line 901, in parse
    result = nodes.Template(self.subparse(), lineno=1)
  File "/Library/Frameworks/Python.framework/Versions/3.7/lib/python3.7/site-packages/jinja2/parser.py", line 883, in subparse
    rv = self.parse_statement()
  File "/Library/Frameworks/Python.framework/Versions/3.7/lib/python3.7/site-packages/jinja2/parser.py", line 130, in parse_statement
    return getattr(self, 'parse_' + self.stream.current.value)()
  File "/Library/Frameworks/Python.framework/Versions/3.7/lib/python3.7/site-packages/jinja2/parser.py", line 268, in parse_block
    node.body = self.parse_statements(('name:endblock',), drop_needle=True)
  File "/Library/Frameworks/Python.framework/Versions/3.7/lib/python3.7/site-packages/jinja2/parser.py", line 165, in parse_statements
    result = self.subparse(end_tokens)
  File "/Library/Frameworks/Python.framework/Versions/3.7/lib/python3.7/site-packages/jinja2/parser.py", line 875, in subparse
    add_data(self.parse_tuple(with_condexpr=True))
  File "/Library/Frameworks/Python.framework/Versions/3.7/lib/python3.7/site-packages/jinja2/parser.py", line 620, in parse_tuple
    args.append(parse())
  File "/Library/Frameworks/Python.framework/Versions/3.7/lib/python3.7/site-packages/jinja2/parser.py", line 432, in parse_expression
    return self.parse_condexpr()
  File "/Library/Frameworks/Python.framework/Versions/3.7/lib/python3.7/site-packages/jinja2/parser.py", line 437, in parse_condexpr
    expr1 = self.parse_or()
  File "/Library/Frameworks/Python.framework/Versions/3.7/lib/python3.7/site-packages/jinja2/parser.py", line 450, in parse_or
    left = self.parse_and()
  File "/Library/Frameworks/Python.framework/Versions/3.7/lib/python3.7/site-packages/jinja2/parser.py", line 459, in parse_and
    left = self.parse_not()
  File "/Library/Frameworks/Python.framework/Versions/3.7/lib/python3.7/site-packages/jinja2/parser.py", line 470, in parse_not
    return self.parse_compare()
  File "/Library/Frameworks/Python.framework/Versions/3.7/lib/python3.7/site-packages/jinja2/parser.py", line 474, in parse_compare
    expr = self.parse_math1()
  File "/Library/Frameworks/Python.framework/Versions/3.7/lib/python3.7/site-packages/jinja2/parser.py", line 496, in parse_math1
    left = self.parse_concat()
  File "/Library/Frameworks/Python.framework/Versions/3.7/lib/python3.7/site-packages/jinja2/parser.py", line 507, in parse_concat
    args = [self.parse_math2()]
  File "/Library/Frameworks/Python.framework/Versions/3.7/lib/python3.7/site-packages/jinja2/parser.py", line 517, in parse_math2
    left = self.parse_pow()
  File "/Library/Frameworks/Python.framework/Versions/3.7/lib/python3.7/site-packages/jinja2/parser.py", line 528, in parse_pow
    left = self.parse_unary()
  File "/Library/Frameworks/Python.framework/Versions/3.7/lib/python3.7/site-packages/jinja2/parser.py", line 547, in parse_unary
    node = self.parse_postfix(node)
  File "/Library/Frameworks/Python.framework/Versions/3.7/lib/python3.7/site-packages/jinja2/parser.py", line 676, in parse_postfix
    node = self.parse_call(node)
  File "/Library/Frameworks/Python.framework/Versions/3.7/lib/python3.7/site-packages/jinja2/parser.py", line 767, in parse_call
    self.stream.expect('comma')
  File "/Library/Frameworks/Python.framework/Versions/3.7/lib/python3.7/site-packages/jinja2/lexer.py", line 384, in expect
    self.name, self.filename)
jinja2.exceptions.TemplateSyntaxError: expected token ',', got 'main'
2020-02-10 19:44:47,011 INFO: Microblog startup [in /Users/yhz/Desktop/pypy/Flask_Learn/app/__init__.py:104]
2020-02-10 19:45:21,376 INFO: Microblog startup [in /Users/yhz/Desktop/pypy/Flask_Learn/app/__init__.py:104]
2020-02-10 19:45:22,409 ERROR: Exception on /auth/login [GET] [in /Library/Frameworks/Python.framework/Versions/3.7/lib/python3.7/site-packages/flask/app.py:1761]
Traceback (most recent call last):
  File "/Library/Frameworks/Python.framework/Versions/3.7/lib/python3.7/site-packages/flask/app.py", line 2292, in wsgi_app
    response = self.full_dispatch_request()
  File "/Library/Frameworks/Python.framework/Versions/3.7/lib/python3.7/site-packages/flask/app.py", line 1815, in full_dispatch_request
    rv = self.handle_user_exception(e)
  File "/Library/Frameworks/Python.framework/Versions/3.7/lib/python3.7/site-packages/flask/app.py", line 1718, in handle_user_exception
    reraise(exc_type, exc_value, tb)
  File "/Library/Frameworks/Python.framework/Versions/3.7/lib/python3.7/site-packages/flask/_compat.py", line 35, in reraise
    raise value
  File "/Library/Frameworks/Python.framework/Versions/3.7/lib/python3.7/site-packages/flask/app.py", line 1813, in full_dispatch_request
    rv = self.dispatch_request()
  File "/Library/Frameworks/Python.framework/Versions/3.7/lib/python3.7/site-packages/flask/app.py", line 1799, in dispatch_request
    return self.view_functions[rule.endpoint](**req.view_args)
  File "/Users/yhz/Desktop/pypy/Flask_Learn/app/auth/routes.py", line 43, in login
    return render_template('auth/login.html', title=_('Sign In'), form=form)
  File "/Library/Frameworks/Python.framework/Versions/3.7/lib/python3.7/site-packages/flask/templating.py", line 135, in render_template
    context, ctx.app)
  File "/Library/Frameworks/Python.framework/Versions/3.7/lib/python3.7/site-packages/flask/templating.py", line 117, in _render
    rv = template.render(context)
  File "/Library/Frameworks/Python.framework/Versions/3.7/lib/python3.7/site-packages/jinja2/asyncsupport.py", line 76, in render
    return original_render(self, *args, **kwargs)
  File "/Library/Frameworks/Python.framework/Versions/3.7/lib/python3.7/site-packages/jinja2/environment.py", line 1008, in render
    return self.environment.handle_exception(exc_info, True)
  File "/Library/Frameworks/Python.framework/Versions/3.7/lib/python3.7/site-packages/jinja2/environment.py", line 780, in handle_exception
    reraise(exc_type, exc_value, tb)
  File "/Library/Frameworks/Python.framework/Versions/3.7/lib/python3.7/site-packages/jinja2/_compat.py", line 37, in reraise
    raise value.with_traceback(tb)
  File "/Users/yhz/Desktop/pypy/Flask_Learn/app/templates/auth/login.html", line 4, in top-level template code
    {% import 'bootstrap/wtf.html' as wtf %}
  File "/Users/yhz/Desktop/pypy/Flask_Learn/app/templates/base.html", line 2, in top-level template code
    {% extends 'bootstrap/base.html' %}
  File "/Library/Frameworks/Python.framework/Versions/3.7/lib/python3.7/site-packages/flask_bootstrap/templates/bootstrap/base.html", line 1, in top-level template code
    {% block doc -%}
  File "/Library/Frameworks/Python.framework/Versions/3.7/lib/python3.7/site-packages/flask_bootstrap/templates/bootstrap/base.html", line 4, in block "doc"
    {%- block html %}
  File "/Library/Frameworks/Python.framework/Versions/3.7/lib/python3.7/site-packages/flask_bootstrap/templates/bootstrap/base.html", line 20, in block "html"
    {% block body -%}
  File "/Library/Frameworks/Python.framework/Versions/3.7/lib/python3.7/site-packages/flask_bootstrap/templates/bootstrap/base.html", line 21, in block "body"
    {% block navbar %}
  File "/Users/yhz/Desktop/pypy/Flask_Learn/app/templates/base.html", line 24, in block "navbar"
    <a class="navbar-brand" href="{{ url_for('yhz.yhz1') }}">测试</a>
  File "/Library/Frameworks/Python.framework/Versions/3.7/lib/python3.7/site-packages/flask/helpers.py", line 356, in url_for
    return appctx.app.handle_url_build_error(error, endpoint, values)
  File "/Library/Frameworks/Python.framework/Versions/3.7/lib/python3.7/site-packages/flask/app.py", line 2061, in handle_url_build_error
    reraise(exc_type, exc_value, tb)
  File "/Library/Frameworks/Python.framework/Versions/3.7/lib/python3.7/site-packages/flask/_compat.py", line 35, in reraise
    raise value
  File "/Library/Frameworks/Python.framework/Versions/3.7/lib/python3.7/site-packages/flask/helpers.py", line 345, in url_for
    force_external=external)
  File "/Library/Frameworks/Python.framework/Versions/3.7/lib/python3.7/site-packages/werkzeug/routing.py", line 1776, in build
    raise BuildError(endpoint, values, method, self)
werkzeug.routing.BuildError: Could not build url for endpoint 'yhz.yhz1'. Did you mean 'auth.login' instead?
2020-02-10 19:51:46,521 INFO: Microblog startup [in /Users/yhz/Desktop/pypy/Flask_Learn/app/__init__.py:104]
2020-02-10 19:51:48,625 ERROR: Exception on /auth/login [GET] [in /Library/Frameworks/Python.framework/Versions/3.7/lib/python3.7/site-packages/flask/app.py:1761]
Traceback (most recent call last):
  File "/Library/Frameworks/Python.framework/Versions/3.7/lib/python3.7/site-packages/flask/app.py", line 2292, in wsgi_app
    response = self.full_dispatch_request()
  File "/Library/Frameworks/Python.framework/Versions/3.7/lib/python3.7/site-packages/flask/app.py", line 1815, in full_dispatch_request
    rv = self.handle_user_exception(e)
  File "/Library/Frameworks/Python.framework/Versions/3.7/lib/python3.7/site-packages/flask/app.py", line 1718, in handle_user_exception
    reraise(exc_type, exc_value, tb)
  File "/Library/Frameworks/Python.framework/Versions/3.7/lib/python3.7/site-packages/flask/_compat.py", line 35, in reraise
    raise value
  File "/Library/Frameworks/Python.framework/Versions/3.7/lib/python3.7/site-packages/flask/app.py", line 1813, in full_dispatch_request
    rv = self.dispatch_request()
  File "/Library/Frameworks/Python.framework/Versions/3.7/lib/python3.7/site-packages/flask/app.py", line 1799, in dispatch_request
    return self.view_functions[rule.endpoint](**req.view_args)
  File "/Users/yhz/Desktop/pypy/Flask_Learn/app/auth/routes.py", line 43, in login
    return render_template('auth/login.html', title=_('Sign In'), form=form)
  File "/Library/Frameworks/Python.framework/Versions/3.7/lib/python3.7/site-packages/flask/templating.py", line 135, in render_template
    context, ctx.app)
  File "/Library/Frameworks/Python.framework/Versions/3.7/lib/python3.7/site-packages/flask/templating.py", line 117, in _render
    rv = template.render(context)
  File "/Library/Frameworks/Python.framework/Versions/3.7/lib/python3.7/site-packages/jinja2/asyncsupport.py", line 76, in render
    return original_render(self, *args, **kwargs)
  File "/Library/Frameworks/Python.framework/Versions/3.7/lib/python3.7/site-packages/jinja2/environment.py", line 1008, in render
    return self.environment.handle_exception(exc_info, True)
  File "/Library/Frameworks/Python.framework/Versions/3.7/lib/python3.7/site-packages/jinja2/environment.py", line 780, in handle_exception
    reraise(exc_type, exc_value, tb)
  File "/Library/Frameworks/Python.framework/Versions/3.7/lib/python3.7/site-packages/jinja2/_compat.py", line 37, in reraise
    raise value.with_traceback(tb)
  File "/Users/yhz/Desktop/pypy/Flask_Learn/app/templates/auth/login.html", line 4, in top-level template code
    {% import 'bootstrap/wtf.html' as wtf %}
  File "/Users/yhz/Desktop/pypy/Flask_Learn/app/templates/base.html", line 2, in top-level template code
    {% extends 'bootstrap/base.html' %}
  File "/Library/Frameworks/Python.framework/Versions/3.7/lib/python3.7/site-packages/flask_bootstrap/templates/bootstrap/base.html", line 1, in top-level template code
    {% block doc -%}
  File "/Library/Frameworks/Python.framework/Versions/3.7/lib/python3.7/site-packages/flask_bootstrap/templates/bootstrap/base.html", line 4, in block "doc"
    {%- block html %}
  File "/Library/Frameworks/Python.framework/Versions/3.7/lib/python3.7/site-packages/flask_bootstrap/templates/bootstrap/base.html", line 20, in block "html"
    {% block body -%}
  File "/Library/Frameworks/Python.framework/Versions/3.7/lib/python3.7/site-packages/flask_bootstrap/templates/bootstrap/base.html", line 21, in block "body"
    {% block navbar %}
  File "/Users/yhz/Desktop/pypy/Flask_Learn/app/templates/base.html", line 24, in block "navbar"
    <!--                <a class="navbar-brand" href="{{ url_for('yhz.yhz1') }}">测试</a>-->
  File "/Library/Frameworks/Python.framework/Versions/3.7/lib/python3.7/site-packages/flask/helpers.py", line 356, in url_for
    return appctx.app.handle_url_build_error(error, endpoint, values)
  File "/Library/Frameworks/Python.framework/Versions/3.7/lib/python3.7/site-packages/flask/app.py", line 2061, in handle_url_build_error
    reraise(exc_type, exc_value, tb)
  File "/Library/Frameworks/Python.framework/Versions/3.7/lib/python3.7/site-packages/flask/_compat.py", line 35, in reraise
    raise value
  File "/Library/Frameworks/Python.framework/Versions/3.7/lib/python3.7/site-packages/flask/helpers.py", line 345, in url_for
    force_external=external)
  File "/Library/Frameworks/Python.framework/Versions/3.7/lib/python3.7/site-packages/werkzeug/routing.py", line 1776, in build
    raise BuildError(endpoint, values, method, self)
werkzeug.routing.BuildError: Could not build url for endpoint 'yhz.yhz1'. Did you mean 'auth.login' instead?
2020-02-10 19:51:53,849 ERROR: Exception on /auth/login [GET] [in /Library/Frameworks/Python.framework/Versions/3.7/lib/python3.7/site-packages/flask/app.py:1761]
Traceback (most recent call last):
  File "/Library/Frameworks/Python.framework/Versions/3.7/lib/python3.7/site-packages/flask/app.py", line 2292, in wsgi_app
    response = self.full_dispatch_request()
  File "/Library/Frameworks/Python.framework/Versions/3.7/lib/python3.7/site-packages/flask/app.py", line 1815, in full_dispatch_request
    rv = self.handle_user_exception(e)
  File "/Library/Frameworks/Python.framework/Versions/3.7/lib/python3.7/site-packages/flask/app.py", line 1718, in handle_user_exception
    reraise(exc_type, exc_value, tb)
  File "/Library/Frameworks/Python.framework/Versions/3.7/lib/python3.7/site-packages/flask/_compat.py", line 35, in reraise
    raise value
  File "/Library/Frameworks/Python.framework/Versions/3.7/lib/python3.7/site-packages/flask/app.py", line 1813, in full_dispatch_request
    rv = self.dispatch_request()
  File "/Library/Frameworks/Python.framework/Versions/3.7/lib/python3.7/site-packages/flask/app.py", line 1799, in dispatch_request
    return self.view_functions[rule.endpoint](**req.view_args)
  File "/Users/yhz/Desktop/pypy/Flask_Learn/app/auth/routes.py", line 43, in login
    return render_template('auth/login.html', title=_('Sign In'), form=form)
  File "/Library/Frameworks/Python.framework/Versions/3.7/lib/python3.7/site-packages/flask/templating.py", line 135, in render_template
    context, ctx.app)
  File "/Library/Frameworks/Python.framework/Versions/3.7/lib/python3.7/site-packages/flask/templating.py", line 117, in _render
    rv = template.render(context)
  File "/Library/Frameworks/Python.framework/Versions/3.7/lib/python3.7/site-packages/jinja2/asyncsupport.py", line 76, in render
    return original_render(self, *args, **kwargs)
  File "/Library/Frameworks/Python.framework/Versions/3.7/lib/python3.7/site-packages/jinja2/environment.py", line 1008, in render
    return self.environment.handle_exception(exc_info, True)
  File "/Library/Frameworks/Python.framework/Versions/3.7/lib/python3.7/site-packages/jinja2/environment.py", line 780, in handle_exception
    reraise(exc_type, exc_value, tb)
  File "/Library/Frameworks/Python.framework/Versions/3.7/lib/python3.7/site-packages/jinja2/_compat.py", line 37, in reraise
    raise value.with_traceback(tb)
  File "/Users/yhz/Desktop/pypy/Flask_Learn/app/templates/auth/login.html", line 4, in top-level template code
    {% import 'bootstrap/wtf.html' as wtf %}
  File "/Users/yhz/Desktop/pypy/Flask_Learn/app/templates/base.html", line 2, in top-level template code
    {% extends 'bootstrap/base.html' %}
  File "/Library/Frameworks/Python.framework/Versions/3.7/lib/python3.7/site-packages/flask_bootstrap/templates/bootstrap/base.html", line 1, in top-level template code
    {% block doc -%}
  File "/Library/Frameworks/Python.framework/Versions/3.7/lib/python3.7/site-packages/flask_bootstrap/templates/bootstrap/base.html", line 4, in block "doc"
    {%- block html %}
  File "/Library/Frameworks/Python.framework/Versions/3.7/lib/python3.7/site-packages/flask_bootstrap/templates/bootstrap/base.html", line 20, in block "html"
    {% block body -%}
  File "/Library/Frameworks/Python.framework/Versions/3.7/lib/python3.7/site-packages/flask_bootstrap/templates/bootstrap/base.html", line 21, in block "body"
    {% block navbar %}
  File "/Users/yhz/Desktop/pypy/Flask_Learn/app/templates/base.html", line 24, in block "navbar"
    <!--                <a class="navbar-brand" href="{{ url_for('yhz.yhz1') }}">测试</a>-->
  File "/Library/Frameworks/Python.framework/Versions/3.7/lib/python3.7/site-packages/flask/helpers.py", line 356, in url_for
    return appctx.app.handle_url_build_error(error, endpoint, values)
  File "/Library/Frameworks/Python.framework/Versions/3.7/lib/python3.7/site-packages/flask/app.py", line 2061, in handle_url_build_error
    reraise(exc_type, exc_value, tb)
  File "/Library/Frameworks/Python.framework/Versions/3.7/lib/python3.7/site-packages/flask/_compat.py", line 35, in reraise
    raise value
  File "/Library/Frameworks/Python.framework/Versions/3.7/lib/python3.7/site-packages/flask/helpers.py", line 345, in url_for
    force_external=external)
  File "/Library/Frameworks/Python.framework/Versions/3.7/lib/python3.7/site-packages/werkzeug/routing.py", line 1776, in build
    raise BuildError(endpoint, values, method, self)
werkzeug.routing.BuildError: Could not build url for endpoint 'yhz.yhz1'. Did you mean 'auth.login' instead?
2020-02-10 19:51:55,475 ERROR: Exception on /auth/login [GET] [in /Library/Frameworks/Python.framework/Versions/3.7/lib/python3.7/site-packages/flask/app.py:1761]
Traceback (most recent call last):
  File "/Library/Frameworks/Python.framework/Versions/3.7/lib/python3.7/site-packages/flask/app.py", line 2292, in wsgi_app
    response = self.full_dispatch_request()
  File "/Library/Frameworks/Python.framework/Versions/3.7/lib/python3.7/site-packages/flask/app.py", line 1815, in full_dispatch_request
    rv = self.handle_user_exception(e)
  File "/Library/Frameworks/Python.framework/Versions/3.7/lib/python3.7/site-packages/flask/app.py", line 1718, in handle_user_exception
    reraise(exc_type, exc_value, tb)
  File "/Library/Frameworks/Python.framework/Versions/3.7/lib/python3.7/site-packages/flask/_compat.py", line 35, in reraise
    raise value
  File "/Library/Frameworks/Python.framework/Versions/3.7/lib/python3.7/site-packages/flask/app.py", line 1813, in full_dispatch_request
    rv = self.dispatch_request()
  File "/Library/Frameworks/Python.framework/Versions/3.7/lib/python3.7/site-packages/flask/app.py", line 1799, in dispatch_request
    return self.view_functions[rule.endpoint](**req.view_args)
  File "/Users/yhz/Desktop/pypy/Flask_Learn/app/auth/routes.py", line 43, in login
    return render_template('auth/login.html', title=_('Sign In'), form=form)
  File "/Library/Frameworks/Python.framework/Versions/3.7/lib/python3.7/site-packages/flask/templating.py", line 135, in render_template
    context, ctx.app)
  File "/Library/Frameworks/Python.framework/Versions/3.7/lib/python3.7/site-packages/flask/templating.py", line 117, in _render
    rv = template.render(context)
  File "/Library/Frameworks/Python.framework/Versions/3.7/lib/python3.7/site-packages/jinja2/asyncsupport.py", line 76, in render
    return original_render(self, *args, **kwargs)
  File "/Library/Frameworks/Python.framework/Versions/3.7/lib/python3.7/site-packages/jinja2/environment.py", line 1008, in render
    return self.environment.handle_exception(exc_info, True)
  File "/Library/Frameworks/Python.framework/Versions/3.7/lib/python3.7/site-packages/jinja2/environment.py", line 780, in handle_exception
    reraise(exc_type, exc_value, tb)
  File "/Library/Frameworks/Python.framework/Versions/3.7/lib/python3.7/site-packages/jinja2/_compat.py", line 37, in reraise
    raise value.with_traceback(tb)
  File "/Users/yhz/Desktop/pypy/Flask_Learn/app/templates/auth/login.html", line 4, in top-level template code
    {% import 'bootstrap/wtf.html' as wtf %}
  File "/Users/yhz/Desktop/pypy/Flask_Learn/app/templates/base.html", line 2, in top-level template code
    {% extends 'bootstrap/base.html' %}
  File "/Library/Frameworks/Python.framework/Versions/3.7/lib/python3.7/site-packages/flask_bootstrap/templates/bootstrap/base.html", line 1, in top-level template code
    {% block doc -%}
  File "/Library/Frameworks/Python.framework/Versions/3.7/lib/python3.7/site-packages/flask_bootstrap/templates/bootstrap/base.html", line 4, in block "doc"
    {%- block html %}
  File "/Library/Frameworks/Python.framework/Versions/3.7/lib/python3.7/site-packages/flask_bootstrap/templates/bootstrap/base.html", line 20, in block "html"
    {% block body -%}
  File "/Library/Frameworks/Python.framework/Versions/3.7/lib/python3.7/site-packages/flask_bootstrap/templates/bootstrap/base.html", line 21, in block "body"
    {% block navbar %}
  File "/Users/yhz/Desktop/pypy/Flask_Learn/app/templates/base.html", line 24, in block "navbar"
    <!--                <a class="navbar-brand" href="{{ url_for('yhz.yhz1') }}">测试</a>-->
  File "/Library/Frameworks/Python.framework/Versions/3.7/lib/python3.7/site-packages/flask/helpers.py", line 356, in url_for
    return appctx.app.handle_url_build_error(error, endpoint, values)
  File "/Library/Frameworks/Python.framework/Versions/3.7/lib/python3.7/site-packages/flask/app.py", line 2061, in handle_url_build_error
    reraise(exc_type, exc_value, tb)
  File "/Library/Frameworks/Python.framework/Versions/3.7/lib/python3.7/site-packages/flask/_compat.py", line 35, in reraise
    raise value
  File "/Library/Frameworks/Python.framework/Versions/3.7/lib/python3.7/site-packages/flask/helpers.py", line 345, in url_for
    force_external=external)
  File "/Library/Frameworks/Python.framework/Versions/3.7/lib/python3.7/site-packages/werkzeug/routing.py", line 1776, in build
    raise BuildError(endpoint, values, method, self)
werkzeug.routing.BuildError: Could not build url for endpoint 'yhz.yhz1'. Did you mean 'auth.login' instead?
2020-02-10 19:53:15,915 INFO: Microblog startup [in /Users/yhz/Desktop/pypy/Flask_Learn/app/__init__.py:104]
2020-02-10 19:53:18,524 ERROR: Exception on /auth/login [GET] [in /Library/Frameworks/Python.framework/Versions/3.7/lib/python3.7/site-packages/flask/app.py:1761]
Traceback (most recent call last):
  File "/Library/Frameworks/Python.framework/Versions/3.7/lib/python3.7/site-packages/flask/app.py", line 2292, in wsgi_app
    response = self.full_dispatch_request()
  File "/Library/Frameworks/Python.framework/Versions/3.7/lib/python3.7/site-packages/flask/app.py", line 1815, in full_dispatch_request
    rv = self.handle_user_exception(e)
  File "/Library/Frameworks/Python.framework/Versions/3.7/lib/python3.7/site-packages/flask/app.py", line 1718, in handle_user_exception
    reraise(exc_type, exc_value, tb)
  File "/Library/Frameworks/Python.framework/Versions/3.7/lib/python3.7/site-packages/flask/_compat.py", line 35, in reraise
    raise value
  File "/Library/Frameworks/Python.framework/Versions/3.7/lib/python3.7/site-packages/flask/app.py", line 1813, in full_dispatch_request
    rv = self.dispatch_request()
  File "/Library/Frameworks/Python.framework/Versions/3.7/lib/python3.7/site-packages/flask/app.py", line 1799, in dispatch_request
    return self.view_functions[rule.endpoint](**req.view_args)
  File "/Users/yhz/Desktop/pypy/Flask_Learn/app/auth/routes.py", line 43, in login
    return render_template('auth/login.html', title=_('Sign In'), form=form)
  File "/Library/Frameworks/Python.framework/Versions/3.7/lib/python3.7/site-packages/flask/templating.py", line 135, in render_template
    context, ctx.app)
  File "/Library/Frameworks/Python.framework/Versions/3.7/lib/python3.7/site-packages/flask/templating.py", line 117, in _render
    rv = template.render(context)
  File "/Library/Frameworks/Python.framework/Versions/3.7/lib/python3.7/site-packages/jinja2/asyncsupport.py", line 76, in render
    return original_render(self, *args, **kwargs)
  File "/Library/Frameworks/Python.framework/Versions/3.7/lib/python3.7/site-packages/jinja2/environment.py", line 1008, in render
    return self.environment.handle_exception(exc_info, True)
  File "/Library/Frameworks/Python.framework/Versions/3.7/lib/python3.7/site-packages/jinja2/environment.py", line 780, in handle_exception
    reraise(exc_type, exc_value, tb)
  File "/Library/Frameworks/Python.framework/Versions/3.7/lib/python3.7/site-packages/jinja2/_compat.py", line 37, in reraise
    raise value.with_traceback(tb)
  File "/Users/yhz/Desktop/pypy/Flask_Learn/app/templates/auth/login.html", line 4, in top-level template code
    {% import 'bootstrap/wtf.html' as wtf %}
  File "/Users/yhz/Desktop/pypy/Flask_Learn/app/templates/base.html", line 2, in top-level template code
    {% extends 'bootstrap/base.html' %}
  File "/Library/Frameworks/Python.framework/Versions/3.7/lib/python3.7/site-packages/flask_bootstrap/templates/bootstrap/base.html", line 1, in top-level template code
    {% block doc -%}
  File "/Library/Frameworks/Python.framework/Versions/3.7/lib/python3.7/site-packages/flask_bootstrap/templates/bootstrap/base.html", line 4, in block "doc"
    {%- block html %}
  File "/Library/Frameworks/Python.framework/Versions/3.7/lib/python3.7/site-packages/flask_bootstrap/templates/bootstrap/base.html", line 20, in block "html"
    {% block body -%}
  File "/Library/Frameworks/Python.framework/Versions/3.7/lib/python3.7/site-packages/flask_bootstrap/templates/bootstrap/base.html", line 21, in block "body"
    {% block navbar %}
  File "/Users/yhz/Desktop/pypy/Flask_Learn/app/templates/base.html", line 24, in block "navbar"
    <a class="navbar-brand" href="{{ url_for('yhz.yhz1') }}">测试</a>
  File "/Library/Frameworks/Python.framework/Versions/3.7/lib/python3.7/site-packages/flask/helpers.py", line 356, in url_for
    return appctx.app.handle_url_build_error(error, endpoint, values)
  File "/Library/Frameworks/Python.framework/Versions/3.7/lib/python3.7/site-packages/flask/app.py", line 2061, in handle_url_build_error
    reraise(exc_type, exc_value, tb)
  File "/Library/Frameworks/Python.framework/Versions/3.7/lib/python3.7/site-packages/flask/_compat.py", line 35, in reraise
    raise value
  File "/Library/Frameworks/Python.framework/Versions/3.7/lib/python3.7/site-packages/flask/helpers.py", line 345, in url_for
    force_external=external)
  File "/Library/Frameworks/Python.framework/Versions/3.7/lib/python3.7/site-packages/werkzeug/routing.py", line 1776, in build
    raise BuildError(endpoint, values, method, self)
werkzeug.routing.BuildError: Could not build url for endpoint 'yhz.yhz1'. Did you mean 'auth.login' instead?
2020-02-10 19:53:42,259 INFO: Microblog startup [in /Users/yhz/Desktop/pypy/Flask_Learn/app/__init__.py:104]
2020-02-10 19:53:43,370 ERROR: Exception on /auth/login [GET] [in /Library/Frameworks/Python.framework/Versions/3.7/lib/python3.7/site-packages/flask/app.py:1761]
Traceback (most recent call last):
  File "/Library/Frameworks/Python.framework/Versions/3.7/lib/python3.7/site-packages/flask/app.py", line 2292, in wsgi_app
    response = self.full_dispatch_request()
  File "/Library/Frameworks/Python.framework/Versions/3.7/lib/python3.7/site-packages/flask/app.py", line 1815, in full_dispatch_request
    rv = self.handle_user_exception(e)
  File "/Library/Frameworks/Python.framework/Versions/3.7/lib/python3.7/site-packages/flask/app.py", line 1718, in handle_user_exception
    reraise(exc_type, exc_value, tb)
  File "/Library/Frameworks/Python.framework/Versions/3.7/lib/python3.7/site-packages/flask/_compat.py", line 35, in reraise
    raise value
  File "/Library/Frameworks/Python.framework/Versions/3.7/lib/python3.7/site-packages/flask/app.py", line 1813, in full_dispatch_request
    rv = self.dispatch_request()
  File "/Library/Frameworks/Python.framework/Versions/3.7/lib/python3.7/site-packages/flask/app.py", line 1799, in dispatch_request
    return self.view_functions[rule.endpoint](**req.view_args)
  File "/Users/yhz/Desktop/pypy/Flask_Learn/app/auth/routes.py", line 43, in login
    return render_template('auth/login.html', title=_('Sign In'), form=form)
  File "/Library/Frameworks/Python.framework/Versions/3.7/lib/python3.7/site-packages/flask/templating.py", line 135, in render_template
    context, ctx.app)
  File "/Library/Frameworks/Python.framework/Versions/3.7/lib/python3.7/site-packages/flask/templating.py", line 117, in _render
    rv = template.render(context)
  File "/Library/Frameworks/Python.framework/Versions/3.7/lib/python3.7/site-packages/jinja2/asyncsupport.py", line 76, in render
    return original_render(self, *args, **kwargs)
  File "/Library/Frameworks/Python.framework/Versions/3.7/lib/python3.7/site-packages/jinja2/environment.py", line 1008, in render
    return self.environment.handle_exception(exc_info, True)
  File "/Library/Frameworks/Python.framework/Versions/3.7/lib/python3.7/site-packages/jinja2/environment.py", line 780, in handle_exception
    reraise(exc_type, exc_value, tb)
  File "/Library/Frameworks/Python.framework/Versions/3.7/lib/python3.7/site-packages/jinja2/_compat.py", line 37, in reraise
    raise value.with_traceback(tb)
  File "/Users/yhz/Desktop/pypy/Flask_Learn/app/templates/auth/login.html", line 4, in top-level template code
    {% import 'bootstrap/wtf.html' as wtf %}
  File "/Users/yhz/Desktop/pypy/Flask_Learn/app/templates/base.html", line 2, in top-level template code
    {% extends 'bootstrap/base.html' %}
  File "/Library/Frameworks/Python.framework/Versions/3.7/lib/python3.7/site-packages/flask_bootstrap/templates/bootstrap/base.html", line 1, in top-level template code
    {% block doc -%}
  File "/Library/Frameworks/Python.framework/Versions/3.7/lib/python3.7/site-packages/flask_bootstrap/templates/bootstrap/base.html", line 4, in block "doc"
    {%- block html %}
  File "/Library/Frameworks/Python.framework/Versions/3.7/lib/python3.7/site-packages/flask_bootstrap/templates/bootstrap/base.html", line 20, in block "html"
    {% block body -%}
  File "/Library/Frameworks/Python.framework/Versions/3.7/lib/python3.7/site-packages/flask_bootstrap/templates/bootstrap/base.html", line 21, in block "body"
    {% block navbar %}
  File "/Users/yhz/Desktop/pypy/Flask_Learn/app/templates/base.html", line 24, in block "navbar"
    <a class="navbar-brand" href="{{ url_for('yhz.yhz1') }}">测试</a>
  File "/Library/Frameworks/Python.framework/Versions/3.7/lib/python3.7/site-packages/flask/helpers.py", line 356, in url_for
    return appctx.app.handle_url_build_error(error, endpoint, values)
  File "/Library/Frameworks/Python.framework/Versions/3.7/lib/python3.7/site-packages/flask/app.py", line 2061, in handle_url_build_error
    reraise(exc_type, exc_value, tb)
  File "/Library/Frameworks/Python.framework/Versions/3.7/lib/python3.7/site-packages/flask/_compat.py", line 35, in reraise
    raise value
  File "/Library/Frameworks/Python.framework/Versions/3.7/lib/python3.7/site-packages/flask/helpers.py", line 345, in url_for
    force_external=external)
  File "/Library/Frameworks/Python.framework/Versions/3.7/lib/python3.7/site-packages/werkzeug/routing.py", line 1776, in build
    raise BuildError(endpoint, values, method, self)
werkzeug.routing.BuildError: Could not build url for endpoint 'yhz.yhz1'. Did you mean 'auth.login' instead?
2020-02-10 19:54:14,447 INFO: Microblog startup [in /Users/yhz/Desktop/pypy/Flask_Learn/app/__init__.py:104]
2020-02-10 19:54:15,012 ERROR: Exception on /auth/login [GET] [in /Library/Frameworks/Python.framework/Versions/3.7/lib/python3.7/site-packages/flask/app.py:1761]
Traceback (most recent call last):
  File "/Library/Frameworks/Python.framework/Versions/3.7/lib/python3.7/site-packages/flask/app.py", line 2292, in wsgi_app
    response = self.full_dispatch_request()
  File "/Library/Frameworks/Python.framework/Versions/3.7/lib/python3.7/site-packages/flask/app.py", line 1815, in full_dispatch_request
    rv = self.handle_user_exception(e)
  File "/Library/Frameworks/Python.framework/Versions/3.7/lib/python3.7/site-packages/flask/app.py", line 1718, in handle_user_exception
    reraise(exc_type, exc_value, tb)
  File "/Library/Frameworks/Python.framework/Versions/3.7/lib/python3.7/site-packages/flask/_compat.py", line 35, in reraise
    raise value
  File "/Library/Frameworks/Python.framework/Versions/3.7/lib/python3.7/site-packages/flask/app.py", line 1813, in full_dispatch_request
    rv = self.dispatch_request()
  File "/Library/Frameworks/Python.framework/Versions/3.7/lib/python3.7/site-packages/flask/app.py", line 1799, in dispatch_request
    return self.view_functions[rule.endpoint](**req.view_args)
  File "/Users/yhz/Desktop/pypy/Flask_Learn/app/auth/routes.py", line 43, in login
    return render_template('auth/login.html', title=_('Sign In'), form=form)
  File "/Library/Frameworks/Python.framework/Versions/3.7/lib/python3.7/site-packages/flask/templating.py", line 135, in render_template
    context, ctx.app)
  File "/Library/Frameworks/Python.framework/Versions/3.7/lib/python3.7/site-packages/flask/templating.py", line 117, in _render
    rv = template.render(context)
  File "/Library/Frameworks/Python.framework/Versions/3.7/lib/python3.7/site-packages/jinja2/asyncsupport.py", line 76, in render
    return original_render(self, *args, **kwargs)
  File "/Library/Frameworks/Python.framework/Versions/3.7/lib/python3.7/site-packages/jinja2/environment.py", line 1008, in render
    return self.environment.handle_exception(exc_info, True)
  File "/Library/Frameworks/Python.framework/Versions/3.7/lib/python3.7/site-packages/jinja2/environment.py", line 780, in handle_exception
    reraise(exc_type, exc_value, tb)
  File "/Library/Frameworks/Python.framework/Versions/3.7/lib/python3.7/site-packages/jinja2/_compat.py", line 37, in reraise
    raise value.with_traceback(tb)
  File "/Users/yhz/Desktop/pypy/Flask_Learn/app/templates/auth/login.html", line 4, in top-level template code
    {% import 'bootstrap/wtf.html' as wtf %}
  File "/Users/yhz/Desktop/pypy/Flask_Learn/app/templates/base.html", line 2, in top-level template code
    {% extends 'bootstrap/base.html' %}
  File "/Library/Frameworks/Python.framework/Versions/3.7/lib/python3.7/site-packages/flask_bootstrap/templates/bootstrap/base.html", line 1, in top-level template code
    {% block doc -%}
  File "/Library/Frameworks/Python.framework/Versions/3.7/lib/python3.7/site-packages/flask_bootstrap/templates/bootstrap/base.html", line 4, in block "doc"
    {%- block html %}
  File "/Library/Frameworks/Python.framework/Versions/3.7/lib/python3.7/site-packages/flask_bootstrap/templates/bootstrap/base.html", line 20, in block "html"
    {% block body -%}
  File "/Library/Frameworks/Python.framework/Versions/3.7/lib/python3.7/site-packages/flask_bootstrap/templates/bootstrap/base.html", line 21, in block "body"
    {% block navbar %}
  File "/Users/yhz/Desktop/pypy/Flask_Learn/app/templates/base.html", line 24, in block "navbar"
    <a class="navbar-brand" href="{{ url_for('yhz.yhz1') }}">测试</a>
  File "/Library/Frameworks/Python.framework/Versions/3.7/lib/python3.7/site-packages/flask/helpers.py", line 356, in url_for
    return appctx.app.handle_url_build_error(error, endpoint, values)
  File "/Library/Frameworks/Python.framework/Versions/3.7/lib/python3.7/site-packages/flask/app.py", line 2061, in handle_url_build_error
    reraise(exc_type, exc_value, tb)
  File "/Library/Frameworks/Python.framework/Versions/3.7/lib/python3.7/site-packages/flask/_compat.py", line 35, in reraise
    raise value
  File "/Library/Frameworks/Python.framework/Versions/3.7/lib/python3.7/site-packages/flask/helpers.py", line 345, in url_for
    force_external=external)
  File "/Library/Frameworks/Python.framework/Versions/3.7/lib/python3.7/site-packages/werkzeug/routing.py", line 1776, in build
    raise BuildError(endpoint, values, method, self)
werkzeug.routing.BuildError: Could not build url for endpoint 'yhz.yhz1'. Did you mean 'auth.login' instead?
2020-02-10 19:54:15,941 ERROR: Exception on /auth/login [GET] [in /Library/Frameworks/Python.framework/Versions/3.7/lib/python3.7/site-packages/flask/app.py:1761]
Traceback (most recent call last):
  File "/Library/Frameworks/Python.framework/Versions/3.7/lib/python3.7/site-packages/flask/app.py", line 2292, in wsgi_app
    response = self.full_dispatch_request()
  File "/Library/Frameworks/Python.framework/Versions/3.7/lib/python3.7/site-packages/flask/app.py", line 1815, in full_dispatch_request
    rv = self.handle_user_exception(e)
  File "/Library/Frameworks/Python.framework/Versions/3.7/lib/python3.7/site-packages/flask/app.py", line 1718, in handle_user_exception
    reraise(exc_type, exc_value, tb)
  File "/Library/Frameworks/Python.framework/Versions/3.7/lib/python3.7/site-packages/flask/_compat.py", line 35, in reraise
    raise value
  File "/Library/Frameworks/Python.framework/Versions/3.7/lib/python3.7/site-packages/flask/app.py", line 1813, in full_dispatch_request
    rv = self.dispatch_request()
  File "/Library/Frameworks/Python.framework/Versions/3.7/lib/python3.7/site-packages/flask/app.py", line 1799, in dispatch_request
    return self.view_functions[rule.endpoint](**req.view_args)
  File "/Users/yhz/Desktop/pypy/Flask_Learn/app/auth/routes.py", line 43, in login
    return render_template('auth/login.html', title=_('Sign In'), form=form)
  File "/Library/Frameworks/Python.framework/Versions/3.7/lib/python3.7/site-packages/flask/templating.py", line 135, in render_template
    context, ctx.app)
  File "/Library/Frameworks/Python.framework/Versions/3.7/lib/python3.7/site-packages/flask/templating.py", line 117, in _render
    rv = template.render(context)
  File "/Library/Frameworks/Python.framework/Versions/3.7/lib/python3.7/site-packages/jinja2/asyncsupport.py", line 76, in render
    return original_render(self, *args, **kwargs)
  File "/Library/Frameworks/Python.framework/Versions/3.7/lib/python3.7/site-packages/jinja2/environment.py", line 1008, in render
    return self.environment.handle_exception(exc_info, True)
  File "/Library/Frameworks/Python.framework/Versions/3.7/lib/python3.7/site-packages/jinja2/environment.py", line 780, in handle_exception
    reraise(exc_type, exc_value, tb)
  File "/Library/Frameworks/Python.framework/Versions/3.7/lib/python3.7/site-packages/jinja2/_compat.py", line 37, in reraise
    raise value.with_traceback(tb)
  File "/Users/yhz/Desktop/pypy/Flask_Learn/app/templates/auth/login.html", line 4, in top-level template code
    {% import 'bootstrap/wtf.html' as wtf %}
  File "/Users/yhz/Desktop/pypy/Flask_Learn/app/templates/base.html", line 2, in top-level template code
    {% extends 'bootstrap/base.html' %}
  File "/Library/Frameworks/Python.framework/Versions/3.7/lib/python3.7/site-packages/flask_bootstrap/templates/bootstrap/base.html", line 1, in top-level template code
    {% block doc -%}
  File "/Library/Frameworks/Python.framework/Versions/3.7/lib/python3.7/site-packages/flask_bootstrap/templates/bootstrap/base.html", line 4, in block "doc"
    {%- block html %}
  File "/Library/Frameworks/Python.framework/Versions/3.7/lib/python3.7/site-packages/flask_bootstrap/templates/bootstrap/base.html", line 20, in block "html"
    {% block body -%}
  File "/Library/Frameworks/Python.framework/Versions/3.7/lib/python3.7/site-packages/flask_bootstrap/templates/bootstrap/base.html", line 21, in block "body"
    {% block navbar %}
  File "/Users/yhz/Desktop/pypy/Flask_Learn/app/templates/base.html", line 24, in block "navbar"
    <a class="navbar-brand" href="{{ url_for('yhz.yhz1') }}">测试</a>
  File "/Library/Frameworks/Python.framework/Versions/3.7/lib/python3.7/site-packages/flask/helpers.py", line 356, in url_for
    return appctx.app.handle_url_build_error(error, endpoint, values)
  File "/Library/Frameworks/Python.framework/Versions/3.7/lib/python3.7/site-packages/flask/app.py", line 2061, in handle_url_build_error
    reraise(exc_type, exc_value, tb)
  File "/Library/Frameworks/Python.framework/Versions/3.7/lib/python3.7/site-packages/flask/_compat.py", line 35, in reraise
    raise value
  File "/Library/Frameworks/Python.framework/Versions/3.7/lib/python3.7/site-packages/flask/helpers.py", line 345, in url_for
    force_external=external)
  File "/Library/Frameworks/Python.framework/Versions/3.7/lib/python3.7/site-packages/werkzeug/routing.py", line 1776, in build
    raise BuildError(endpoint, values, method, self)
werkzeug.routing.BuildError: Could not build url for endpoint 'yhz.yhz1'. Did you mean 'auth.login' instead?
2020-02-10 19:54:31,677 INFO: Microblog startup [in /Users/yhz/Desktop/pypy/Flask_Learn/app/__init__.py:104]
